2024-03-17 15:25:19.778335: W external/xla/xla/service/hlo_rematerialization.cc:2941] Can't reduce memory use below -1.88TiB (-2064790164282 bytes) by rematerialization; only reduced to 8.00TiB (8796093022576 bytes), down from 8.00TiB (8796093022736 bytes) originally
2024-03-17 15:25:19.794358: W external/xla/xla/service/hlo_rematerialization.cc:2941] Can't reduce memory use below -1.88TiB (-2064790164282 bytes) by rematerialization; only reduced to 8.00TiB (8796093022576 bytes), down from 8.00TiB (8796093022736 bytes) originally
2024-03-17 15:25:19.778648: W external/xla/xla/service/hlo_rematerialization.cc:2941] Can't reduce memory use below -1.88TiB (-2064790164282 bytes) by rematerialization; only reduced to 8.00TiB (8796093022576 bytes), down from 8.00TiB (8796093022736 bytes) originally
2024-03-17 15:25:19.779840: W external/xla/xla/service/hlo_rematerialization.cc:2941] Can't reduce memory use below -1.88TiB (-2064790164282 bytes) by rematerialization; only reduced to 8.00TiB (8796093022576 bytes), down from 8.00TiB (8796093022736 bytes) originally
2024-03-17 15:25:19.779901: W external/xla/xla/service/hlo_rematerialization.cc:2941] Can't reduce memory use below -1.88TiB (-2064790164282 bytes) by rematerialization; only reduced to 8.00TiB (8796093022576 bytes), down from 8.00TiB (8796093022736 bytes) originally
2024-03-17 15:25:19.782507: E external/xla/xla/status_macros.cc:54] INTERNAL: RET_CHECK failure (external/xla/xla/service/gpu/fusions/fusion_emitter.cc:96) device_info.block_dim_limit().x == 0 || launch_dims.block_counts().x < device_info.block_dim_limit().x Kernel 'input_concatenate_fusion' launch needs more blocks (4294967295) than allowed by hardware (2147483647).
*** Begin stack trace ***
	
	
	
	
	
	
	
	
	
	
	
	
	
	
	
	
	
	
	
	
	
	
	
	
	
	
	
	
	
	
	_PyObject_MakeTpCall
	
	_PyEval_EvalFrameDefault
	_PyFunction_Vectorcall
	_PyEval_EvalFrameDefault
	_PyFunction_Vectorcall
	_PyEval_EvalFrameDefault
	_PyFunction_Vectorcall
	_PyEval_EvalFrameDefault
	_PyFunction_Vectorcall
	_PyEval_EvalFrameDefault
	_PyFunction_Vectorcall
	
	
	
	
	
	
	
	
	_PyObject_MakeTpCall
	
	
	_PyObject_MakeTpCall
	_PyEval_EvalFrameDefault
	_PyFunction_Vectorcall
	PyObject_Call
	_PyEval_EvalFrameDefault
	_PyFunction_Vectorcall
	_PyEval_EvalFrameDefault
	_PyFunction_Vectorcall
	PyObject_Call
	_PyEval_EvalFrameDefault
	_PyFunction_Vectorcall
	
	
	_PyEval_EvalFrameDefault
	_PyFunction_Vectorcall
	PyObject_Call
	_PyEval_EvalFrameDefault
	_PyFunction_Vectorcall
	_PyEval_EvalFrameDefault
	_PyFunction_Vectorcall
	_PyEval_EvalFrameDefault
	
	PyObject_Call
	_PyEval_EvalFrameDefault
	_PyFunction_Vectorcall
	_PyEval_EvalFrameDefault
	_PyFunction_Vectorcall
	_PyEval_EvalFrameDefault
	_PyFunction_Vectorcall
	
	
	_PyEval_EvalFrameDefault
	_PyFunction_Vectorcall
	_PyEval_EvalFrameDefault
	_PyFunction_Vectorcall
	_PyEval_EvalFrameDefault
	
	PyEval_EvalCode
	
	
	
	_PyRun_SimpleFileObject
	_PyRun_AnyFileObject
	Py_RunMain
	Py_BytesMain
	__libc_start_main
	
*** End stack trace ***

2024-03-17 15:25:19.782651: E external/xla/xla/status_macros.cc:54] INTERNAL: RET_CHECK failure (external/xla/xla/service/gpu/fusions/fusion_emitter.cc:96) device_info.block_dim_limit().x == 0 || launch_dims.block_counts().x < device_info.block_dim_limit().x Kernel 'input_concatenate_fusion' launch needs more blocks (4294967295) than allowed by hardware (2147483647).
*** Begin stack trace ***
	
	
	
	
	
	
	
	
	
	
	
	
	
	
	
	
	
	
	
	
	
	
	
	
	
	
	
	
	
	
	_PyObject_MakeTpCall
	
	_PyEval_EvalFrameDefault
	_PyFunction_Vectorcall
	_PyEval_EvalFrameDefault
	_PyFunction_Vectorcall
	_PyEval_EvalFrameDefault
	_PyFunction_Vectorcall
	_PyEval_EvalFrameDefault
	_PyFunction_Vectorcall
	_PyEval_EvalFrameDefault
	_PyFunction_Vectorcall
	
	
	
	
	
	
	
	
	_PyObject_MakeTpCall
	
	
	_PyObject_MakeTpCall
	_PyEval_EvalFrameDefault
	_PyFunction_Vectorcall
	PyObject_Call
	_PyEval_EvalFrameDefault
	_PyFunction_Vectorcall
	_PyEval_EvalFrameDefault
	_PyFunction_Vectorcall
	PyObject_Call
	_PyEval_EvalFrameDefault
	_PyFunction_Vectorcall
	
	
	_PyEval_EvalFrameDefault
	_PyFunction_Vectorcall
	PyObject_Call
	_PyEval_EvalFrameDefault
	_PyFunction_Vectorcall
	_PyEval_EvalFrameDefault
	_PyFunction_Vectorcall
	_PyEval_EvalFrameDefault
	
	PyObject_Call
	_PyEval_EvalFrameDefault
	_PyFunction_Vectorcall
	_PyEval_EvalFrameDefault
	_PyFunction_Vectorcall
	_PyEval_EvalFrameDefault
	_PyFunction_Vectorcall
	
	
	_PyEval_EvalFrameDefault
	_PyFunction_Vectorcall
	_PyEval_EvalFrameDefault
	_PyFunction_Vectorcall
	_PyEval_EvalFrameDefault
	
	PyEval_EvalCode
	
	
	
	_PyRun_SimpleFileObject
	_PyRun_AnyFileObject
	Py_RunMain
	Py_BytesMain
	__libc_start_main
	
*** End stack trace ***

2024-03-17 15:25:19.783949: E external/xla/xla/status_macros.cc:54] INTERNAL: RET_CHECK failure (external/xla/xla/service/gpu/fusions/fusion_emitter.cc:96) device_info.block_dim_limit().x == 0 || launch_dims.block_counts().x < device_info.block_dim_limit().x Kernel 'input_concatenate_fusion' launch needs more blocks (4294967295) than allowed by hardware (2147483647).
*** Begin stack trace ***
	
	
	
	
	
	
	
	
	
	
	
	
	
	
	
	
	
	
	
	
	
	
	
	
	
	
	
	
	
	
	_PyObject_MakeTpCall
	
	_PyEval_EvalFrameDefault
	_PyFunction_Vectorcall
	_PyEval_EvalFrameDefault
	_PyFunction_Vectorcall
	_PyEval_EvalFrameDefault
	_PyFunction_Vectorcall
	_PyEval_EvalFrameDefault
	_PyFunction_Vectorcall
	_PyEval_EvalFrameDefault
	_PyFunction_Vectorcall
	
	
	
	
	
	
	
	
	_PyObject_MakeTpCall
	
	
	_PyObject_MakeTpCall
	_PyEval_EvalFrameDefault
	_PyFunction_Vectorcall
	PyObject_Call
	_PyEval_EvalFrameDefault
	_PyFunction_Vectorcall
	_PyEval_EvalFrameDefault
	_PyFunction_Vectorcall
	PyObject_Call
	_PyEval_EvalFrameDefault
	_PyFunction_Vectorcall
	
	
	_PyEval_EvalFrameDefault
	_PyFunction_Vectorcall
	PyObject_Call
	_PyEval_EvalFrameDefault
	_PyFunction_Vectorcall
	_PyEval_EvalFrameDefault
	_PyFunction_Vectorcall
	_PyEval_EvalFrameDefault
	
	PyObject_Call
	_PyEval_EvalFrameDefault
	_PyFunction_Vectorcall
	_PyEval_EvalFrameDefault
	_PyFunction_Vectorcall
	_PyEval_EvalFrameDefault
	_PyFunction_Vectorcall
	
	
	_PyEval_EvalFrameDefault
	_PyFunction_Vectorcall
	_PyEval_EvalFrameDefault
	_PyFunction_Vectorcall
	_PyEval_EvalFrameDefault
	
	PyEval_EvalCode
	
	
	
	_PyRun_SimpleFileObject
	_PyRun_AnyFileObject
	Py_RunMain
	Py_BytesMain
	__libc_start_main
	
*** End stack trace ***

2024-03-17 15:25:19.783957: E external/xla/xla/status_macros.cc:54] INTERNAL: RET_CHECK failure (external/xla/xla/service/gpu/fusions/fusion_emitter.cc:96) device_info.block_dim_limit().x == 0 || launch_dims.block_counts().x < device_info.block_dim_limit().x Kernel 'input_concatenate_fusion' launch needs more blocks (4294967295) than allowed by hardware (2147483647).
*** Begin stack trace ***
	
	
	
	
	
	
	
	
	
	
	
	
	
	
	
	
	
	
	
	
	
	
	
	
	
	
	
	
	
	
	_PyObject_MakeTpCall
	
	_PyEval_EvalFrameDefault
	_PyFunction_Vectorcall
	_PyEval_EvalFrameDefault
	_PyFunction_Vectorcall
	_PyEval_EvalFrameDefault
	_PyFunction_Vectorcall
	_PyEval_EvalFrameDefault
	_PyFunction_Vectorcall
	_PyEval_EvalFrameDefault
	_PyFunction_Vectorcall
	
	
	
	
	
	
	
	
	_PyObject_MakeTpCall
	
	
	_PyObject_MakeTpCall
	_PyEval_EvalFrameDefault
	_PyFunction_Vectorcall
	PyObject_Call
	_PyEval_EvalFrameDefault
	_PyFunction_Vectorcall
	_PyEval_EvalFrameDefault
	_PyFunction_Vectorcall
	PyObject_Call
	_PyEval_EvalFrameDefault
	_PyFunction_Vectorcall
	
	
	_PyEval_EvalFrameDefault
	_PyFunction_Vectorcall
	PyObject_Call
	_PyEval_EvalFrameDefault
	_PyFunction_Vectorcall
	_PyEval_EvalFrameDefault
	_PyFunction_Vectorcall
	_PyEval_EvalFrameDefault
	
	PyObject_Call
	_PyEval_EvalFrameDefault
	_PyFunction_Vectorcall
	_PyEval_EvalFrameDefault
	_PyFunction_Vectorcall
	_PyEval_EvalFrameDefault
	_PyFunction_Vectorcall
	
	
	_PyEval_EvalFrameDefault
	_PyFunction_Vectorcall
	_PyEval_EvalFrameDefault
	_PyFunction_Vectorcall
	_PyEval_EvalFrameDefault
	
	PyEval_EvalCode
	
	
	
	_PyRun_SimpleFileObject
	_PyRun_AnyFileObject
	Py_RunMain
	Py_BytesMain
	__libc_start_main
	
*** End stack trace ***

jax.errors.SimplifiedTraceback: For simplicity, JAX has removed its internal frames from the traceback of the following exception. Set JAX_TRACEBACK_FILTERING=off to include these.

The above exception was the direct cause of the following exception:

Traceback (most recent call last):
  File "/gpfsdswork/projects/rech/tkc/commun/jaxDecomp/benchmarks/pfft3d.py", line 168, in <module>
    run_benchmark(pdims, global_shape, backend, nb_nodes, output_path)
  File "/gpfsdswork/projects/rech/tkc/commun/jaxDecomp/benchmarks/pfft3d.py", line 32, in run_benchmark
    array = jax.random.normal(
  File "/gpfsdswork/projects/rech/tkc/commun/jaxDecomp/venv/v100/lib/python3.10/site-packages/jax/_src/random.py", line 720, in normal
    return _normal(key, shape, dtype)  # type: ignore
jaxlib.xla_extension.XlaRuntimeError: INTERNAL: RET_CHECK failure (external/xla/xla/service/gpu/fusions/fusion_emitter.cc:96) device_info.block_dim_limit().x == 0 || launch_dims.block_counts().x < device_info.block_dim_limit().x Kernel 'input_concatenate_fusion' launch needs more blocks (4294967295) than allowed by hardware (2147483647).
jax.errors.SimplifiedTraceback: For simplicity, JAX has removed its internal frames from the traceback of the following exception. Set JAX_TRACEBACK_FILTERING=off to include these.

The above exception was the direct cause of the following exception:

Traceback (most recent call last):
  File "/gpfsdswork/projects/rech/tkc/commun/jaxDecomp/benchmarks/pfft3d.py", line 168, in <module>
    run_benchmark(pdims, global_shape, backend, nb_nodes, output_path)
  File "/gpfsdswork/projects/rech/tkc/commun/jaxDecomp/benchmarks/pfft3d.py", line 32, in run_benchmark
    array = jax.random.normal(
  File "/gpfsdswork/projects/rech/tkc/commun/jaxDecomp/venv/v100/lib/python3.10/site-packages/jax/_src/random.py", line 720, in normal
    return _normal(key, shape, dtype)  # type: ignore
jaxlib.xla_extension.XlaRuntimeError: INTERNAL: RET_CHECK failure (external/xla/xla/service/gpu/fusions/fusion_emitter.cc:96) device_info.block_dim_limit().x == 0 || launch_dims.block_counts().x < device_info.block_dim_limit().x Kernel 'input_concatenate_fusion' launch needs more blocks (4294967295) than allowed by hardware (2147483647).
jax.errors.SimplifiedTraceback: For simplicity, JAX has removed its internal frames from the traceback of the following exception. Set JAX_TRACEBACK_FILTERING=off to include these.

The above exception was the direct cause of the following exception:

Traceback (most recent call last):
  File "/gpfsdswork/projects/rech/tkc/commun/jaxDecomp/benchmarks/pfft3d.py", line 168, in <module>
    run_benchmark(pdims, global_shape, backend, nb_nodes, output_path)
  File "/gpfsdswork/projects/rech/tkc/commun/jaxDecomp/benchmarks/pfft3d.py", line 32, in run_benchmark
    array = jax.random.normal(
  File "/gpfsdswork/projects/rech/tkc/commun/jaxDecomp/venv/v100/lib/python3.10/site-packages/jax/_src/random.py", line 720, in normal
    return _normal(key, shape, dtype)  # type: ignore
jaxlib.xla_extension.XlaRuntimeError: INTERNAL: RET_CHECK failure (external/xla/xla/service/gpu/fusions/fusion_emitter.cc:96) device_info.block_dim_limit().x == 0 || launch_dims.block_counts().x < device_info.block_dim_limit().x Kernel 'input_concatenate_fusion' launch needs more blocks (4294967295) than allowed by hardware (2147483647).
jax.errors.SimplifiedTraceback: For simplicity, JAX has removed its internal frames from the traceback of the following exception. Set JAX_TRACEBACK_FILTERING=off to include these.

The above exception was the direct cause of the following exception:

Traceback (most recent call last):
  File "/gpfsdswork/projects/rech/tkc/commun/jaxDecomp/benchmarks/pfft3d.py", line 168, in <module>
    run_benchmark(pdims, global_shape, backend, nb_nodes, output_path)
  File "/gpfsdswork/projects/rech/tkc/commun/jaxDecomp/benchmarks/pfft3d.py", line 32, in run_benchmark
    array = jax.random.normal(
  File "/gpfsdswork/projects/rech/tkc/commun/jaxDecomp/venv/v100/lib/python3.10/site-packages/jax/_src/random.py", line 720, in normal
    return _normal(key, shape, dtype)  # type: ignore
jaxlib.xla_extension.XlaRuntimeError: INTERNAL: RET_CHECK failure (external/xla/xla/service/gpu/fusions/fusion_emitter.cc:96) device_info.block_dim_limit().x == 0 || launch_dims.block_counts().x < device_info.block_dim_limit().x Kernel 'input_concatenate_fusion' launch needs more blocks (4294967295) than allowed by hardware (2147483647).
2024-03-17 15:25:19.794517: W external/xla/xla/service/hlo_rematerialization.cc:2941] Can't reduce memory use below -1.88TiB (-2064790164282 bytes) by rematerialization; only reduced to 8.00TiB (8796093022576 bytes), down from 8.00TiB (8796093022736 bytes) originally
2024-03-17 15:25:19.795548: W external/xla/xla/service/hlo_rematerialization.cc:2941] Can't reduce memory use below -1.88TiB (-2064790164282 bytes) by rematerialization; only reduced to 8.00TiB (8796093022576 bytes), down from 8.00TiB (8796093022736 bytes) originally
2024-03-17 15:25:19.795931: W external/xla/xla/service/hlo_rematerialization.cc:2941] Can't reduce memory use below -1.88TiB (-2064790164282 bytes) by rematerialization; only reduced to 8.00TiB (8796093022576 bytes), down from 8.00TiB (8796093022736 bytes) originally
2024-03-17 15:25:19.798547: E external/xla/xla/status_macros.cc:54] INTERNAL: RET_CHECK failure (external/xla/xla/service/gpu/fusions/fusion_emitter.cc:96) device_info.block_dim_limit().x == 0 || launch_dims.block_counts().x < device_info.block_dim_limit().x Kernel 'input_concatenate_fusion' launch needs more blocks (4294967295) than allowed by hardware (2147483647).
*** Begin stack trace ***
	
	
	
	
	
	
	
	
	
	
	
	
	
	
	
	
	
	
	
	
	
	
	
	
	
	
	
	
	
	
	_PyObject_MakeTpCall
	
	_PyEval_EvalFrameDefault
	_PyFunction_Vectorcall
	_PyEval_EvalFrameDefault
	_PyFunction_Vectorcall
	_PyEval_EvalFrameDefault
	_PyFunction_Vectorcall
	_PyEval_EvalFrameDefault
	_PyFunction_Vectorcall
	_PyEval_EvalFrameDefault
	_PyFunction_Vectorcall
	
	
	
	
	
	
	
	
	_PyObject_MakeTpCall
	
	
	_PyObject_MakeTpCall
	_PyEval_EvalFrameDefault
	_PyFunction_Vectorcall
	PyObject_Call
	_PyEval_EvalFrameDefault
	_PyFunction_Vectorcall
	_PyEval_EvalFrameDefault
	_PyFunction_Vectorcall
	PyObject_Call
	_PyEval_EvalFrameDefault
	_PyFunction_Vectorcall
	
	
	_PyEval_EvalFrameDefault
	_PyFunction_Vectorcall
	PyObject_Call
	_PyEval_EvalFrameDefault
	_PyFunction_Vectorcall
	_PyEval_EvalFrameDefault
	_PyFunction_Vectorcall
	_PyEval_EvalFrameDefault
	
	PyObject_Call
	_PyEval_EvalFrameDefault
	_PyFunction_Vectorcall
	_PyEval_EvalFrameDefault
	_PyFunction_Vectorcall
	_PyEval_EvalFrameDefault
	_PyFunction_Vectorcall
	
	
	_PyEval_EvalFrameDefault
	_PyFunction_Vectorcall
	_PyEval_EvalFrameDefault
	_PyFunction_Vectorcall
	_PyEval_EvalFrameDefault
	
	PyEval_EvalCode
	
	
	
	_PyRun_SimpleFileObject
	_PyRun_AnyFileObject
	Py_RunMain
	Py_BytesMain
	__libc_start_main
	
*** End stack trace ***

2024-03-17 15:25:19.798526: E external/xla/xla/status_macros.cc:54] INTERNAL: RET_CHECK failure (external/xla/xla/service/gpu/fusions/fusion_emitter.cc:96) device_info.block_dim_limit().x == 0 || launch_dims.block_counts().x < device_info.block_dim_limit().x Kernel 'input_concatenate_fusion' launch needs more blocks (4294967295) than allowed by hardware (2147483647).
*** Begin stack trace ***
	
	
	
	
	
	
	
	
	
	
	
	
	
	
	
	
	
	
	
	
	
	
	
	
	
	
	
	
	
	
	_PyObject_MakeTpCall
	
	_PyEval_EvalFrameDefault
	_PyFunction_Vectorcall
	_PyEval_EvalFrameDefault
	_PyFunction_Vectorcall
	_PyEval_EvalFrameDefault
	_PyFunction_Vectorcall
	_PyEval_EvalFrameDefault
	_PyFunction_Vectorcall
	_PyEval_EvalFrameDefault
	_PyFunction_Vectorcall
	
	
	
	
	
	
	
	
	_PyObject_MakeTpCall
	
	
	_PyObject_MakeTpCall
	_PyEval_EvalFrameDefault
	_PyFunction_Vectorcall
	PyObject_Call
	_PyEval_EvalFrameDefault
	_PyFunction_Vectorcall
	_PyEval_EvalFrameDefault
	_PyFunction_Vectorcall
	PyObject_Call
	_PyEval_EvalFrameDefault
	_PyFunction_Vectorcall
	
	
	_PyEval_EvalFrameDefault
	_PyFunction_Vectorcall
	PyObject_Call
	_PyEval_EvalFrameDefault
	_PyFunction_Vectorcall
	_PyEval_EvalFrameDefault
	_PyFunction_Vectorcall
	_PyEval_EvalFrameDefault
	
	PyObject_Call
	_PyEval_EvalFrameDefault
	_PyFunction_Vectorcall
	_PyEval_EvalFrameDefault
	_PyFunction_Vectorcall
	_PyEval_EvalFrameDefault
	_PyFunction_Vectorcall
	
	
	_PyEval_EvalFrameDefault
	_PyFunction_Vectorcall
	_PyEval_EvalFrameDefault
	_PyFunction_Vectorcall
	_PyEval_EvalFrameDefault
	
	PyEval_EvalCode
	
	
	
	_PyRun_SimpleFileObject
	_PyRun_AnyFileObject
	Py_RunMain
	Py_BytesMain
	__libc_start_main
	
*** End stack trace ***

2024-03-17 15:25:19.799679: E external/xla/xla/status_macros.cc:54] INTERNAL: RET_CHECK failure (external/xla/xla/service/gpu/fusions/fusion_emitter.cc:96) device_info.block_dim_limit().x == 0 || launch_dims.block_counts().x < device_info.block_dim_limit().x Kernel 'input_concatenate_fusion' launch needs more blocks (4294967295) than allowed by hardware (2147483647).
*** Begin stack trace ***
	
	
	
	
	
	
	
	
	
	
	
	
	
	
	
	
	
	
	
	
	
	
	
	
	
	
	
	
	
	
	_PyObject_MakeTpCall
	
	_PyEval_EvalFrameDefault
	_PyFunction_Vectorcall
	_PyEval_EvalFrameDefault
	_PyFunction_Vectorcall
	_PyEval_EvalFrameDefault
	_PyFunction_Vectorcall
	_PyEval_EvalFrameDefault
	_PyFunction_Vectorcall
	_PyEval_EvalFrameDefault
	_PyFunction_Vectorcall
	
	
	
	
	
	
	
	
	_PyObject_MakeTpCall
	
	
	_PyObject_MakeTpCall
	_PyEval_EvalFrameDefault
	_PyFunction_Vectorcall
	PyObject_Call
	_PyEval_EvalFrameDefault
	_PyFunction_Vectorcall
	_PyEval_EvalFrameDefault
	_PyFunction_Vectorcall
	PyObject_Call
	_PyEval_EvalFrameDefault
	_PyFunction_Vectorcall
	
	
	_PyEval_EvalFrameDefault
	_PyFunction_Vectorcall
	PyObject_Call
	_PyEval_EvalFrameDefault
	_PyFunction_Vectorcall
	_PyEval_EvalFrameDefault
	_PyFunction_Vectorcall
	_PyEval_EvalFrameDefault
	
	PyObject_Call
	_PyEval_EvalFrameDefault
	_PyFunction_Vectorcall
	_PyEval_EvalFrameDefault
	_PyFunction_Vectorcall
	_PyEval_EvalFrameDefault
	_PyFunction_Vectorcall
	
	
	_PyEval_EvalFrameDefault
	_PyFunction_Vectorcall
	_PyEval_EvalFrameDefault
	_PyFunction_Vectorcall
	_PyEval_EvalFrameDefault
	
	PyEval_EvalCode
	
	
	
	_PyRun_SimpleFileObject
	_PyRun_AnyFileObject
	Py_RunMain
	Py_BytesMain
	__libc_start_main
	
*** End stack trace ***

2024-03-17 15:25:19.800010: E external/xla/xla/status_macros.cc:54] INTERNAL: RET_CHECK failure (external/xla/xla/service/gpu/fusions/fusion_emitter.cc:96) device_info.block_dim_limit().x == 0 || launch_dims.block_counts().x < device_info.block_dim_limit().x Kernel 'input_concatenate_fusion' launch needs more blocks (4294967295) than allowed by hardware (2147483647).
*** Begin stack trace ***
	
	
	
	
	
	
	
	
	
	
	
	
	
	
	
	
	
	
	
	
	
	
	
	
	
	
	
	
	
	
	_PyObject_MakeTpCall
	
	_PyEval_EvalFrameDefault
	_PyFunction_Vectorcall
	_PyEval_EvalFrameDefault
	_PyFunction_Vectorcall
	_PyEval_EvalFrameDefault
	_PyFunction_Vectorcall
	_PyEval_EvalFrameDefault
	_PyFunction_Vectorcall
	_PyEval_EvalFrameDefault
	_PyFunction_Vectorcall
	
	
	
	
	
	
	
	
	_PyObject_MakeTpCall
	
	
	_PyObject_MakeTpCall
	_PyEval_EvalFrameDefault
	_PyFunction_Vectorcall
	PyObject_Call
	_PyEval_EvalFrameDefault
	_PyFunction_Vectorcall
	_PyEval_EvalFrameDefault
	_PyFunction_Vectorcall
	PyObject_Call
	_PyEval_EvalFrameDefault
	_PyFunction_Vectorcall
	
	
	_PyEval_EvalFrameDefault
	_PyFunction_Vectorcall
	PyObject_Call
	_PyEval_EvalFrameDefault
	_PyFunction_Vectorcall
	_PyEval_EvalFrameDefault
	_PyFunction_Vectorcall
	_PyEval_EvalFrameDefault
	
	PyObject_Call
	_PyEval_EvalFrameDefault
	_PyFunction_Vectorcall
	_PyEval_EvalFrameDefault
	_PyFunction_Vectorcall
	_PyEval_EvalFrameDefault
	_PyFunction_Vectorcall
	
	
	_PyEval_EvalFrameDefault
	_PyFunction_Vectorcall
	_PyEval_EvalFrameDefault
	_PyFunction_Vectorcall
	_PyEval_EvalFrameDefault
	
	PyEval_EvalCode
	
	
	
	_PyRun_SimpleFileObject
	_PyRun_AnyFileObject
	Py_RunMain
	Py_BytesMain
	__libc_start_main
	
*** End stack trace ***

jax.errors.SimplifiedTraceback: For simplicity, JAX has removed its internal frames from the traceback of the following exception. Set JAX_TRACEBACK_FILTERING=off to include these.

The above exception was the direct cause of the following exception:

Traceback (most recent call last):
  File "/gpfsdswork/projects/rech/tkc/commun/jaxDecomp/benchmarks/pfft3d.py", line 168, in <module>
    run_benchmark(pdims, global_shape, backend, nb_nodes, output_path)
  File "/gpfsdswork/projects/rech/tkc/commun/jaxDecomp/benchmarks/pfft3d.py", line 32, in run_benchmark
    array = jax.random.normal(
  File "/gpfsdswork/projects/rech/tkc/commun/jaxDecomp/venv/v100/lib/python3.10/site-packages/jax/_src/random.py", line 720, in normal
    return _normal(key, shape, dtype)  # type: ignore
jaxlib.xla_extension.XlaRuntimeError: INTERNAL: RET_CHECK failure (external/xla/xla/service/gpu/fusions/fusion_emitter.cc:96) device_info.block_dim_limit().x == 0 || launch_dims.block_counts().x < device_info.block_dim_limit().x Kernel 'input_concatenate_fusion' launch needs more blocks (4294967295) than allowed by hardware (2147483647).
jax.errors.SimplifiedTraceback: For simplicity, JAX has removed its internal frames from the traceback of the following exception. Set JAX_TRACEBACK_FILTERING=off to include these.

The above exception was the direct cause of the following exception:

Traceback (most recent call last):
  File "/gpfsdswork/projects/rech/tkc/commun/jaxDecomp/benchmarks/pfft3d.py", line 168, in <module>
    run_benchmark(pdims, global_shape, backend, nb_nodes, output_path)
  File "/gpfsdswork/projects/rech/tkc/commun/jaxDecomp/benchmarks/pfft3d.py", line 32, in run_benchmark
    array = jax.random.normal(
  File "/gpfsdswork/projects/rech/tkc/commun/jaxDecomp/venv/v100/lib/python3.10/site-packages/jax/_src/random.py", line 720, in normal
    return _normal(key, shape, dtype)  # type: ignore
jaxlib.xla_extension.XlaRuntimeError: INTERNAL: RET_CHECK failure (external/xla/xla/service/gpu/fusions/fusion_emitter.cc:96) device_info.block_dim_limit().x == 0 || launch_dims.block_counts().x < device_info.block_dim_limit().x Kernel 'input_concatenate_fusion' launch needs more blocks (4294967295) than allowed by hardware (2147483647).
jax.errors.SimplifiedTraceback: For simplicity, JAX has removed its internal frames from the traceback of the following exception. Set JAX_TRACEBACK_FILTERING=off to include these.

The above exception was the direct cause of the following exception:

Traceback (most recent call last):
  File "/gpfsdswork/projects/rech/tkc/commun/jaxDecomp/benchmarks/pfft3d.py", line 168, in <module>
    run_benchmark(pdims, global_shape, backend, nb_nodes, output_path)
  File "/gpfsdswork/projects/rech/tkc/commun/jaxDecomp/benchmarks/pfft3d.py", line 32, in run_benchmark
    array = jax.random.normal(
  File "/gpfsdswork/projects/rech/tkc/commun/jaxDecomp/venv/v100/lib/python3.10/site-packages/jax/_src/random.py", line 720, in normal
    return _normal(key, shape, dtype)  # type: ignore
jaxlib.xla_extension.XlaRuntimeError: INTERNAL: RET_CHECK failure (external/xla/xla/service/gpu/fusions/fusion_emitter.cc:96) device_info.block_dim_limit().x == 0 || launch_dims.block_counts().x < device_info.block_dim_limit().x Kernel 'input_concatenate_fusion' launch needs more blocks (4294967295) than allowed by hardware (2147483647).
jax.errors.SimplifiedTraceback: For simplicity, JAX has removed its internal frames from the traceback of the following exception. Set JAX_TRACEBACK_FILTERING=off to include these.

The above exception was the direct cause of the following exception:

Traceback (most recent call last):
  File "/gpfsdswork/projects/rech/tkc/commun/jaxDecomp/benchmarks/pfft3d.py", line 168, in <module>
    run_benchmark(pdims, global_shape, backend, nb_nodes, output_path)
  File "/gpfsdswork/projects/rech/tkc/commun/jaxDecomp/benchmarks/pfft3d.py", line 32, in run_benchmark
    array = jax.random.normal(
  File "/gpfsdswork/projects/rech/tkc/commun/jaxDecomp/venv/v100/lib/python3.10/site-packages/jax/_src/random.py", line 720, in normal
    return _normal(key, shape, dtype)  # type: ignore
jaxlib.xla_extension.XlaRuntimeError: INTERNAL: RET_CHECK failure (external/xla/xla/service/gpu/fusions/fusion_emitter.cc:96) device_info.block_dim_limit().x == 0 || launch_dims.block_counts().x < device_info.block_dim_limit().x Kernel 'input_concatenate_fusion' launch needs more blocks (4294967295) than allowed by hardware (2147483647).
srun: error: r7i6n7: tasks 4-7: Exited with exit code 1
srun: Terminating StepId=1124578.31
slurmstepd: error: *** STEP 1124578.31 ON r7i1n0 CANCELLED AT 2024-03-17T15:25:20 ***
srun: error: r7i1n0: tasks 0-3: Exited with exit code 1
