2024-03-17 16:39:23.929568: W external/xla/xla/service/hlo_rematerialization.cc:2941] Can't reduce memory use below -7.58TiB (-8332006442606 bytes) by rematerialization; only reduced to 32.00TiB (35184372090768 bytes), down from 32.00TiB (35184372090896 bytes) originally
2024-03-17 16:39:23.940538: W external/xla/xla/service/hlo_rematerialization.cc:2941] Can't reduce memory use below -7.58TiB (-8332006442606 bytes) by rematerialization; only reduced to 32.00TiB (35184372090768 bytes), down from 32.00TiB (35184372090896 bytes) originally
2024-03-17 16:39:23.958758: W external/xla/xla/service/hlo_rematerialization.cc:2941] Can't reduce memory use below -7.58TiB (-8332006442606 bytes) by rematerialization; only reduced to 32.00TiB (35184372090768 bytes), down from 32.00TiB (35184372090896 bytes) originally
2024-03-17 16:39:23.933499: E external/xla/xla/status_macros.cc:54] INTERNAL: RET_CHECK failure (external/xla/xla/service/gpu/fusions/fusion_emitter.cc:96) device_info.block_dim_limit().x == 0 || launch_dims.block_counts().x < device_info.block_dim_limit().x Kernel 'loop_broadcast_fusion_2_remat2_1' launch needs more blocks (2147483648) than allowed by hardware (2147483647).
*** Begin stack trace ***
	
	
	
	
	
	
	
	
	
	
	
	
	
	
	
	
	
	
	
	
	
	
	
	
	
	
	
	
	
	
	
	
	
	_PyObject_MakeTpCall
	
	_PyEval_EvalFrameDefault
	_PyFunction_Vectorcall
	_PyEval_EvalFrameDefault
	_PyFunction_Vectorcall
	_PyEval_EvalFrameDefault
	_PyFunction_Vectorcall
	_PyEval_EvalFrameDefault
	_PyFunction_Vectorcall
	_PyEval_EvalFrameDefault
	_PyFunction_Vectorcall
	
	
	
	
	
	
	
	
	_PyObject_MakeTpCall
	
	
	_PyObject_MakeTpCall
	_PyEval_EvalFrameDefault
	_PyFunction_Vectorcall
	PyObject_Call
	_PyEval_EvalFrameDefault
	_PyFunction_Vectorcall
	_PyEval_EvalFrameDefault
	_PyFunction_Vectorcall
	PyObject_Call
	_PyEval_EvalFrameDefault
	_PyFunction_Vectorcall
	
	
	_PyEval_EvalFrameDefault
	_PyFunction_Vectorcall
	PyObject_Call
	_PyEval_EvalFrameDefault
	_PyFunction_Vectorcall
	_PyEval_EvalFrameDefault
	_PyFunction_Vectorcall
	_PyEval_EvalFrameDefault
	
	PyObject_Call
	_PyEval_EvalFrameDefault
	_PyFunction_Vectorcall
	_PyEval_EvalFrameDefault
	_PyFunction_Vectorcall
	_PyEval_EvalFrameDefault
	_PyFunction_Vectorcall
	
	
	_PyEval_EvalFrameDefault
	_PyFunction_Vectorcall
	_PyEval_EvalFrameDefault
	_PyFunction_Vectorcall
	_PyEval_EvalFrameDefault
	
	PyEval_EvalCode
	
	
	
	_PyRun_SimpleFileObject
	_PyRun_AnyFileObject
	Py_RunMain
	Py_BytesMain
	__libc_start_main
	
*** End stack trace ***

jax.errors.SimplifiedTraceback: For simplicity, JAX has removed its internal frames from the traceback of the following exception. Set JAX_TRACEBACK_FILTERING=off to include these.

The above exception was the direct cause of the following exception:

Traceback (most recent call last):
  File "/gpfsdswork/projects/rech/tkc/commun/jaxDecomp/benchmarks/pfft3d.py", line 168, in <module>
    run_benchmark(pdims, global_shape, backend, nb_nodes, output_path)
  File "/gpfsdswork/projects/rech/tkc/commun/jaxDecomp/benchmarks/pfft3d.py", line 32, in run_benchmark
    array = jax.random.normal(
  File "/gpfsdswork/projects/rech/tkc/commun/jaxDecomp/venv/v100/lib/python3.10/site-packages/jax/_src/random.py", line 720, in normal
    return _normal(key, shape, dtype)  # type: ignore
jaxlib.xla_extension.XlaRuntimeError: INTERNAL: RET_CHECK failure (external/xla/xla/service/gpu/fusions/fusion_emitter.cc:96) device_info.block_dim_limit().x == 0 || launch_dims.block_counts().x < device_info.block_dim_limit().x Kernel 'loop_broadcast_fusion_2_remat2_1' launch needs more blocks (2147483648) than allowed by hardware (2147483647).
2024-03-17 16:39:23.963005: W external/xla/xla/service/hlo_rematerialization.cc:2941] Can't reduce memory use below -7.58TiB (-8332006442606 bytes) by rematerialization; only reduced to 32.00TiB (35184372090768 bytes), down from 32.00TiB (35184372090896 bytes) originally
2024-03-17 16:39:23.962995: W external/xla/xla/service/hlo_rematerialization.cc:2941] Can't reduce memory use below -7.58TiB (-8332006442606 bytes) by rematerialization; only reduced to 32.00TiB (35184372090768 bytes), down from 32.00TiB (35184372090896 bytes) originally
2024-03-17 16:39:23.966915: E external/xla/xla/status_macros.cc:54] INTERNAL: RET_CHECK failure (external/xla/xla/service/gpu/fusions/fusion_emitter.cc:96) device_info.block_dim_limit().x == 0 || launch_dims.block_counts().x < device_info.block_dim_limit().x Kernel 'loop_broadcast_fusion_2_remat2_1' launch needs more blocks (2147483648) than allowed by hardware (2147483647).
*** Begin stack trace ***
	
	
	
	
	
	
	
	
	
	
	
	
	
	
	
	
	
	
	
	
	
	
	
	
	
	
	
	
	
	
	
	
	
	_PyObject_MakeTpCall
	
	_PyEval_EvalFrameDefault
	_PyFunction_Vectorcall
	_PyEval_EvalFrameDefault
	_PyFunction_Vectorcall
	_PyEval_EvalFrameDefault
	_PyFunction_Vectorcall
	_PyEval_EvalFrameDefault
	_PyFunction_Vectorcall
	_PyEval_EvalFrameDefault
	_PyFunction_Vectorcall
	
	
	
	
	
	
	
	
	_PyObject_MakeTpCall
	
	
	_PyObject_MakeTpCall
	_PyEval_EvalFrameDefault
	_PyFunction_Vectorcall
	PyObject_Call
	_PyEval_EvalFrameDefault
	_PyFunction_Vectorcall
	_PyEval_EvalFrameDefault
	_PyFunction_Vectorcall
	PyObject_Call
	_PyEval_EvalFrameDefault
	_PyFunction_Vectorcall
	
	
	_PyEval_EvalFrameDefault
	_PyFunction_Vectorcall
	PyObject_Call
	_PyEval_EvalFrameDefault
	_PyFunction_Vectorcall
	_PyEval_EvalFrameDefault
	_PyFunction_Vectorcall
	_PyEval_EvalFrameDefault
	
	PyObject_Call
	_PyEval_EvalFrameDefault
	_PyFunction_Vectorcall
	_PyEval_EvalFrameDefault
	_PyFunction_Vectorcall
	_PyEval_EvalFrameDefault
	_PyFunction_Vectorcall
	
	
	_PyEval_EvalFrameDefault
	_PyFunction_Vectorcall
	_PyEval_EvalFrameDefault
	_PyFunction_Vectorcall
	_PyEval_EvalFrameDefault
	
	PyEval_EvalCode
	
	
	
	_PyRun_SimpleFileObject
	_PyRun_AnyFileObject
	Py_RunMain
	Py_BytesMain
	__libc_start_main
	
*** End stack trace ***

2024-03-17 16:39:23.966901: E external/xla/xla/status_macros.cc:54] INTERNAL: RET_CHECK failure (external/xla/xla/service/gpu/fusions/fusion_emitter.cc:96) device_info.block_dim_limit().x == 0 || launch_dims.block_counts().x < device_info.block_dim_limit().x Kernel 'loop_broadcast_fusion_2_remat2_1' launch needs more blocks (2147483648) than allowed by hardware (2147483647).
*** Begin stack trace ***
	
	
	
	
	
	
	
	
	
	
	
	
	
	
	
	
	
	
	
	
	
	
	
	
	
	
	
	
	
	
	
	
	
	_PyObject_MakeTpCall
	
	_PyEval_EvalFrameDefault
	_PyFunction_Vectorcall
	_PyEval_EvalFrameDefault
	_PyFunction_Vectorcall
	_PyEval_EvalFrameDefault
	_PyFunction_Vectorcall
	_PyEval_EvalFrameDefault
	_PyFunction_Vectorcall
	_PyEval_EvalFrameDefault
	_PyFunction_Vectorcall
	
	
	
	
	
	
	
	
	_PyObject_MakeTpCall
	
	
	_PyObject_MakeTpCall
	_PyEval_EvalFrameDefault
	_PyFunction_Vectorcall
	PyObject_Call
	_PyEval_EvalFrameDefault
	_PyFunction_Vectorcall
	_PyEval_EvalFrameDefault
	_PyFunction_Vectorcall
	PyObject_Call
	_PyEval_EvalFrameDefault
	_PyFunction_Vectorcall
	
	
	_PyEval_EvalFrameDefault
	_PyFunction_Vectorcall
	PyObject_Call
	_PyEval_EvalFrameDefault
	_PyFunction_Vectorcall
	_PyEval_EvalFrameDefault
	_PyFunction_Vectorcall
	_PyEval_EvalFrameDefault
	
	PyObject_Call
	_PyEval_EvalFrameDefault
	_PyFunction_Vectorcall
	_PyEval_EvalFrameDefault
	_PyFunction_Vectorcall
	_PyEval_EvalFrameDefault
	_PyFunction_Vectorcall
	
	
	_PyEval_EvalFrameDefault
	_PyFunction_Vectorcall
	_PyEval_EvalFrameDefault
	_PyFunction_Vectorcall
	_PyEval_EvalFrameDefault
	
	PyEval_EvalCode
	
	
	
	_PyRun_SimpleFileObject
	_PyRun_AnyFileObject
	Py_RunMain
	Py_BytesMain
	__libc_start_main
	
*** End stack trace ***

2024-03-17 16:39:23.967282: W external/xla/xla/service/hlo_rematerialization.cc:2941] Can't reduce memory use below -7.58TiB (-8332006442606 bytes) by rematerialization; only reduced to 32.00TiB (35184372090768 bytes), down from 32.00TiB (35184372090896 bytes) originally
2024-03-17 16:39:23.971079: E external/xla/xla/status_macros.cc:54] INTERNAL: RET_CHECK failure (external/xla/xla/service/gpu/fusions/fusion_emitter.cc:96) device_info.block_dim_limit().x == 0 || launch_dims.block_counts().x < device_info.block_dim_limit().x Kernel 'loop_broadcast_fusion_2_remat2_1' launch needs more blocks (2147483648) than allowed by hardware (2147483647).
*** Begin stack trace ***
	
	
	
	
	
	
	
	
	
	
	
	
	
	
	
	
	
	
	
	
	
	
	
	
	
	
	
	
	
	
	
	
	
	_PyObject_MakeTpCall
	
	_PyEval_EvalFrameDefault
	_PyFunction_Vectorcall
	_PyEval_EvalFrameDefault
	_PyFunction_Vectorcall
	_PyEval_EvalFrameDefault
	_PyFunction_Vectorcall
	_PyEval_EvalFrameDefault
	_PyFunction_Vectorcall
	_PyEval_EvalFrameDefault
	_PyFunction_Vectorcall
	
	
	
	
	
	
	
	
	_PyObject_MakeTpCall
	
	
	_PyObject_MakeTpCall
	_PyEval_EvalFrameDefault
	_PyFunction_Vectorcall
	PyObject_Call
	_PyEval_EvalFrameDefault
	_PyFunction_Vectorcall
	_PyEval_EvalFrameDefault
	_PyFunction_Vectorcall
	PyObject_Call
	_PyEval_EvalFrameDefault
	_PyFunction_Vectorcall
	
	
	_PyEval_EvalFrameDefault
	_PyFunction_Vectorcall
	PyObject_Call
	_PyEval_EvalFrameDefault
	_PyFunction_Vectorcall
	_PyEval_EvalFrameDefault
	_PyFunction_Vectorcall
	_PyEval_EvalFrameDefault
	
	PyObject_Call
	_PyEval_EvalFrameDefault
	_PyFunction_Vectorcall
	_PyEval_EvalFrameDefault
	_PyFunction_Vectorcall
	_PyEval_EvalFrameDefault
	_PyFunction_Vectorcall
	
	
	_PyEval_EvalFrameDefault
	_PyFunction_Vectorcall
	_PyEval_EvalFrameDefault
	_PyFunction_Vectorcall
	_PyEval_EvalFrameDefault
	
	PyEval_EvalCode
	
	
	
	_PyRun_SimpleFileObject
	_PyRun_AnyFileObject
	Py_RunMain
	Py_BytesMain
	__libc_start_main
	
*** End stack trace ***

2024-03-17 16:39:23.980464: W external/xla/xla/service/hlo_rematerialization.cc:2941] Can't reduce memory use below -7.58TiB (-8332006442606 bytes) by rematerialization; only reduced to 32.00TiB (35184372090768 bytes), down from 32.00TiB (35184372090896 bytes) originally
2024-03-17 16:39:23.940518: W external/xla/xla/service/hlo_rematerialization.cc:2941] Can't reduce memory use below -7.58TiB (-8332006442606 bytes) by rematerialization; only reduced to 32.00TiB (35184372090768 bytes), down from 32.00TiB (35184372090896 bytes) originally
2024-03-17 16:39:23.944487: E external/xla/xla/status_macros.cc:54] INTERNAL: RET_CHECK failure (external/xla/xla/service/gpu/fusions/fusion_emitter.cc:96) device_info.block_dim_limit().x == 0 || launch_dims.block_counts().x < device_info.block_dim_limit().x Kernel 'loop_broadcast_fusion_2_remat2_1' launch needs more blocks (2147483648) than allowed by hardware (2147483647).
*** Begin stack trace ***
	
	
	
	
	
	
	
	
	
	
	
	
	
	
	
	
	
	
	
	
	
	
	
	
	
	
	
	
	
	
	
	
	
	_PyObject_MakeTpCall
	
	_PyEval_EvalFrameDefault
	_PyFunction_Vectorcall
	_PyEval_EvalFrameDefault
	_PyFunction_Vectorcall
	_PyEval_EvalFrameDefault
	_PyFunction_Vectorcall
	_PyEval_EvalFrameDefault
	_PyFunction_Vectorcall
	_PyEval_EvalFrameDefault
	_PyFunction_Vectorcall
	
	
	
	
	
	
	
	
	_PyObject_MakeTpCall
	
	
	_PyObject_MakeTpCall
	_PyEval_EvalFrameDefault
	_PyFunction_Vectorcall
	PyObject_Call
	_PyEval_EvalFrameDefault
	_PyFunction_Vectorcall
	_PyEval_EvalFrameDefault
	_PyFunction_Vectorcall
	PyObject_Call
	_PyEval_EvalFrameDefault
	_PyFunction_Vectorcall
	
	
	_PyEval_EvalFrameDefault
	_PyFunction_Vectorcall
	PyObject_Call
	_PyEval_EvalFrameDefault
	_PyFunction_Vectorcall
	_PyEval_EvalFrameDefault
	_PyFunction_Vectorcall
	_PyEval_EvalFrameDefault
	
	PyObject_Call
	_PyEval_EvalFrameDefault
	_PyFunction_Vectorcall
	_PyEval_EvalFrameDefault
	_PyFunction_Vectorcall
	_PyEval_EvalFrameDefault
	_PyFunction_Vectorcall
	
	
	_PyEval_EvalFrameDefault
	_PyFunction_Vectorcall
	_PyEval_EvalFrameDefault
	_PyFunction_Vectorcall
	_PyEval_EvalFrameDefault
	
	PyEval_EvalCode
	
	
	
	_PyRun_SimpleFileObject
	_PyRun_AnyFileObject
	Py_RunMain
	Py_BytesMain
	__libc_start_main
	
*** End stack trace ***

2024-03-17 16:39:23.944498: E external/xla/xla/status_macros.cc:54] INTERNAL: RET_CHECK failure (external/xla/xla/service/gpu/fusions/fusion_emitter.cc:96) device_info.block_dim_limit().x == 0 || launch_dims.block_counts().x < device_info.block_dim_limit().x Kernel 'loop_broadcast_fusion_2_remat2_1' launch needs more blocks (2147483648) than allowed by hardware (2147483647).
*** Begin stack trace ***
	
	
	
	
	
	
	
	
	
	
	
	
	
	
	
	
	
	
	
	
	
	
	
	
	
	
	
	
	
	
	
	
	
	_PyObject_MakeTpCall
	
	_PyEval_EvalFrameDefault
	_PyFunction_Vectorcall
	_PyEval_EvalFrameDefault
	_PyFunction_Vectorcall
	_PyEval_EvalFrameDefault
	_PyFunction_Vectorcall
	_PyEval_EvalFrameDefault
	_PyFunction_Vectorcall
	_PyEval_EvalFrameDefault
	_PyFunction_Vectorcall
	
	
	
	
	
	
	
	
	_PyObject_MakeTpCall
	
	
	_PyObject_MakeTpCall
	_PyEval_EvalFrameDefault
	_PyFunction_Vectorcall
	PyObject_Call
	_PyEval_EvalFrameDefault
	_PyFunction_Vectorcall
	_PyEval_EvalFrameDefault
	_PyFunction_Vectorcall
	PyObject_Call
	_PyEval_EvalFrameDefault
	_PyFunction_Vectorcall
	
	
	_PyEval_EvalFrameDefault
	_PyFunction_Vectorcall
	PyObject_Call
	_PyEval_EvalFrameDefault
	_PyFunction_Vectorcall
	_PyEval_EvalFrameDefault
	_PyFunction_Vectorcall
	_PyEval_EvalFrameDefault
	
	PyObject_Call
	_PyEval_EvalFrameDefault
	_PyFunction_Vectorcall
	_PyEval_EvalFrameDefault
	_PyFunction_Vectorcall
	_PyEval_EvalFrameDefault
	_PyFunction_Vectorcall
	
	
	_PyEval_EvalFrameDefault
	_PyFunction_Vectorcall
	_PyEval_EvalFrameDefault
	_PyFunction_Vectorcall
	_PyEval_EvalFrameDefault
	
	PyEval_EvalCode
	
	
	
	_PyRun_SimpleFileObject
	_PyRun_AnyFileObject
	Py_RunMain
	Py_BytesMain
	__libc_start_main
	
*** End stack trace ***

2024-03-17 16:39:23.952561: W external/xla/xla/service/hlo_rematerialization.cc:2941] Can't reduce memory use below -7.58TiB (-8332006442606 bytes) by rematerialization; only reduced to 32.00TiB (35184372090768 bytes), down from 32.00TiB (35184372090896 bytes) originally
2024-03-17 16:39:23.952677: W external/xla/xla/service/hlo_rematerialization.cc:2941] Can't reduce memory use below -7.58TiB (-8332006442606 bytes) by rematerialization; only reduced to 32.00TiB (35184372090768 bytes), down from 32.00TiB (35184372090896 bytes) originally
2024-03-17 16:39:23.956432: E external/xla/xla/status_macros.cc:54] INTERNAL: RET_CHECK failure (external/xla/xla/service/gpu/fusions/fusion_emitter.cc:96) device_info.block_dim_limit().x == 0 || launch_dims.block_counts().x < device_info.block_dim_limit().x Kernel 'loop_broadcast_fusion_2_remat2_1' launch needs more blocks (2147483648) than allowed by hardware (2147483647).
*** Begin stack trace ***
	
	
	
	
	
	
	
	
	
	
	
	
	
	
	
	
	
	
	
	
	
	
	
	
	
	
	
	
	
	
	
	
	
	_PyObject_MakeTpCall
	
	_PyEval_EvalFrameDefault
	_PyFunction_Vectorcall
	_PyEval_EvalFrameDefault
	_PyFunction_Vectorcall
	_PyEval_EvalFrameDefault
	_PyFunction_Vectorcall
	_PyEval_EvalFrameDefault
	_PyFunction_Vectorcall
	_PyEval_EvalFrameDefault
	_PyFunction_Vectorcall
	
	
	
	
	
	
	
	
	_PyObject_MakeTpCall
	
	
	_PyObject_MakeTpCall
	_PyEval_EvalFrameDefault
	_PyFunction_Vectorcall
	PyObject_Call
	_PyEval_EvalFrameDefault
	_PyFunction_Vectorcall
	_PyEval_EvalFrameDefault
	_PyFunction_Vectorcall
	PyObject_Call
	_PyEval_EvalFrameDefault
	_PyFunction_Vectorcall
	
	
	_PyEval_EvalFrameDefault
	_PyFunction_Vectorcall
	PyObject_Call
	_PyEval_EvalFrameDefault
	_PyFunction_Vectorcall
	_PyEval_EvalFrameDefault
	_PyFunction_Vectorcall
	_PyEval_EvalFrameDefault
	
	PyObject_Call
	_PyEval_EvalFrameDefault
	_PyFunction_Vectorcall
	_PyEval_EvalFrameDefault
	_PyFunction_Vectorcall
	_PyEval_EvalFrameDefault
	_PyFunction_Vectorcall
	
	
	_PyEval_EvalFrameDefault
	_PyFunction_Vectorcall
	_PyEval_EvalFrameDefault
	_PyFunction_Vectorcall
	_PyEval_EvalFrameDefault
	
	PyEval_EvalCode
	
	
	
	_PyRun_SimpleFileObject
	_PyRun_AnyFileObject
	Py_RunMain
	Py_BytesMain
	__libc_start_main
	
*** End stack trace ***

2024-03-17 16:39:23.956494: E external/xla/xla/status_macros.cc:54] INTERNAL: RET_CHECK failure (external/xla/xla/service/gpu/fusions/fusion_emitter.cc:96) device_info.block_dim_limit().x == 0 || launch_dims.block_counts().x < device_info.block_dim_limit().x Kernel 'loop_broadcast_fusion_2_remat2_1' launch needs more blocks (2147483648) than allowed by hardware (2147483647).
*** Begin stack trace ***
	
	
	
	
	
	
	
	
	
	
	
	
	
	
	
	
	
	
	
	
	
	
	
	
	
	
	
	
	
	
	
	
	
	_PyObject_MakeTpCall
	
	_PyEval_EvalFrameDefault
	_PyFunction_Vectorcall
	_PyEval_EvalFrameDefault
	_PyFunction_Vectorcall
	_PyEval_EvalFrameDefault
	_PyFunction_Vectorcall
	_PyEval_EvalFrameDefault
	_PyFunction_Vectorcall
	_PyEval_EvalFrameDefault
	_PyFunction_Vectorcall
	
	
	
	
	
	
	
	
	_PyObject_MakeTpCall
	
	
	_PyObject_MakeTpCall
	_PyEval_EvalFrameDefault
	_PyFunction_Vectorcall
	PyObject_Call
	_PyEval_EvalFrameDefault
	_PyFunction_Vectorcall
	_PyEval_EvalFrameDefault
	_PyFunction_Vectorcall
	PyObject_Call
	_PyEval_EvalFrameDefault
	_PyFunction_Vectorcall
	
	
	_PyEval_EvalFrameDefault
	_PyFunction_Vectorcall
	PyObject_Call
	_PyEval_EvalFrameDefault
	_PyFunction_Vectorcall
	_PyEval_EvalFrameDefault
	_PyFunction_Vectorcall
	_PyEval_EvalFrameDefault
	
	PyObject_Call
	_PyEval_EvalFrameDefault
	_PyFunction_Vectorcall
	_PyEval_EvalFrameDefault
	_PyFunction_Vectorcall
	_PyEval_EvalFrameDefault
	_PyFunction_Vectorcall
	
	
	_PyEval_EvalFrameDefault
	_PyFunction_Vectorcall
	_PyEval_EvalFrameDefault
	_PyFunction_Vectorcall
	_PyEval_EvalFrameDefault
	
	PyEval_EvalCode
	
	
	
	_PyRun_SimpleFileObject
	_PyRun_AnyFileObject
	Py_RunMain
	Py_BytesMain
	__libc_start_main
	
*** End stack trace ***

jax.errors.SimplifiedTraceback: For simplicity, JAX has removed its internal frames from the traceback of the following exception. Set JAX_TRACEBACK_FILTERING=off to include these.

The above exception was the direct cause of the following exception:

Traceback (most recent call last):
  File "/gpfsdswork/projects/rech/tkc/commun/jaxDecomp/benchmarks/pfft3d.py", line 168, in <module>
    run_benchmark(pdims, global_shape, backend, nb_nodes, output_path)
  File "/gpfsdswork/projects/rech/tkc/commun/jaxDecomp/benchmarks/pfft3d.py", line 32, in run_benchmark
    array = jax.random.normal(
  File "/gpfsdswork/projects/rech/tkc/commun/jaxDecomp/venv/v100/lib/python3.10/site-packages/jax/_src/random.py", line 720, in normal
    return _normal(key, shape, dtype)  # type: ignore
jaxlib.xla_extension.XlaRuntimeError: INTERNAL: RET_CHECK failure (external/xla/xla/service/gpu/fusions/fusion_emitter.cc:96) device_info.block_dim_limit().x == 0 || launch_dims.block_counts().x < device_info.block_dim_limit().x Kernel 'loop_broadcast_fusion_2_remat2_1' launch needs more blocks (2147483648) than allowed by hardware (2147483647).
jax.errors.SimplifiedTraceback: For simplicity, JAX has removed its internal frames from the traceback of the following exception. Set JAX_TRACEBACK_FILTERING=off to include these.

The above exception was the direct cause of the following exception:

Traceback (most recent call last):
  File "/gpfsdswork/projects/rech/tkc/commun/jaxDecomp/benchmarks/pfft3d.py", line 168, in <module>
    run_benchmark(pdims, global_shape, backend, nb_nodes, output_path)
  File "/gpfsdswork/projects/rech/tkc/commun/jaxDecomp/benchmarks/pfft3d.py", line 32, in run_benchmark
    array = jax.random.normal(
  File "/gpfsdswork/projects/rech/tkc/commun/jaxDecomp/venv/v100/lib/python3.10/site-packages/jax/_src/random.py", line 720, in normal
    return _normal(key, shape, dtype)  # type: ignore
jaxlib.xla_extension.XlaRuntimeError: INTERNAL: RET_CHECK failure (external/xla/xla/service/gpu/fusions/fusion_emitter.cc:96) device_info.block_dim_limit().x == 0 || launch_dims.block_counts().x < device_info.block_dim_limit().x Kernel 'loop_broadcast_fusion_2_remat2_1' launch needs more blocks (2147483648) than allowed by hardware (2147483647).
jax.errors.SimplifiedTraceback: For simplicity, JAX has removed its internal frames from the traceback of the following exception. Set JAX_TRACEBACK_FILTERING=off to include these.

The above exception was the direct cause of the following exception:

Traceback (most recent call last):
  File "/gpfsdswork/projects/rech/tkc/commun/jaxDecomp/benchmarks/pfft3d.py", line 168, in <module>
    run_benchmark(pdims, global_shape, backend, nb_nodes, output_path)
  File "/gpfsdswork/projects/rech/tkc/commun/jaxDecomp/benchmarks/pfft3d.py", line 32, in run_benchmark
    array = jax.random.normal(
  File "/gpfsdswork/projects/rech/tkc/commun/jaxDecomp/venv/v100/lib/python3.10/site-packages/jax/_src/random.py", line 720, in normal
    return _normal(key, shape, dtype)  # type: ignore
jaxlib.xla_extension.XlaRuntimeError: INTERNAL: RET_CHECK failure (external/xla/xla/service/gpu/fusions/fusion_emitter.cc:96) device_info.block_dim_limit().x == 0 || launch_dims.block_counts().x < device_info.block_dim_limit().x Kernel 'loop_broadcast_fusion_2_remat2_1' launch needs more blocks (2147483648) than allowed by hardware (2147483647).
jax.errors.SimplifiedTraceback: For simplicity, JAX has removed its internal frames from the traceback of the following exception. Set JAX_TRACEBACK_FILTERING=off to include these.

The above exception was the direct cause of the following exception:

Traceback (most recent call last):
  File "/gpfsdswork/projects/rech/tkc/commun/jaxDecomp/benchmarks/pfft3d.py", line 168, in <module>
    run_benchmark(pdims, global_shape, backend, nb_nodes, output_path)
  File "/gpfsdswork/projects/rech/tkc/commun/jaxDecomp/benchmarks/pfft3d.py", line 32, in run_benchmark
    array = jax.random.normal(
  File "/gpfsdswork/projects/rech/tkc/commun/jaxDecomp/venv/v100/lib/python3.10/site-packages/jax/_src/random.py", line 720, in normal
    return _normal(key, shape, dtype)  # type: ignore
jaxlib.xla_extension.XlaRuntimeError: INTERNAL: RET_CHECK failure (external/xla/xla/service/gpu/fusions/fusion_emitter.cc:96) device_info.block_dim_limit().x == 0 || launch_dims.block_counts().x < device_info.block_dim_limit().x Kernel 'loop_broadcast_fusion_2_remat2_1' launch needs more blocks (2147483648) than allowed by hardware (2147483647).
jax.errors.SimplifiedTraceback: For simplicity, JAX has removed its internal frames from the traceback of the following exception. Set JAX_TRACEBACK_FILTERING=off to include these.

The above exception was the direct cause of the following exception:

Traceback (most recent call last):
  File "/gpfsdswork/projects/rech/tkc/commun/jaxDecomp/benchmarks/pfft3d.py", line 168, in <module>
    run_benchmark(pdims, global_shape, backend, nb_nodes, output_path)
  File "/gpfsdswork/projects/rech/tkc/commun/jaxDecomp/benchmarks/pfft3d.py", line 32, in run_benchmark
    array = jax.random.normal(
  File "/gpfsdswork/projects/rech/tkc/commun/jaxDecomp/venv/v100/lib/python3.10/site-packages/jax/_src/random.py", line 720, in normal
    return _normal(key, shape, dtype)  # type: ignore
jaxlib.xla_extension.XlaRuntimeError: INTERNAL: RET_CHECK failure (external/xla/xla/service/gpu/fusions/fusion_emitter.cc:96) device_info.block_dim_limit().x == 0 || launch_dims.block_counts().x < device_info.block_dim_limit().x Kernel 'loop_broadcast_fusion_2_remat2_1' launch needs more blocks (2147483648) than allowed by hardware (2147483647).
jax.errors.SimplifiedTraceback: For simplicity, JAX has removed its internal frames from the traceback of the following exception. Set JAX_TRACEBACK_FILTERING=off to include these.

The above exception was the direct cause of the following exception:

Traceback (most recent call last):
  File "/gpfsdswork/projects/rech/tkc/commun/jaxDecomp/benchmarks/pfft3d.py", line 168, in <module>
    run_benchmark(pdims, global_shape, backend, nb_nodes, output_path)
  File "/gpfsdswork/projects/rech/tkc/commun/jaxDecomp/benchmarks/pfft3d.py", line 32, in run_benchmark
    array = jax.random.normal(
  File "/gpfsdswork/projects/rech/tkc/commun/jaxDecomp/venv/v100/lib/python3.10/site-packages/jax/_src/random.py", line 720, in normal
    return _normal(key, shape, dtype)  # type: ignore
jaxlib.xla_extension.XlaRuntimeError: INTERNAL: RET_CHECK failure (external/xla/xla/service/gpu/fusions/fusion_emitter.cc:96) device_info.block_dim_limit().x == 0 || launch_dims.block_counts().x < device_info.block_dim_limit().x Kernel 'loop_broadcast_fusion_2_remat2_1' launch needs more blocks (2147483648) than allowed by hardware (2147483647).
jax.errors.SimplifiedTraceback: For simplicity, JAX has removed its internal frames from the traceback of the following exception. Set JAX_TRACEBACK_FILTERING=off to include these.

The above exception was the direct cause of the following exception:

Traceback (most recent call last):
  File "/gpfsdswork/projects/rech/tkc/commun/jaxDecomp/benchmarks/pfft3d.py", line 168, in <module>
    run_benchmark(pdims, global_shape, backend, nb_nodes, output_path)
  File "/gpfsdswork/projects/rech/tkc/commun/jaxDecomp/benchmarks/pfft3d.py", line 32, in run_benchmark
    array = jax.random.normal(
  File "/gpfsdswork/projects/rech/tkc/commun/jaxDecomp/venv/v100/lib/python3.10/site-packages/jax/_src/random.py", line 720, in normal
    return _normal(key, shape, dtype)  # type: ignore
jaxlib.xla_extension.XlaRuntimeError: INTERNAL: RET_CHECK failure (external/xla/xla/service/gpu/fusions/fusion_emitter.cc:96) device_info.block_dim_limit().x == 0 || launch_dims.block_counts().x < device_info.block_dim_limit().x Kernel 'loop_broadcast_fusion_2_remat2_1' launch needs more blocks (2147483648) than allowed by hardware (2147483647).
2024-03-17 16:39:23.959010: W external/xla/xla/service/hlo_rematerialization.cc:2941] Can't reduce memory use below -7.58TiB (-8332006442606 bytes) by rematerialization; only reduced to 32.00TiB (35184372090768 bytes), down from 32.00TiB (35184372090896 bytes) originally
2024-03-17 16:39:23.962681: E external/xla/xla/status_macros.cc:54] INTERNAL: RET_CHECK failure (external/xla/xla/service/gpu/fusions/fusion_emitter.cc:96) device_info.block_dim_limit().x == 0 || launch_dims.block_counts().x < device_info.block_dim_limit().x Kernel 'loop_broadcast_fusion_2_remat2_1' launch needs more blocks (2147483648) than allowed by hardware (2147483647).
*** Begin stack trace ***
	
	
	
	
	
	
	
	
	
	
	
	
	
	
	
	
	
	
	
	
	
	
	
	
	
	
	
	
	
	
	
	
	
	_PyObject_MakeTpCall
	
	_PyEval_EvalFrameDefault
	_PyFunction_Vectorcall
	_PyEval_EvalFrameDefault
	_PyFunction_Vectorcall
	_PyEval_EvalFrameDefault
	_PyFunction_Vectorcall
	_PyEval_EvalFrameDefault
	_PyFunction_Vectorcall
	_PyEval_EvalFrameDefault
	_PyFunction_Vectorcall
	
	
	
	
	
	
	
	
	_PyObject_MakeTpCall
	
	
	_PyObject_MakeTpCall
	_PyEval_EvalFrameDefault
	_PyFunction_Vectorcall
	PyObject_Call
	_PyEval_EvalFrameDefault
	_PyFunction_Vectorcall
	_PyEval_EvalFrameDefault
	_PyFunction_Vectorcall
	PyObject_Call
	_PyEval_EvalFrameDefault
	_PyFunction_Vectorcall
	
	
	_PyEval_EvalFrameDefault
	_PyFunction_Vectorcall
	PyObject_Call
	_PyEval_EvalFrameDefault
	_PyFunction_Vectorcall
	_PyEval_EvalFrameDefault
	_PyFunction_Vectorcall
	_PyEval_EvalFrameDefault
	
	PyObject_Call
	_PyEval_EvalFrameDefault
	_PyFunction_Vectorcall
	_PyEval_EvalFrameDefault
	_PyFunction_Vectorcall
	_PyEval_EvalFrameDefault
	_PyFunction_Vectorcall
	
	
	_PyEval_EvalFrameDefault
	_PyFunction_Vectorcall
	_PyEval_EvalFrameDefault
	_PyFunction_Vectorcall
	_PyEval_EvalFrameDefault
	
	PyEval_EvalCode
	
	
	
	_PyRun_SimpleFileObject
	_PyRun_AnyFileObject
	Py_RunMain
	Py_BytesMain
	__libc_start_main
	
*** End stack trace ***

2024-03-17 16:39:23.962806: E external/xla/xla/status_macros.cc:54] INTERNAL: RET_CHECK failure (external/xla/xla/service/gpu/fusions/fusion_emitter.cc:96) device_info.block_dim_limit().x == 0 || launch_dims.block_counts().x < device_info.block_dim_limit().x Kernel 'loop_broadcast_fusion_2_remat2_1' launch needs more blocks (2147483648) than allowed by hardware (2147483647).
*** Begin stack trace ***
	
	
	
	
	
	
	
	
	
	
	
	
	
	
	
	
	
	
	
	
	
	
	
	
	
	
	
	
	
	
	
	
	
	_PyObject_MakeTpCall
	
	_PyEval_EvalFrameDefault
	_PyFunction_Vectorcall
	_PyEval_EvalFrameDefault
	_PyFunction_Vectorcall
	_PyEval_EvalFrameDefault
	_PyFunction_Vectorcall
	_PyEval_EvalFrameDefault
	_PyFunction_Vectorcall
	_PyEval_EvalFrameDefault
	_PyFunction_Vectorcall
	
	
	
	
	
	
	
	
	_PyObject_MakeTpCall
	
	
	_PyObject_MakeTpCall
	_PyEval_EvalFrameDefault
	_PyFunction_Vectorcall
	PyObject_Call
	_PyEval_EvalFrameDefault
	_PyFunction_Vectorcall
	_PyEval_EvalFrameDefault
	_PyFunction_Vectorcall
	PyObject_Call
	_PyEval_EvalFrameDefault
	_PyFunction_Vectorcall
	
	
	_PyEval_EvalFrameDefault
	_PyFunction_Vectorcall
	PyObject_Call
	_PyEval_EvalFrameDefault
	_PyFunction_Vectorcall
	_PyEval_EvalFrameDefault
	_PyFunction_Vectorcall
	_PyEval_EvalFrameDefault
	
	PyObject_Call
	_PyEval_EvalFrameDefault
	_PyFunction_Vectorcall
	_PyEval_EvalFrameDefault
	_PyFunction_Vectorcall
	_PyEval_EvalFrameDefault
	_PyFunction_Vectorcall
	
	
	_PyEval_EvalFrameDefault
	_PyFunction_Vectorcall
	_PyEval_EvalFrameDefault
	_PyFunction_Vectorcall
	_PyEval_EvalFrameDefault
	
	PyEval_EvalCode
	
	
	
	_PyRun_SimpleFileObject
	_PyRun_AnyFileObject
	Py_RunMain
	Py_BytesMain
	__libc_start_main
	
*** End stack trace ***

2024-03-17 16:39:23.972125: W external/xla/xla/service/hlo_rematerialization.cc:2941] Can't reduce memory use below -7.58TiB (-8332006442606 bytes) by rematerialization; only reduced to 32.00TiB (35184372090768 bytes), down from 32.00TiB (35184372090896 bytes) originally
2024-03-17 16:39:23.972156: W external/xla/xla/service/hlo_rematerialization.cc:2941] Can't reduce memory use below -7.58TiB (-8332006442606 bytes) by rematerialization; only reduced to 32.00TiB (35184372090768 bytes), down from 32.00TiB (35184372090896 bytes) originally
2024-03-17 16:39:23.976057: E external/xla/xla/status_macros.cc:54] INTERNAL: RET_CHECK failure (external/xla/xla/service/gpu/fusions/fusion_emitter.cc:96) device_info.block_dim_limit().x == 0 || launch_dims.block_counts().x < device_info.block_dim_limit().x Kernel 'loop_broadcast_fusion_2_remat2_1' launch needs more blocks (2147483648) than allowed by hardware (2147483647).
*** Begin stack trace ***
	
	
	
	
	
	
	
	
	
	
	
	
	
	
	
	
	
	
	
	
	
	
	
	
	
	
	
	
	
	
	
	
	
	_PyObject_MakeTpCall
	
	_PyEval_EvalFrameDefault
	_PyFunction_Vectorcall
	_PyEval_EvalFrameDefault
	_PyFunction_Vectorcall
	_PyEval_EvalFrameDefault
	_PyFunction_Vectorcall
	_PyEval_EvalFrameDefault
	_PyFunction_Vectorcall
	_PyEval_EvalFrameDefault
	_PyFunction_Vectorcall
	
	
	
	
	
	
	
	
	_PyObject_MakeTpCall
	
	
	_PyObject_MakeTpCall
	_PyEval_EvalFrameDefault
	_PyFunction_Vectorcall
	PyObject_Call
	_PyEval_EvalFrameDefault
	_PyFunction_Vectorcall
	_PyEval_EvalFrameDefault
	_PyFunction_Vectorcall
	PyObject_Call
	_PyEval_EvalFrameDefault
	_PyFunction_Vectorcall
	
	
	_PyEval_EvalFrameDefault
	_PyFunction_Vectorcall
	PyObject_Call
	_PyEval_EvalFrameDefault
	_PyFunction_Vectorcall
	_PyEval_EvalFrameDefault
	_PyFunction_Vectorcall
	_PyEval_EvalFrameDefault
	
	PyObject_Call
	_PyEval_EvalFrameDefault
	_PyFunction_Vectorcall
	_PyEval_EvalFrameDefault
	_PyFunction_Vectorcall
	_PyEval_EvalFrameDefault
	_PyFunction_Vectorcall
	
	
	_PyEval_EvalFrameDefault
	_PyFunction_Vectorcall
	_PyEval_EvalFrameDefault
	_PyFunction_Vectorcall
	_PyEval_EvalFrameDefault
	
	PyEval_EvalCode
	
	
	
	_PyRun_SimpleFileObject
	_PyRun_AnyFileObject
	Py_RunMain
	Py_BytesMain
	__libc_start_main
	
*** End stack trace ***

2024-03-17 16:39:23.976061: E external/xla/xla/status_macros.cc:54] INTERNAL: RET_CHECK failure (external/xla/xla/service/gpu/fusions/fusion_emitter.cc:96) device_info.block_dim_limit().x == 0 || launch_dims.block_counts().x < device_info.block_dim_limit().x Kernel 'loop_broadcast_fusion_2_remat2_1' launch needs more blocks (2147483648) than allowed by hardware (2147483647).
*** Begin stack trace ***
	
	
	
	
	
	
	
	
	
	
	
	
	
	
	
	
	
	
	
	
	
	
	
	
	
	
	
	
	
	
	
	
	
	_PyObject_MakeTpCall
	
	_PyEval_EvalFrameDefault
	_PyFunction_Vectorcall
	_PyEval_EvalFrameDefault
	_PyFunction_Vectorcall
	_PyEval_EvalFrameDefault
	_PyFunction_Vectorcall
	_PyEval_EvalFrameDefault
	_PyFunction_Vectorcall
	_PyEval_EvalFrameDefault
	_PyFunction_Vectorcall
	
	
	
	
	
	
	
	
	_PyObject_MakeTpCall
	
	
	_PyObject_MakeTpCall
	_PyEval_EvalFrameDefault
	_PyFunction_Vectorcall
	PyObject_Call
	_PyEval_EvalFrameDefault
	_PyFunction_Vectorcall
	_PyEval_EvalFrameDefault
	_PyFunction_Vectorcall
	PyObject_Call
	_PyEval_EvalFrameDefault
	_PyFunction_Vectorcall
	
	
	_PyEval_EvalFrameDefault
	_PyFunction_Vectorcall
	PyObject_Call
	_PyEval_EvalFrameDefault
	_PyFunction_Vectorcall
	_PyEval_EvalFrameDefault
	_PyFunction_Vectorcall
	_PyEval_EvalFrameDefault
	
	PyObject_Call
	_PyEval_EvalFrameDefault
	_PyFunction_Vectorcall
	_PyEval_EvalFrameDefault
	_PyFunction_Vectorcall
	_PyEval_EvalFrameDefault
	_PyFunction_Vectorcall
	
	
	_PyEval_EvalFrameDefault
	_PyFunction_Vectorcall
	_PyEval_EvalFrameDefault
	_PyFunction_Vectorcall
	_PyEval_EvalFrameDefault
	
	PyEval_EvalCode
	
	
	
	_PyRun_SimpleFileObject
	_PyRun_AnyFileObject
	Py_RunMain
	Py_BytesMain
	__libc_start_main
	
*** End stack trace ***

jax.errors.SimplifiedTraceback: For simplicity, JAX has removed its internal frames from the traceback of the following exception. Set JAX_TRACEBACK_FILTERING=off to include these.

The above exception was the direct cause of the following exception:

Traceback (most recent call last):
  File "/gpfsdswork/projects/rech/tkc/commun/jaxDecomp/benchmarks/pfft3d.py", line 168, in <module>
    run_benchmark(pdims, global_shape, backend, nb_nodes, output_path)
  File "/gpfsdswork/projects/rech/tkc/commun/jaxDecomp/benchmarks/pfft3d.py", line 32, in run_benchmark
    array = jax.random.normal(
  File "/gpfsdswork/projects/rech/tkc/commun/jaxDecomp/venv/v100/lib/python3.10/site-packages/jax/_src/random.py", line 720, in normal
    return _normal(key, shape, dtype)  # type: ignore
jaxlib.xla_extension.XlaRuntimeError: INTERNAL: RET_CHECK failure (external/xla/xla/service/gpu/fusions/fusion_emitter.cc:96) device_info.block_dim_limit().x == 0 || launch_dims.block_counts().x < device_info.block_dim_limit().x Kernel 'loop_broadcast_fusion_2_remat2_1' launch needs more blocks (2147483648) than allowed by hardware (2147483647).
jax.errors.SimplifiedTraceback: For simplicity, JAX has removed its internal frames from the traceback of the following exception. Set JAX_TRACEBACK_FILTERING=off to include these.

The above exception was the direct cause of the following exception:

Traceback (most recent call last):
  File "/gpfsdswork/projects/rech/tkc/commun/jaxDecomp/benchmarks/pfft3d.py", line 168, in <module>
    run_benchmark(pdims, global_shape, backend, nb_nodes, output_path)
  File "/gpfsdswork/projects/rech/tkc/commun/jaxDecomp/benchmarks/pfft3d.py", line 32, in run_benchmark
    array = jax.random.normal(
  File "/gpfsdswork/projects/rech/tkc/commun/jaxDecomp/venv/v100/lib/python3.10/site-packages/jax/_src/random.py", line 720, in normal
    return _normal(key, shape, dtype)  # type: ignore
jaxlib.xla_extension.XlaRuntimeError: INTERNAL: RET_CHECK failure (external/xla/xla/service/gpu/fusions/fusion_emitter.cc:96) device_info.block_dim_limit().x == 0 || launch_dims.block_counts().x < device_info.block_dim_limit().x Kernel 'loop_broadcast_fusion_2_remat2_1' launch needs more blocks (2147483648) than allowed by hardware (2147483647).
jax.errors.SimplifiedTraceback: For simplicity, JAX has removed its internal frames from the traceback of the following exception. Set JAX_TRACEBACK_FILTERING=off to include these.

The above exception was the direct cause of the following exception:

Traceback (most recent call last):
  File "/gpfsdswork/projects/rech/tkc/commun/jaxDecomp/benchmarks/pfft3d.py", line 168, in <module>
    run_benchmark(pdims, global_shape, backend, nb_nodes, output_path)
  File "/gpfsdswork/projects/rech/tkc/commun/jaxDecomp/benchmarks/pfft3d.py", line 32, in run_benchmark
    array = jax.random.normal(
  File "/gpfsdswork/projects/rech/tkc/commun/jaxDecomp/venv/v100/lib/python3.10/site-packages/jax/_src/random.py", line 720, in normal
    return _normal(key, shape, dtype)  # type: ignore
jaxlib.xla_extension.XlaRuntimeError: INTERNAL: RET_CHECK failure (external/xla/xla/service/gpu/fusions/fusion_emitter.cc:96) device_info.block_dim_limit().x == 0 || launch_dims.block_counts().x < device_info.block_dim_limit().x Kernel 'loop_broadcast_fusion_2_remat2_1' launch needs more blocks (2147483648) than allowed by hardware (2147483647).
jax.errors.SimplifiedTraceback: For simplicity, JAX has removed its internal frames from the traceback of the following exception. Set JAX_TRACEBACK_FILTERING=off to include these.

The above exception was the direct cause of the following exception:

Traceback (most recent call last):
  File "/gpfsdswork/projects/rech/tkc/commun/jaxDecomp/benchmarks/pfft3d.py", line 168, in <module>
    run_benchmark(pdims, global_shape, backend, nb_nodes, output_path)
  File "/gpfsdswork/projects/rech/tkc/commun/jaxDecomp/benchmarks/pfft3d.py", line 32, in run_benchmark
    array = jax.random.normal(
  File "/gpfsdswork/projects/rech/tkc/commun/jaxDecomp/venv/v100/lib/python3.10/site-packages/jax/_src/random.py", line 720, in normal
    return _normal(key, shape, dtype)  # type: ignore
jaxlib.xla_extension.XlaRuntimeError: INTERNAL: RET_CHECK failure (external/xla/xla/service/gpu/fusions/fusion_emitter.cc:96) device_info.block_dim_limit().x == 0 || launch_dims.block_counts().x < device_info.block_dim_limit().x Kernel 'loop_broadcast_fusion_2_remat2_1' launch needs more blocks (2147483648) than allowed by hardware (2147483647).
2024-03-17 16:39:23.981360: W external/xla/xla/service/hlo_rematerialization.cc:2941] Can't reduce memory use below -7.58TiB (-8332006442606 bytes) by rematerialization; only reduced to 32.00TiB (35184372090768 bytes), down from 32.00TiB (35184372090896 bytes) originally
2024-03-17 16:39:23.981982: W external/xla/xla/service/hlo_rematerialization.cc:2941] Can't reduce memory use below -7.58TiB (-8332006442606 bytes) by rematerialization; only reduced to 32.00TiB (35184372090768 bytes), down from 32.00TiB (35184372090896 bytes) originally
2024-03-17 16:39:23.983074: W external/xla/xla/service/hlo_rematerialization.cc:2941] Can't reduce memory use below -7.58TiB (-8332006442606 bytes) by rematerialization; only reduced to 32.00TiB (35184372090768 bytes), down from 32.00TiB (35184372090896 bytes) originally
2024-03-17 16:39:23.984362: E external/xla/xla/status_macros.cc:54] INTERNAL: RET_CHECK failure (external/xla/xla/service/gpu/fusions/fusion_emitter.cc:96) device_info.block_dim_limit().x == 0 || launch_dims.block_counts().x < device_info.block_dim_limit().x Kernel 'loop_broadcast_fusion_2_remat2_1' launch needs more blocks (2147483648) than allowed by hardware (2147483647).
*** Begin stack trace ***
	
	
	
	
	
	
	
	
	
	
	
	
	
	
	
	
	
	
	
	
	
	
	
	
	
	
	
	
	
	
	
	
	
	_PyObject_MakeTpCall
	
	_PyEval_EvalFrameDefault
	_PyFunction_Vectorcall
	_PyEval_EvalFrameDefault
	_PyFunction_Vectorcall
	_PyEval_EvalFrameDefault
	_PyFunction_Vectorcall
	_PyEval_EvalFrameDefault
	_PyFunction_Vectorcall
	_PyEval_EvalFrameDefault
	_PyFunction_Vectorcall
	
	
	
	
	
	
	
	
	_PyObject_MakeTpCall
	
	
	_PyObject_MakeTpCall
	_PyEval_EvalFrameDefault
	_PyFunction_Vectorcall
	PyObject_Call
	_PyEval_EvalFrameDefault
	_PyFunction_Vectorcall
	_PyEval_EvalFrameDefault
	_PyFunction_Vectorcall
	PyObject_Call
	_PyEval_EvalFrameDefault
	_PyFunction_Vectorcall
	
	
	_PyEval_EvalFrameDefault
	_PyFunction_Vectorcall
	PyObject_Call
	_PyEval_EvalFrameDefault
	_PyFunction_Vectorcall
	_PyEval_EvalFrameDefault
	_PyFunction_Vectorcall
	_PyEval_EvalFrameDefault
	
	PyObject_Call
	_PyEval_EvalFrameDefault
	_PyFunction_Vectorcall
	_PyEval_EvalFrameDefault
	_PyFunction_Vectorcall
	_PyEval_EvalFrameDefault
	_PyFunction_Vectorcall
	
	
	_PyEval_EvalFrameDefault
	_PyFunction_Vectorcall
	_PyEval_EvalFrameDefault
	_PyFunction_Vectorcall
	_PyEval_EvalFrameDefault
	
	PyEval_EvalCode
	
	
	
	_PyRun_SimpleFileObject
	_PyRun_AnyFileObject
	Py_RunMain
	Py_BytesMain
	__libc_start_main
	
*** End stack trace ***

2024-03-17 16:39:23.985171: E external/xla/xla/status_macros.cc:54] INTERNAL: RET_CHECK failure (external/xla/xla/service/gpu/fusions/fusion_emitter.cc:96) device_info.block_dim_limit().x == 0 || launch_dims.block_counts().x < device_info.block_dim_limit().x Kernel 'loop_broadcast_fusion_2_remat2_1' launch needs more blocks (2147483648) than allowed by hardware (2147483647).
*** Begin stack trace ***
	
	
	
	
	
	
	
	
	
	
	
	
	
	
	
	
	
	
	
	
	
	
	
	
	
	
	
	
	
	
	
	
	
	_PyObject_MakeTpCall
	
	_PyEval_EvalFrameDefault
	_PyFunction_Vectorcall
	_PyEval_EvalFrameDefault
	_PyFunction_Vectorcall
	_PyEval_EvalFrameDefault
	_PyFunction_Vectorcall
	_PyEval_EvalFrameDefault
	_PyFunction_Vectorcall
	_PyEval_EvalFrameDefault
	_PyFunction_Vectorcall
	
	
	
	
	
	
	
	
	_PyObject_MakeTpCall
	
	
	_PyObject_MakeTpCall
	_PyEval_EvalFrameDefault
	_PyFunction_Vectorcall
	PyObject_Call
	_PyEval_EvalFrameDefault
	_PyFunction_Vectorcall
	_PyEval_EvalFrameDefault
	_PyFunction_Vectorcall
	PyObject_Call
	_PyEval_EvalFrameDefault
	_PyFunction_Vectorcall
	
	
	_PyEval_EvalFrameDefault
	_PyFunction_Vectorcall
	PyObject_Call
	_PyEval_EvalFrameDefault
	_PyFunction_Vectorcall
	_PyEval_EvalFrameDefault
	_PyFunction_Vectorcall
	_PyEval_EvalFrameDefault
	
	PyObject_Call
	_PyEval_EvalFrameDefault
	_PyFunction_Vectorcall
	_PyEval_EvalFrameDefault
	_PyFunction_Vectorcall
	_PyEval_EvalFrameDefault
	_PyFunction_Vectorcall
	
	
	_PyEval_EvalFrameDefault
	_PyFunction_Vectorcall
	_PyEval_EvalFrameDefault
	_PyFunction_Vectorcall
	_PyEval_EvalFrameDefault
	
	PyEval_EvalCode
	
	
	
	_PyRun_SimpleFileObject
	_PyRun_AnyFileObject
	Py_RunMain
	Py_BytesMain
	__libc_start_main
	
*** End stack trace ***

2024-03-17 16:39:23.985843: E external/xla/xla/status_macros.cc:54] INTERNAL: RET_CHECK failure (external/xla/xla/service/gpu/fusions/fusion_emitter.cc:96) device_info.block_dim_limit().x == 0 || launch_dims.block_counts().x < device_info.block_dim_limit().x Kernel 'loop_broadcast_fusion_2_remat2_1' launch needs more blocks (2147483648) than allowed by hardware (2147483647).
*** Begin stack trace ***
	
	
	
	
	
	
	
	
	
	
	
	
	
	
	
	
	
	
	
	
	
	
	
	
	
	
	
	
	
	
	
	
	
	_PyObject_MakeTpCall
	
	_PyEval_EvalFrameDefault
	_PyFunction_Vectorcall
	_PyEval_EvalFrameDefault
	_PyFunction_Vectorcall
	_PyEval_EvalFrameDefault
	_PyFunction_Vectorcall
	_PyEval_EvalFrameDefault
	_PyFunction_Vectorcall
	_PyEval_EvalFrameDefault
	_PyFunction_Vectorcall
	
	
	
	
	
	
	
	
	_PyObject_MakeTpCall
	
	
	_PyObject_MakeTpCall
	_PyEval_EvalFrameDefault
	_PyFunction_Vectorcall
	PyObject_Call
	_PyEval_EvalFrameDefault
	_PyFunction_Vectorcall
	_PyEval_EvalFrameDefault
	_PyFunction_Vectorcall
	PyObject_Call
	_PyEval_EvalFrameDefault
	_PyFunction_Vectorcall
	
	
	_PyEval_EvalFrameDefault
	_PyFunction_Vectorcall
	PyObject_Call
	_PyEval_EvalFrameDefault
	_PyFunction_Vectorcall
	_PyEval_EvalFrameDefault
	_PyFunction_Vectorcall
	_PyEval_EvalFrameDefault
	
	PyObject_Call
	_PyEval_EvalFrameDefault
	_PyFunction_Vectorcall
	_PyEval_EvalFrameDefault
	_PyFunction_Vectorcall
	_PyEval_EvalFrameDefault
	_PyFunction_Vectorcall
	
	
	_PyEval_EvalFrameDefault
	_PyFunction_Vectorcall
	_PyEval_EvalFrameDefault
	_PyFunction_Vectorcall
	_PyEval_EvalFrameDefault
	
	PyEval_EvalCode
	
	
	
	_PyRun_SimpleFileObject
	_PyRun_AnyFileObject
	Py_RunMain
	Py_BytesMain
	__libc_start_main
	
*** End stack trace ***

2024-03-17 16:39:23.986907: E external/xla/xla/status_macros.cc:54] INTERNAL: RET_CHECK failure (external/xla/xla/service/gpu/fusions/fusion_emitter.cc:96) device_info.block_dim_limit().x == 0 || launch_dims.block_counts().x < device_info.block_dim_limit().x Kernel 'loop_broadcast_fusion_2_remat2_1' launch needs more blocks (2147483648) than allowed by hardware (2147483647).
*** Begin stack trace ***
	
	
	
	
	
	
	
	
	
	
	
	
	
	
	
	
	
	
	
	
	
	
	
	
	
	
	
	
	
	
	
	
	
	_PyObject_MakeTpCall
	
	_PyEval_EvalFrameDefault
	_PyFunction_Vectorcall
	_PyEval_EvalFrameDefault
	_PyFunction_Vectorcall
	_PyEval_EvalFrameDefault
	_PyFunction_Vectorcall
	_PyEval_EvalFrameDefault
	_PyFunction_Vectorcall
	_PyEval_EvalFrameDefault
	_PyFunction_Vectorcall
	
	
	
	
	
	
	
	
	_PyObject_MakeTpCall
	
	
	_PyObject_MakeTpCall
	_PyEval_EvalFrameDefault
	_PyFunction_Vectorcall
	PyObject_Call
	_PyEval_EvalFrameDefault
	_PyFunction_Vectorcall
	_PyEval_EvalFrameDefault
	_PyFunction_Vectorcall
	PyObject_Call
	_PyEval_EvalFrameDefault
	_PyFunction_Vectorcall
	
	
	_PyEval_EvalFrameDefault
	_PyFunction_Vectorcall
	PyObject_Call
	_PyEval_EvalFrameDefault
	_PyFunction_Vectorcall
	_PyEval_EvalFrameDefault
	_PyFunction_Vectorcall
	_PyEval_EvalFrameDefault
	
	PyObject_Call
	_PyEval_EvalFrameDefault
	_PyFunction_Vectorcall
	_PyEval_EvalFrameDefault
	_PyFunction_Vectorcall
	_PyEval_EvalFrameDefault
	_PyFunction_Vectorcall
	
	
	_PyEval_EvalFrameDefault
	_PyFunction_Vectorcall
	_PyEval_EvalFrameDefault
	_PyFunction_Vectorcall
	_PyEval_EvalFrameDefault
	
	PyEval_EvalCode
	
	
	
	_PyRun_SimpleFileObject
	_PyRun_AnyFileObject
	Py_RunMain
	Py_BytesMain
	__libc_start_main
	
*** End stack trace ***

jax.errors.SimplifiedTraceback: For simplicity, JAX has removed its internal frames from the traceback of the following exception. Set JAX_TRACEBACK_FILTERING=off to include these.

The above exception was the direct cause of the following exception:

Traceback (most recent call last):
  File "/gpfsdswork/projects/rech/tkc/commun/jaxDecomp/benchmarks/pfft3d.py", line 168, in <module>
    run_benchmark(pdims, global_shape, backend, nb_nodes, output_path)
  File "/gpfsdswork/projects/rech/tkc/commun/jaxDecomp/benchmarks/pfft3d.py", line 32, in run_benchmark
    array = jax.random.normal(
  File "/gpfsdswork/projects/rech/tkc/commun/jaxDecomp/venv/v100/lib/python3.10/site-packages/jax/_src/random.py", line 720, in normal
    return _normal(key, shape, dtype)  # type: ignore
jaxlib.xla_extension.XlaRuntimeError: INTERNAL: RET_CHECK failure (external/xla/xla/service/gpu/fusions/fusion_emitter.cc:96) device_info.block_dim_limit().x == 0 || launch_dims.block_counts().x < device_info.block_dim_limit().x Kernel 'loop_broadcast_fusion_2_remat2_1' launch needs more blocks (2147483648) than allowed by hardware (2147483647).
jax.errors.SimplifiedTraceback: For simplicity, JAX has removed its internal frames from the traceback of the following exception. Set JAX_TRACEBACK_FILTERING=off to include these.

The above exception was the direct cause of the following exception:

Traceback (most recent call last):
  File "/gpfsdswork/projects/rech/tkc/commun/jaxDecomp/benchmarks/pfft3d.py", line 168, in <module>
    run_benchmark(pdims, global_shape, backend, nb_nodes, output_path)
  File "/gpfsdswork/projects/rech/tkc/commun/jaxDecomp/benchmarks/pfft3d.py", line 32, in run_benchmark
    array = jax.random.normal(
  File "/gpfsdswork/projects/rech/tkc/commun/jaxDecomp/venv/v100/lib/python3.10/site-packages/jax/_src/random.py", line 720, in normal
    return _normal(key, shape, dtype)  # type: ignore
jaxlib.xla_extension.XlaRuntimeError: INTERNAL: RET_CHECK failure (external/xla/xla/service/gpu/fusions/fusion_emitter.cc:96) device_info.block_dim_limit().x == 0 || launch_dims.block_counts().x < device_info.block_dim_limit().x Kernel 'loop_broadcast_fusion_2_remat2_1' launch needs more blocks (2147483648) than allowed by hardware (2147483647).
jax.errors.SimplifiedTraceback: For simplicity, JAX has removed its internal frames from the traceback of the following exception. Set JAX_TRACEBACK_FILTERING=off to include these.

The above exception was the direct cause of the following exception:

Traceback (most recent call last):
  File "/gpfsdswork/projects/rech/tkc/commun/jaxDecomp/benchmarks/pfft3d.py", line 168, in <module>
    run_benchmark(pdims, global_shape, backend, nb_nodes, output_path)
  File "/gpfsdswork/projects/rech/tkc/commun/jaxDecomp/benchmarks/pfft3d.py", line 32, in run_benchmark
    array = jax.random.normal(
  File "/gpfsdswork/projects/rech/tkc/commun/jaxDecomp/venv/v100/lib/python3.10/site-packages/jax/_src/random.py", line 720, in normal
    return _normal(key, shape, dtype)  # type: ignore
jaxlib.xla_extension.XlaRuntimeError: INTERNAL: RET_CHECK failure (external/xla/xla/service/gpu/fusions/fusion_emitter.cc:96) device_info.block_dim_limit().x == 0 || launch_dims.block_counts().x < device_info.block_dim_limit().x Kernel 'loop_broadcast_fusion_2_remat2_1' launch needs more blocks (2147483648) than allowed by hardware (2147483647).
jax.errors.SimplifiedTraceback: For simplicity, JAX has removed its internal frames from the traceback of the following exception. Set JAX_TRACEBACK_FILTERING=off to include these.

The above exception was the direct cause of the following exception:

Traceback (most recent call last):
  File "/gpfsdswork/projects/rech/tkc/commun/jaxDecomp/benchmarks/pfft3d.py", line 168, in <module>
    run_benchmark(pdims, global_shape, backend, nb_nodes, output_path)
  File "/gpfsdswork/projects/rech/tkc/commun/jaxDecomp/benchmarks/pfft3d.py", line 32, in run_benchmark
    array = jax.random.normal(
  File "/gpfsdswork/projects/rech/tkc/commun/jaxDecomp/venv/v100/lib/python3.10/site-packages/jax/_src/random.py", line 720, in normal
    return _normal(key, shape, dtype)  # type: ignore
jaxlib.xla_extension.XlaRuntimeError: INTERNAL: RET_CHECK failure (external/xla/xla/service/gpu/fusions/fusion_emitter.cc:96) device_info.block_dim_limit().x == 0 || launch_dims.block_counts().x < device_info.block_dim_limit().x Kernel 'loop_broadcast_fusion_2_remat2_1' launch needs more blocks (2147483648) than allowed by hardware (2147483647).
srun: error: r7i7n3: tasks 5-7: Exited with exit code 1
srun: Terminating StepId=1124850.14
srun: error: r7i2n6: tasks 0-3: Exited with exit code 1
srun: error: r8i5n6: tasks 8-11: Exited with exit code 1
srun: error: r9i0n3: tasks 12-15: Exited with exit code 1
srun: error: r7i7n3: task 4: Exited with exit code 1
