2024-03-19 02:36:37.832950: W external/xla/xla/service/hlo_rematerialization.cc:2941] Can't reduce memory use below -3.78TiB (-4153862257057 bytes) by rematerialization; only reduced to 16.00TiB (17592186045328 bytes), down from 16.00TiB (17592186045456 bytes) originally
2024-03-19 02:36:37.846534: W external/xla/xla/service/hlo_rematerialization.cc:2941] Can't reduce memory use below -3.78TiB (-4153862257057 bytes) by rematerialization; only reduced to 16.00TiB (17592186045328 bytes), down from 16.00TiB (17592186045456 bytes) originally
2024-03-19 02:36:37.850551: W external/xla/xla/service/hlo_rematerialization.cc:2941] Can't reduce memory use below -3.78TiB (-4153862257057 bytes) by rematerialization; only reduced to 16.00TiB (17592186045328 bytes), down from 16.00TiB (17592186045456 bytes) originally
2024-03-19 02:36:37.856453: W external/xla/xla/service/hlo_rematerialization.cc:2941] Can't reduce memory use below -3.78TiB (-4153862257057 bytes) by rematerialization; only reduced to 16.00TiB (17592186045328 bytes), down from 16.00TiB (17592186045456 bytes) originally
2024-03-19 02:36:37.868746: W external/xla/xla/service/hlo_rematerialization.cc:2941] Can't reduce memory use below -3.78TiB (-4153862257057 bytes) by rematerialization; only reduced to 16.00TiB (17592186045328 bytes), down from 16.00TiB (17592186045456 bytes) originally
2024-03-19 02:36:37.836552: W external/xla/xla/service/hlo_rematerialization.cc:2941] Can't reduce memory use below -3.78TiB (-4153862257057 bytes) by rematerialization; only reduced to 16.00TiB (17592186045328 bytes), down from 16.00TiB (17592186045456 bytes) originally
2024-03-19 02:36:37.837303: E external/xla/xla/status_macros.cc:54] INTERNAL: RET_CHECK failure (external/xla/xla/service/gpu/fusions/fusion_emitter.cc:96) device_info.block_dim_limit().x == 0 || launch_dims.block_counts().x < device_info.block_dim_limit().x Kernel 'input_concatenate_fusion' launch needs more blocks (8589934590) than allowed by hardware (2147483647).
*** Begin stack trace ***
	
	
	
	
	
	
	
	
	
	
	
	
	
	
	
	
	
	
	
	
	
	
	
	
	
	
	
	
	
	
	_PyObject_MakeTpCall
	
	_PyEval_EvalFrameDefault
	_PyFunction_Vectorcall
	_PyEval_EvalFrameDefault
	_PyFunction_Vectorcall
	_PyEval_EvalFrameDefault
	_PyFunction_Vectorcall
	_PyEval_EvalFrameDefault
	_PyFunction_Vectorcall
	_PyEval_EvalFrameDefault
	_PyFunction_Vectorcall
	
	
	
	
	
	
	
	
	_PyObject_MakeTpCall
	
	
	_PyObject_MakeTpCall
	_PyEval_EvalFrameDefault
	_PyFunction_Vectorcall
	PyObject_Call
	_PyEval_EvalFrameDefault
	_PyFunction_Vectorcall
	_PyEval_EvalFrameDefault
	_PyFunction_Vectorcall
	PyObject_Call
	_PyEval_EvalFrameDefault
	_PyFunction_Vectorcall
	
	
	_PyEval_EvalFrameDefault
	_PyFunction_Vectorcall
	PyObject_Call
	_PyEval_EvalFrameDefault
	_PyFunction_Vectorcall
	_PyEval_EvalFrameDefault
	_PyFunction_Vectorcall
	_PyEval_EvalFrameDefault
	
	PyObject_Call
	_PyEval_EvalFrameDefault
	_PyFunction_Vectorcall
	_PyEval_EvalFrameDefault
	_PyFunction_Vectorcall
	_PyEval_EvalFrameDefault
	_PyFunction_Vectorcall
	
	
	_PyEval_EvalFrameDefault
	_PyFunction_Vectorcall
	_PyEval_EvalFrameDefault
	_PyFunction_Vectorcall
	_PyEval_EvalFrameDefault
	
	PyEval_EvalCode
	
	
	
	_PyRun_SimpleFileObject
	_PyRun_AnyFileObject
	Py_RunMain
	Py_BytesMain
	__libc_start_main
	
*** End stack trace ***

2024-03-19 02:36:37.840770: E external/xla/xla/status_macros.cc:54] INTERNAL: RET_CHECK failure (external/xla/xla/service/gpu/fusions/fusion_emitter.cc:96) device_info.block_dim_limit().x == 0 || launch_dims.block_counts().x < device_info.block_dim_limit().x Kernel 'input_concatenate_fusion' launch needs more blocks (8589934590) than allowed by hardware (2147483647).
*** Begin stack trace ***
	
	
	
	
	
	
	
	
	
	
	
	
	
	
	
	
	
	
	
	
	
	
	
	
	
	
	
	
	
	
	_PyObject_MakeTpCall
	
	_PyEval_EvalFrameDefault
	_PyFunction_Vectorcall
	_PyEval_EvalFrameDefault
	_PyFunction_Vectorcall
	_PyEval_EvalFrameDefault
	_PyFunction_Vectorcall
	_PyEval_EvalFrameDefault
	_PyFunction_Vectorcall
	_PyEval_EvalFrameDefault
	_PyFunction_Vectorcall
	
	
	
	
	
	
	
	
	_PyObject_MakeTpCall
	
	
	_PyObject_MakeTpCall
	_PyEval_EvalFrameDefault
	_PyFunction_Vectorcall
	PyObject_Call
	_PyEval_EvalFrameDefault
	_PyFunction_Vectorcall
	_PyEval_EvalFrameDefault
	_PyFunction_Vectorcall
	PyObject_Call
	_PyEval_EvalFrameDefault
	_PyFunction_Vectorcall
	
	
	_PyEval_EvalFrameDefault
	_PyFunction_Vectorcall
	PyObject_Call
	_PyEval_EvalFrameDefault
	_PyFunction_Vectorcall
	_PyEval_EvalFrameDefault
	_PyFunction_Vectorcall
	_PyEval_EvalFrameDefault
	
	PyObject_Call
	_PyEval_EvalFrameDefault
	_PyFunction_Vectorcall
	_PyEval_EvalFrameDefault
	_PyFunction_Vectorcall
	_PyEval_EvalFrameDefault
	_PyFunction_Vectorcall
	
	
	_PyEval_EvalFrameDefault
	_PyFunction_Vectorcall
	_PyEval_EvalFrameDefault
	_PyFunction_Vectorcall
	_PyEval_EvalFrameDefault
	
	PyEval_EvalCode
	
	
	
	_PyRun_SimpleFileObject
	_PyRun_AnyFileObject
	Py_RunMain
	Py_BytesMain
	__libc_start_main
	
*** End stack trace ***

jax.errors.SimplifiedTraceback: For simplicity, JAX has removed its internal frames from the traceback of the following exception. Set JAX_TRACEBACK_FILTERING=off to include these.

The above exception was the direct cause of the following exception:

Traceback (most recent call last):
  File "/gpfsdswork/projects/rech/tkc/commun/jaxDecomp/benchmarks/pfft3d.py", line 170, in <module>
    run_benchmark(pdims, global_shape, backend, nb_nodes, output_path)
  File "/gpfsdswork/projects/rech/tkc/commun/jaxDecomp/benchmarks/pfft3d.py", line 34, in run_benchmark
    array = jax.random.normal(
  File "/gpfsdswork/projects/rech/tkc/commun/jaxDecomp/venv/v100/lib/python3.10/site-packages/jax/_src/random.py", line 720, in normal
    return _normal(key, shape, dtype)  # type: ignore
jaxlib.xla_extension.XlaRuntimeError: INTERNAL: RET_CHECK failure (external/xla/xla/service/gpu/fusions/fusion_emitter.cc:96) device_info.block_dim_limit().x == 0 || launch_dims.block_counts().x < device_info.block_dim_limit().x Kernel 'input_concatenate_fusion' launch needs more blocks (8589934590) than allowed by hardware (2147483647).
jax.errors.SimplifiedTraceback: For simplicity, JAX has removed its internal frames from the traceback of the following exception. Set JAX_TRACEBACK_FILTERING=off to include these.

The above exception was the direct cause of the following exception:

Traceback (most recent call last):
  File "/gpfsdswork/projects/rech/tkc/commun/jaxDecomp/benchmarks/pfft3d.py", line 170, in <module>
    run_benchmark(pdims, global_shape, backend, nb_nodes, output_path)
  File "/gpfsdswork/projects/rech/tkc/commun/jaxDecomp/benchmarks/pfft3d.py", line 34, in run_benchmark
    array = jax.random.normal(
  File "/gpfsdswork/projects/rech/tkc/commun/jaxDecomp/venv/v100/lib/python3.10/site-packages/jax/_src/random.py", line 720, in normal
    return _normal(key, shape, dtype)  # type: ignore
jaxlib.xla_extension.XlaRuntimeError: INTERNAL: RET_CHECK failure (external/xla/xla/service/gpu/fusions/fusion_emitter.cc:96) device_info.block_dim_limit().x == 0 || launch_dims.block_counts().x < device_info.block_dim_limit().x Kernel 'input_concatenate_fusion' launch needs more blocks (8589934590) than allowed by hardware (2147483647).
2024-03-19 02:36:37.880140: W external/xla/xla/service/hlo_rematerialization.cc:2941] Can't reduce memory use below -3.78TiB (-4153862257057 bytes) by rematerialization; only reduced to 16.00TiB (17592186045328 bytes), down from 16.00TiB (17592186045456 bytes) originally
2024-03-19 02:36:37.885297: W external/xla/xla/service/hlo_rematerialization.cc:2941] Can't reduce memory use below -3.78TiB (-4153862257057 bytes) by rematerialization; only reduced to 16.00TiB (17592186045328 bytes), down from 16.00TiB (17592186045456 bytes) originally
2024-03-19 02:36:37.885927: W external/xla/xla/service/hlo_rematerialization.cc:2941] Can't reduce memory use below -3.78TiB (-4153862257057 bytes) by rematerialization; only reduced to 16.00TiB (17592186045328 bytes), down from 16.00TiB (17592186045456 bytes) originally
2024-03-19 02:36:37.850794: E external/xla/xla/status_macros.cc:54] INTERNAL: RET_CHECK failure (external/xla/xla/service/gpu/fusions/fusion_emitter.cc:96) device_info.block_dim_limit().x == 0 || launch_dims.block_counts().x < device_info.block_dim_limit().x Kernel 'input_concatenate_fusion' launch needs more blocks (8589934590) than allowed by hardware (2147483647).
*** Begin stack trace ***
	
	
	
	
	
	
	
	
	
	
	
	
	
	
	
	
	
	
	
	
	
	
	
	
	
	
	
	
	
	
	_PyObject_MakeTpCall
	
	_PyEval_EvalFrameDefault
	_PyFunction_Vectorcall
	_PyEval_EvalFrameDefault
	_PyFunction_Vectorcall
	_PyEval_EvalFrameDefault
	_PyFunction_Vectorcall
	_PyEval_EvalFrameDefault
	_PyFunction_Vectorcall
	_PyEval_EvalFrameDefault
	_PyFunction_Vectorcall
	
	
	
	
	
	
	
	
	_PyObject_MakeTpCall
	
	
	_PyObject_MakeTpCall
	_PyEval_EvalFrameDefault
	_PyFunction_Vectorcall
	PyObject_Call
	_PyEval_EvalFrameDefault
	_PyFunction_Vectorcall
	_PyEval_EvalFrameDefault
	_PyFunction_Vectorcall
	PyObject_Call
	_PyEval_EvalFrameDefault
	_PyFunction_Vectorcall
	
	
	_PyEval_EvalFrameDefault
	_PyFunction_Vectorcall
	PyObject_Call
	_PyEval_EvalFrameDefault
	_PyFunction_Vectorcall
	_PyEval_EvalFrameDefault
	_PyFunction_Vectorcall
	_PyEval_EvalFrameDefault
	
	PyObject_Call
	_PyEval_EvalFrameDefault
	_PyFunction_Vectorcall
	_PyEval_EvalFrameDefault
	_PyFunction_Vectorcall
	_PyEval_EvalFrameDefault
	_PyFunction_Vectorcall
	
	
	_PyEval_EvalFrameDefault
	_PyFunction_Vectorcall
	_PyEval_EvalFrameDefault
	_PyFunction_Vectorcall
	_PyEval_EvalFrameDefault
	
	PyEval_EvalCode
	
	
	
	_PyRun_SimpleFileObject
	_PyRun_AnyFileObject
	Py_RunMain
	Py_BytesMain
	__libc_start_main
	
*** End stack trace ***

2024-03-19 02:36:37.862035: W external/xla/xla/service/hlo_rematerialization.cc:2941] Can't reduce memory use below -3.78TiB (-4153862257057 bytes) by rematerialization; only reduced to 16.00TiB (17592186045328 bytes), down from 16.00TiB (17592186045456 bytes) originally
2024-03-19 02:36:37.862474: W external/xla/xla/service/hlo_rematerialization.cc:2941] Can't reduce memory use below -3.78TiB (-4153862257057 bytes) by rematerialization; only reduced to 16.00TiB (17592186045328 bytes), down from 16.00TiB (17592186045456 bytes) originally
2024-03-19 02:36:37.865674: W external/xla/xla/service/hlo_rematerialization.cc:2941] Can't reduce memory use below -3.78TiB (-4153862257057 bytes) by rematerialization; only reduced to 16.00TiB (17592186045328 bytes), down from 16.00TiB (17592186045456 bytes) originally
2024-03-19 02:36:37.866260: E external/xla/xla/status_macros.cc:54] INTERNAL: RET_CHECK failure (external/xla/xla/service/gpu/fusions/fusion_emitter.cc:96) device_info.block_dim_limit().x == 0 || launch_dims.block_counts().x < device_info.block_dim_limit().x Kernel 'input_concatenate_fusion' launch needs more blocks (8589934590) than allowed by hardware (2147483647).
*** Begin stack trace ***
	
	
	
	
	
	
	
	
	
	
	
	
	
	
	
	
	
	
	
	
	
	
	
	
	
	
	
	
	
	
	_PyObject_MakeTpCall
	
	_PyEval_EvalFrameDefault
	_PyFunction_Vectorcall
	_PyEval_EvalFrameDefault
	_PyFunction_Vectorcall
	_PyEval_EvalFrameDefault
	_PyFunction_Vectorcall
	_PyEval_EvalFrameDefault
	_PyFunction_Vectorcall
	_PyEval_EvalFrameDefault
	_PyFunction_Vectorcall
	
	
	
	
	
	
	
	
	_PyObject_MakeTpCall
	
	
	_PyObject_MakeTpCall
	_PyEval_EvalFrameDefault
	_PyFunction_Vectorcall
	PyObject_Call
	_PyEval_EvalFrameDefault
	_PyFunction_Vectorcall
	_PyEval_EvalFrameDefault
	_PyFunction_Vectorcall
	PyObject_Call
	_PyEval_EvalFrameDefault
	_PyFunction_Vectorcall
	
	
	_PyEval_EvalFrameDefault
	_PyFunction_Vectorcall
	PyObject_Call
	_PyEval_EvalFrameDefault
	_PyFunction_Vectorcall
	_PyEval_EvalFrameDefault
	_PyFunction_Vectorcall
	_PyEval_EvalFrameDefault
	
	PyObject_Call
	_PyEval_EvalFrameDefault
	_PyFunction_Vectorcall
	_PyEval_EvalFrameDefault
	_PyFunction_Vectorcall
	_PyEval_EvalFrameDefault
	_PyFunction_Vectorcall
	
	
	_PyEval_EvalFrameDefault
	_PyFunction_Vectorcall
	_PyEval_EvalFrameDefault
	_PyFunction_Vectorcall
	_PyEval_EvalFrameDefault
	
	PyEval_EvalCode
	
	
	
	_PyRun_SimpleFileObject
	_PyRun_AnyFileObject
	Py_RunMain
	Py_BytesMain
	__libc_start_main
	
*** End stack trace ***

2024-03-19 02:36:37.866621: E external/xla/xla/status_macros.cc:54] INTERNAL: RET_CHECK failure (external/xla/xla/service/gpu/fusions/fusion_emitter.cc:96) device_info.block_dim_limit().x == 0 || launch_dims.block_counts().x < device_info.block_dim_limit().x Kernel 'input_concatenate_fusion' launch needs more blocks (8589934590) than allowed by hardware (2147483647).
*** Begin stack trace ***
	
	
	
	
	
	
	
	
	
	
	
	
	
	
	
	
	
	
	
	
	
	
	
	
	
	
	
	
	
	
	_PyObject_MakeTpCall
	
	_PyEval_EvalFrameDefault
	_PyFunction_Vectorcall
	_PyEval_EvalFrameDefault
	_PyFunction_Vectorcall
	_PyEval_EvalFrameDefault
	_PyFunction_Vectorcall
	_PyEval_EvalFrameDefault
	_PyFunction_Vectorcall
	_PyEval_EvalFrameDefault
	_PyFunction_Vectorcall
	
	
	
	
	
	
	
	
	_PyObject_MakeTpCall
	
	
	_PyObject_MakeTpCall
	_PyEval_EvalFrameDefault
	_PyFunction_Vectorcall
	PyObject_Call
	_PyEval_EvalFrameDefault
	_PyFunction_Vectorcall
	_PyEval_EvalFrameDefault
	_PyFunction_Vectorcall
	PyObject_Call
	_PyEval_EvalFrameDefault
	_PyFunction_Vectorcall
	
	
	_PyEval_EvalFrameDefault
	_PyFunction_Vectorcall
	PyObject_Call
	_PyEval_EvalFrameDefault
	_PyFunction_Vectorcall
	_PyEval_EvalFrameDefault
	_PyFunction_Vectorcall
	_PyEval_EvalFrameDefault
	
	PyObject_Call
	_PyEval_EvalFrameDefault
	_PyFunction_Vectorcall
	_PyEval_EvalFrameDefault
	_PyFunction_Vectorcall
	_PyEval_EvalFrameDefault
	_PyFunction_Vectorcall
	
	
	_PyEval_EvalFrameDefault
	_PyFunction_Vectorcall
	_PyEval_EvalFrameDefault
	_PyFunction_Vectorcall
	_PyEval_EvalFrameDefault
	
	PyEval_EvalCode
	
	
	
	_PyRun_SimpleFileObject
	_PyRun_AnyFileObject
	Py_RunMain
	Py_BytesMain
	__libc_start_main
	
*** End stack trace ***

jax.errors.SimplifiedTraceback: For simplicity, JAX has removed its internal frames from the traceback of the following exception. Set JAX_TRACEBACK_FILTERING=off to include these.

The above exception was the direct cause of the following exception:

Traceback (most recent call last):
  File "/gpfsdswork/projects/rech/tkc/commun/jaxDecomp/benchmarks/pfft3d.py", line 170, in <module>
    run_benchmark(pdims, global_shape, backend, nb_nodes, output_path)
  File "/gpfsdswork/projects/rech/tkc/commun/jaxDecomp/benchmarks/pfft3d.py", line 34, in run_benchmark
    array = jax.random.normal(
  File "/gpfsdswork/projects/rech/tkc/commun/jaxDecomp/venv/v100/lib/python3.10/site-packages/jax/_src/random.py", line 720, in normal
    return _normal(key, shape, dtype)  # type: ignore
2024-03-19 02:36:37.858514: W external/xla/xla/service/hlo_rematerialization.cc:2941] Can't reduce memory use below -3.78TiB (-4153862257057 bytes) by rematerialization; only reduced to 16.00TiB (17592186045328 bytes), down from 16.00TiB (17592186045456 bytes) originally
jaxlib.xla_extension.XlaRuntimeError: INTERNAL: RET_CHECK failure (external/xla/xla/service/gpu/fusions/fusion_emitter.cc:96) device_info.block_dim_limit().x == 0 || launch_dims.block_counts().x < device_info.block_dim_limit().x Kernel 'input_concatenate_fusion' launch needs more blocks (8589934590) than allowed by hardware (2147483647).
2024-03-19 02:36:37.858580: W external/xla/xla/service/hlo_rematerialization.cc:2941] Can't reduce memory use below -3.78TiB (-4153862257057 bytes) by rematerialization; only reduced to 16.00TiB (17592186045328 bytes), down from 16.00TiB (17592186045456 bytes) originally
2024-03-19 02:36:37.869920: E external/xla/xla/status_macros.cc:54] INTERNAL: RET_CHECK failure (external/xla/xla/service/gpu/fusions/fusion_emitter.cc:96) device_info.block_dim_limit().x == 0 || launch_dims.block_counts().x < device_info.block_dim_limit().x Kernel 'input_concatenate_fusion' launch needs more blocks (8589934590) than allowed by hardware (2147483647).
*** Begin stack trace ***
	
	
	
	
	
	
	
	
	
	
	
	
	
	
	
	
	
	
	
	
	
	
	
	
	
	
	
	
	
	
	_PyObject_MakeTpCall
	
	_PyEval_EvalFrameDefault
	_PyFunction_Vectorcall
	_PyEval_EvalFrameDefault
	_PyFunction_Vectorcall
	_PyEval_EvalFrameDefault
	_PyFunction_Vectorcall
	_PyEval_EvalFrameDefault
	_PyFunction_Vectorcall
	_PyEval_EvalFrameDefault
	_PyFunction_Vectorcall
	
	
	
	
	
	
	
	
	_PyObject_MakeTpCall
	
	
	_PyObject_MakeTpCall
	_PyEval_EvalFrameDefault
	_PyFunction_Vectorcall
	PyObject_Call
	_PyEval_EvalFrameDefault
	_PyFunction_Vectorcall
	_PyEval_EvalFrameDefault
	_PyFunction_Vectorcall
	PyObject_Call
	_PyEval_EvalFrameDefault
2024-03-19 02:36:37.859051: W external/xla/xla/service/hlo_rematerialization.cc:2941] Can't reduce memory use below -3.78TiB (-4153862257057 bytes) by rematerialization; only reduced to 16.00TiB (17592186045328 bytes), down from 16.00TiB (17592186045456 bytes) originally
	_PyFunction_Vectorcall
	
	
	_PyEval_EvalFrameDefault
	_PyFunction_Vectorcall
	PyObject_Call
	_PyEval_EvalFrameDefault
	_PyFunction_Vectorcall
	_PyEval_EvalFrameDefault
	_PyFunction_Vectorcall
	_PyEval_EvalFrameDefault
	
	PyObject_Call
	_PyEval_EvalFrameDefault
	_PyFunction_Vectorcall
	_PyEval_EvalFrameDefault
	_PyFunction_Vectorcall
	_PyEval_EvalFrameDefault
	_PyFunction_Vectorcall
	
	
	_PyEval_EvalFrameDefault
	_PyFunction_Vectorcall
	_PyEval_EvalFrameDefault
	_PyFunction_Vectorcall
	_PyEval_EvalFrameDefault
	
	PyEval_EvalCode
	
	
	
	_PyRun_SimpleFileObject
	_PyRun_AnyFileObject
	Py_RunMain
	Py_BytesMain
	__libc_start_main
	
*** End stack trace ***

2024-03-19 02:36:37.860811: E external/xla/xla/status_macros.cc:54] INTERNAL: RET_CHECK failure (external/xla/xla/service/gpu/fusions/fusion_emitter.cc:96) device_info.block_dim_limit().x == 0 || launch_dims.block_counts().x < device_info.block_dim_limit().x Kernel 'input_concatenate_fusion' launch needs more blocks (8589934590) than allowed by hardware (2147483647).
*** Begin stack trace ***
	
	
	
	
	
	
	
	
	
	
	
	
	
	
	
	
	
	
	
	
	
	
	
	
	
	
	
	
	
	
	_PyObject_MakeTpCall
	
	_PyEval_EvalFrameDefault
	_PyFunction_Vectorcall
	_PyEval_EvalFrameDefault
	_PyFunction_Vectorcall
	_PyEval_EvalFrameDefault
	_PyFunction_Vectorcall
	_PyEval_EvalFrameDefault
	_PyFunction_Vectorcall
	_PyEval_EvalFrameDefault
	_PyFunction_Vectorcall
	
	
	
	
	
	
	
	
	_PyObject_MakeTpCall
	
	
	_PyObject_MakeTpCall
	_PyEval_EvalFrameDefault
	_PyFunction_Vectorcall
	PyObject_Call
	_PyEval_EvalFrameDefault
	_PyFunction_Vectorcall
	_PyEval_EvalFrameDefault
	_PyFunction_Vectorcall
	PyObject_Call
	_PyEval_EvalFrameDefault
jax.errors.SimplifiedTraceback: For simplicity, JAX has removed its internal frames from the traceback of the following exception. Set JAX_TRACEBACK_FILTERING=off to include these.

The above exception was the direct cause of the following exception:

Traceback (most recent call last):
  File "/gpfsdswork/projects/rech/tkc/commun/jaxDecomp/benchmarks/pfft3d.py", line 170, in <module>
    run_benchmark(pdims, global_shape, backend, nb_nodes, output_path)
  File "/gpfsdswork/projects/rech/tkc/commun/jaxDecomp/benchmarks/pfft3d.py", line 34, in run_benchmark
    array = jax.random.normal(
  File "/gpfsdswork/projects/rech/tkc/commun/jaxDecomp/venv/v100/lib/python3.10/site-packages/jax/_src/random.py", line 720, in normal
    return _normal(key, shape, dtype)  # type: ignore
	_PyFunction_Vectorcall
	
	
	_PyEval_EvalFrameDefault
	_PyFunction_Vectorcall
	PyObject_Call
	_PyEval_EvalFrameDefault
	_PyFunction_Vectorcall
	_PyEval_EvalFrameDefault
	_PyFunction_Vectorcall
	_PyEval_EvalFrameDefault
	
	PyObject_Call
	_PyEval_EvalFrameDefault
	_PyFunction_Vectorcall
	_PyEval_EvalFrameDefault
	_PyFunction_Vectorcall
	_PyEval_EvalFrameDefault
	_PyFunction_Vectorcall
	
	
	_PyEval_EvalFrameDefault
	_PyFunction_Vectorcall
	_PyEval_EvalFrameDefault
	_PyFunction_Vectorcall
	_PyEval_EvalFrameDefault
	
	PyEval_EvalCode
	
	
	
	_PyRun_SimpleFileObject
	_PyRun_AnyFileObject
	Py_RunMain
	Py_BytesMain
	__libc_start_main
	
*** End stack trace ***

jaxlib.xla_extension.XlaRuntimeError: INTERNAL: RET_CHECK failure (external/xla/xla/service/gpu/fusions/fusion_emitter.cc:96) device_info.block_dim_limit().x == 0 || launch_dims.block_counts().x < device_info.block_dim_limit().x Kernel 'input_concatenate_fusion' launch needs more blocks (8589934590) than allowed by hardware (2147483647).
2024-03-19 02:36:37.862758: E external/xla/xla/status_macros.cc:54] INTERNAL: RET_CHECK failure (external/xla/xla/service/gpu/fusions/fusion_emitter.cc:96) device_info.block_dim_limit().x == 0 || launch_dims.block_counts().x < device_info.block_dim_limit().x Kernel 'input_concatenate_fusion' launch needs more blocks (8589934590) than allowed by hardware (2147483647).
*** Begin stack trace ***
	
	
	
	
	
	
	
	
	
	
	
	
	
	
	
	
	
	
	
	
	
	
	
	
	
	
	
	
	
	
	_PyObject_MakeTpCall
	
	_PyEval_EvalFrameDefault
	_PyFunction_Vectorcall
	_PyEval_EvalFrameDefault
	_PyFunction_Vectorcall
	_PyEval_EvalFrameDefault
	_PyFunction_Vectorcall
	_PyEval_EvalFrameDefault
	_PyFunction_Vectorcall
	_PyEval_EvalFrameDefault
	_PyFunction_Vectorcall
	
	
	
	
	
	
	
	
	_PyObject_MakeTpCall
	
	
	_PyObject_MakeTpCall
	_PyEval_EvalFrameDefault
	_PyFunction_Vectorcall
	PyObject_Call
	_PyEval_EvalFrameDefault
	_PyFunction_Vectorcall
	_PyEval_EvalFrameDefault
	_PyFunction_Vectorcall
	PyObject_Call
	_PyEval_EvalFrameDefault
jax.errors.SimplifiedTraceback: For simplicity, JAX has removed its internal frames from the traceback of the following exception. Set JAX_TRACEBACK_FILTERING=off to include these.

The above exception was the direct cause of the following exception:

Traceback (most recent call last):
  File "/gpfsdswork/projects/rech/tkc/commun/jaxDecomp/benchmarks/pfft3d.py", line 170, in <module>
    run_benchmark(pdims, global_shape, backend, nb_nodes, output_path)
  File "/gpfsdswork/projects/rech/tkc/commun/jaxDecomp/benchmarks/pfft3d.py", line 34, in run_benchmark
    array = jax.random.normal(
  File "/gpfsdswork/projects/rech/tkc/commun/jaxDecomp/venv/v100/lib/python3.10/site-packages/jax/_src/random.py", line 720, in normal
    return _normal(key, shape, dtype)  # type: ignore
	_PyFunction_Vectorcall
	
	
	_PyEval_EvalFrameDefault
	_PyFunction_Vectorcall
	PyObject_Call
	_PyEval_EvalFrameDefault
	_PyFunction_Vectorcall
	_PyEval_EvalFrameDefault
	_PyFunction_Vectorcall
	_PyEval_EvalFrameDefault
	
	PyObject_Call
	_PyEval_EvalFrameDefault
	_PyFunction_Vectorcall
	_PyEval_EvalFrameDefault
	_PyFunction_Vectorcall
	_PyEval_EvalFrameDefault
	_PyFunction_Vectorcall
	
	
	_PyEval_EvalFrameDefault
	_PyFunction_Vectorcall
	_PyEval_EvalFrameDefault
	_PyFunction_Vectorcall
	_PyEval_EvalFrameDefault
	
	PyEval_EvalCode
	
	
	
	_PyRun_SimpleFileObject
	_PyRun_AnyFileObject
	Py_RunMain
	Py_BytesMain
	__libc_start_main
	
*** End stack trace ***

jaxlib.xla_extension.XlaRuntimeError: INTERNAL: RET_CHECK failure (external/xla/xla/service/gpu/fusions/fusion_emitter.cc:96) device_info.block_dim_limit().x == 0 || launch_dims.block_counts().x < device_info.block_dim_limit().x Kernel 'input_concatenate_fusion' launch needs more blocks (8589934590) than allowed by hardware (2147483647).
2024-03-19 02:36:37.862776: E external/xla/xla/status_macros.cc:54] INTERNAL: RET_CHECK failure (external/xla/xla/service/gpu/fusions/fusion_emitter.cc:96) device_info.block_dim_limit().x == 0 || launch_dims.block_counts().x < device_info.block_dim_limit().x Kernel 'input_concatenate_fusion' launch needs more blocks (8589934590) than allowed by hardware (2147483647).
*** Begin stack trace ***
	
	
	
	
	
	
	
	
	
	
	
	
	
	
	
	
	
	
	
	
	
	
	
	
	
	
	
	
	
	
	_PyObject_MakeTpCall
	
	_PyEval_EvalFrameDefault
	_PyFunction_Vectorcall
	_PyEval_EvalFrameDefault
	_PyFunction_Vectorcall
	_PyEval_EvalFrameDefault
	_PyFunction_Vectorcall
	_PyEval_EvalFrameDefault
	_PyFunction_Vectorcall
	_PyEval_EvalFrameDefault
	_PyFunction_Vectorcall
	
	
	
	
	
	
	
	
	_PyObject_MakeTpCall
	
	
	_PyObject_MakeTpCall
	_PyEval_EvalFrameDefault
	_PyFunction_Vectorcall
	PyObject_Call
	_PyEval_EvalFrameDefault
	_PyFunction_Vectorcall
	_PyEval_EvalFrameDefault
	_PyFunction_Vectorcall
	PyObject_Call
	_PyEval_EvalFrameDefault
	_PyFunction_Vectorcall
	
	
	_PyEval_EvalFrameDefault
	_PyFunction_Vectorcall
	PyObject_Call
	_PyEval_EvalFrameDefault
	_PyFunction_Vectorcall
	_PyEval_EvalFrameDefault
	_PyFunction_Vectorcall
	_PyEval_EvalFrameDefault
	
	PyObject_Call
	_PyEval_EvalFrameDefault
	_PyFunction_Vectorcall
	_PyEval_EvalFrameDefault
	_PyFunction_Vectorcall
	_PyEval_EvalFrameDefault
	_PyFunction_Vectorcall
	
	
	_PyEval_EvalFrameDefault
	_PyFunction_Vectorcall
	_PyEval_EvalFrameDefault
	_PyFunction_Vectorcall
	_PyEval_EvalFrameDefault
	
	PyEval_EvalCode
	
	
	
	_PyRun_SimpleFileObject
	_PyRun_AnyFileObject
	Py_RunMain
	Py_BytesMain
	__libc_start_main
	
*** End stack trace ***

2024-03-19 02:36:37.863169: E external/xla/xla/status_macros.cc:54] INTERNAL: RET_CHECK failure (external/xla/xla/service/gpu/fusions/fusion_emitter.cc:96) device_info.block_dim_limit().x == 0 || launch_dims.block_counts().x < device_info.block_dim_limit().x Kernel 'input_concatenate_fusion' launch needs more blocks (8589934590) than allowed by hardware (2147483647).
*** Begin stack trace ***
	
	
	
	
	
	
	
	
	
	
	
	
	
	
	
	
	
	
	
	
	
	
	
	
	
	
	
	
	
	
	_PyObject_MakeTpCall
	
	_PyEval_EvalFrameDefault
	_PyFunction_Vectorcall
	_PyEval_EvalFrameDefault
	_PyFunction_Vectorcall
	_PyEval_EvalFrameDefault
	_PyFunction_Vectorcall
	_PyEval_EvalFrameDefault
	_PyFunction_Vectorcall
	_PyEval_EvalFrameDefault
	_PyFunction_Vectorcall
	
	
	
	
	
	
	
	
	_PyObject_MakeTpCall
	
	
	_PyObject_MakeTpCall
	_PyEval_EvalFrameDefault
	_PyFunction_Vectorcall
	PyObject_Call
	_PyEval_EvalFrameDefault
	_PyFunction_Vectorcall
	_PyEval_EvalFrameDefault
	_PyFunction_Vectorcall
	PyObject_Call
	_PyEval_EvalFrameDefault
	_PyFunction_Vectorcall
	
	
	_PyEval_EvalFrameDefault
	_PyFunction_Vectorcall
	PyObject_Call
	_PyEval_EvalFrameDefault
	_PyFunction_Vectorcall
	_PyEval_EvalFrameDefault
	_PyFunction_Vectorcall
	_PyEval_EvalFrameDefault
	
	PyObject_Call
	_PyEval_EvalFrameDefault
	_PyFunction_Vectorcall
	_PyEval_EvalFrameDefault
	_PyFunction_Vectorcall
	_PyEval_EvalFrameDefault
	_PyFunction_Vectorcall
	
	
	_PyEval_EvalFrameDefault
	_PyFunction_Vectorcall
	_PyEval_EvalFrameDefault
	_PyFunction_Vectorcall
	_PyEval_EvalFrameDefault
	
	PyEval_EvalCode
	
	
	
	_PyRun_SimpleFileObject
	_PyRun_AnyFileObject
	Py_RunMain
	Py_BytesMain
	__libc_start_main
	
*** End stack trace ***

jax.errors.SimplifiedTraceback: For simplicity, JAX has removed its internal frames from the traceback of the following exception. Set JAX_TRACEBACK_FILTERING=off to include these.

The above exception was the direct cause of the following exception:

Traceback (most recent call last):
  File "/gpfsdswork/projects/rech/tkc/commun/jaxDecomp/benchmarks/pfft3d.py", line 170, in <module>
    run_benchmark(pdims, global_shape, backend, nb_nodes, output_path)
  File "/gpfsdswork/projects/rech/tkc/commun/jaxDecomp/benchmarks/pfft3d.py", line 34, in run_benchmark
    array = jax.random.normal(
  File "/gpfsdswork/projects/rech/tkc/commun/jaxDecomp/venv/v100/lib/python3.10/site-packages/jax/_src/random.py", line 720, in normal
    return _normal(key, shape, dtype)  # type: ignore
jaxlib.xla_extension.XlaRuntimeError: INTERNAL: RET_CHECK failure (external/xla/xla/service/gpu/fusions/fusion_emitter.cc:96) device_info.block_dim_limit().x == 0 || launch_dims.block_counts().x < device_info.block_dim_limit().x Kernel 'input_concatenate_fusion' launch needs more blocks (8589934590) than allowed by hardware (2147483647).
jax.errors.SimplifiedTraceback: For simplicity, JAX has removed its internal frames from the traceback of the following exception. Set JAX_TRACEBACK_FILTERING=off to include these.

The above exception was the direct cause of the following exception:

Traceback (most recent call last):
  File "/gpfsdswork/projects/rech/tkc/commun/jaxDecomp/benchmarks/pfft3d.py", line 170, in <module>
    run_benchmark(pdims, global_shape, backend, nb_nodes, output_path)
  File "/gpfsdswork/projects/rech/tkc/commun/jaxDecomp/benchmarks/pfft3d.py", line 34, in run_benchmark
    array = jax.random.normal(
  File "/gpfsdswork/projects/rech/tkc/commun/jaxDecomp/venv/v100/lib/python3.10/site-packages/jax/_src/random.py", line 720, in normal
    return _normal(key, shape, dtype)  # type: ignore
jaxlib.xla_extension.XlaRuntimeError: INTERNAL: RET_CHECK failure (external/xla/xla/service/gpu/fusions/fusion_emitter.cc:96) device_info.block_dim_limit().x == 0 || launch_dims.block_counts().x < device_info.block_dim_limit().x Kernel 'input_concatenate_fusion' launch needs more blocks (8589934590) than allowed by hardware (2147483647).
jax.errors.SimplifiedTraceback: For simplicity, JAX has removed its internal frames from the traceback of the following exception. Set JAX_TRACEBACK_FILTERING=off to include these.

The above exception was the direct cause of the following exception:

Traceback (most recent call last):
  File "/gpfsdswork/projects/rech/tkc/commun/jaxDecomp/benchmarks/pfft3d.py", line 170, in <module>
    run_benchmark(pdims, global_shape, backend, nb_nodes, output_path)
  File "/gpfsdswork/projects/rech/tkc/commun/jaxDecomp/benchmarks/pfft3d.py", line 34, in run_benchmark
    array = jax.random.normal(
  File "/gpfsdswork/projects/rech/tkc/commun/jaxDecomp/venv/v100/lib/python3.10/site-packages/jax/_src/random.py", line 720, in normal
    return _normal(key, shape, dtype)  # type: ignore
jaxlib.xla_extension.XlaRuntimeError: INTERNAL: RET_CHECK failure (external/xla/xla/service/gpu/fusions/fusion_emitter.cc:96) device_info.block_dim_limit().x == 0 || launch_dims.block_counts().x < device_info.block_dim_limit().x Kernel 'input_concatenate_fusion' launch needs more blocks (8589934590) than allowed by hardware (2147483647).
jax.errors.SimplifiedTraceback: For simplicity, JAX has removed its internal frames from the traceback of the following exception. Set JAX_TRACEBACK_FILTERING=off to include these.

The above exception was the direct cause of the following exception:

Traceback (most recent call last):
  File "/gpfsdswork/projects/rech/tkc/commun/jaxDecomp/benchmarks/pfft3d.py", line 170, in <module>
    run_benchmark(pdims, global_shape, backend, nb_nodes, output_path)
  File "/gpfsdswork/projects/rech/tkc/commun/jaxDecomp/benchmarks/pfft3d.py", line 34, in run_benchmark
    array = jax.random.normal(
  File "/gpfsdswork/projects/rech/tkc/commun/jaxDecomp/venv/v100/lib/python3.10/site-packages/jax/_src/random.py", line 720, in normal
    return _normal(key, shape, dtype)  # type: ignore
jaxlib.xla_extension.XlaRuntimeError: INTERNAL: RET_CHECK failure (external/xla/xla/service/gpu/fusions/fusion_emitter.cc:96) device_info.block_dim_limit().x == 0 || launch_dims.block_counts().x < device_info.block_dim_limit().x Kernel 'input_concatenate_fusion' launch needs more blocks (8589934590) than allowed by hardware (2147483647).
2024-03-19 02:36:37.850749: W external/xla/xla/service/hlo_rematerialization.cc:2941] Can't reduce memory use below -3.78TiB (-4153862257057 bytes) by rematerialization; only reduced to 16.00TiB (17592186045328 bytes), down from 16.00TiB (17592186045456 bytes) originally
2024-03-19 02:36:37.854822: E external/xla/xla/status_macros.cc:54] INTERNAL: RET_CHECK failure (external/xla/xla/service/gpu/fusions/fusion_emitter.cc:96) device_info.block_dim_limit().x == 0 || launch_dims.block_counts().x < device_info.block_dim_limit().x Kernel 'input_concatenate_fusion' launch needs more blocks (8589934590) than allowed by hardware (2147483647).
*** Begin stack trace ***
	
	
	
	
	
	
	
	
	
	
	
	
	
	
	
	
	
	
	
	
	
	
	
	
	
	
	
	
	
	
	_PyObject_MakeTpCall
	
	_PyEval_EvalFrameDefault
	_PyFunction_Vectorcall
	_PyEval_EvalFrameDefault
	_PyFunction_Vectorcall
	_PyEval_EvalFrameDefault
	_PyFunction_Vectorcall
	_PyEval_EvalFrameDefault
	_PyFunction_Vectorcall
	_PyEval_EvalFrameDefault
	_PyFunction_Vectorcall
	
	
	
	
	
	
	
	
	_PyObject_MakeTpCall
	
	
	_PyObject_MakeTpCall
	_PyEval_EvalFrameDefault
	_PyFunction_Vectorcall
	PyObject_Call
	_PyEval_EvalFrameDefault
	_PyFunction_Vectorcall
	_PyEval_EvalFrameDefault
	_PyFunction_Vectorcall
	PyObject_Call
	_PyEval_EvalFrameDefault
	_PyFunction_Vectorcall
	
	
	_PyEval_EvalFrameDefault
	_PyFunction_Vectorcall
	PyObject_Call
	_PyEval_EvalFrameDefault
	_PyFunction_Vectorcall
	_PyEval_EvalFrameDefault
	_PyFunction_Vectorcall
	_PyEval_EvalFrameDefault
	
	PyObject_Call
	_PyEval_EvalFrameDefault
	_PyFunction_Vectorcall
	_PyEval_EvalFrameDefault
	_PyFunction_Vectorcall
	_PyEval_EvalFrameDefault
	_PyFunction_Vectorcall
	
	
	_PyEval_EvalFrameDefault
	_PyFunction_Vectorcall
	_PyEval_EvalFrameDefault
	_PyFunction_Vectorcall
	_PyEval_EvalFrameDefault
	
	PyEval_EvalCode
	
	
	
	_PyRun_SimpleFileObject
	_PyRun_AnyFileObject
	Py_RunMain
	Py_BytesMain
	__libc_start_main
	
*** End stack trace ***

2024-03-19 02:36:37.854912: E external/xla/xla/status_macros.cc:54] INTERNAL: RET_CHECK failure (external/xla/xla/service/gpu/fusions/fusion_emitter.cc:96) device_info.block_dim_limit().x == 0 || launch_dims.block_counts().x < device_info.block_dim_limit().x Kernel 'input_concatenate_fusion' launch needs more blocks (8589934590) than allowed by hardware (2147483647).
*** Begin stack trace ***
	
	
	
	
	
	
	
	
	
	
	
	
	
	
	
	
	
	
	
	
	
	
	
	
	
	
	
	
	
	
	_PyObject_MakeTpCall
	
	_PyEval_EvalFrameDefault
	_PyFunction_Vectorcall
	_PyEval_EvalFrameDefault
	_PyFunction_Vectorcall
	_PyEval_EvalFrameDefault
	_PyFunction_Vectorcall
	_PyEval_EvalFrameDefault
	_PyFunction_Vectorcall
	_PyEval_EvalFrameDefault
	_PyFunction_Vectorcall
	
	
	
	
	
	
	
	
	_PyObject_MakeTpCall
	
	
	_PyObject_MakeTpCall
	_PyEval_EvalFrameDefault
	_PyFunction_Vectorcall
	PyObject_Call
	_PyEval_EvalFrameDefault
	_PyFunction_Vectorcall
	_PyEval_EvalFrameDefault
	_PyFunction_Vectorcall
	PyObject_Call
	_PyEval_EvalFrameDefault
	_PyFunction_Vectorcall
	
	
	_PyEval_EvalFrameDefault
	_PyFunction_Vectorcall
	PyObject_Call
	_PyEval_EvalFrameDefault
	_PyFunction_Vectorcall
	_PyEval_EvalFrameDefault
	_PyFunction_Vectorcall
	_PyEval_EvalFrameDefault
	
	PyObject_Call
	_PyEval_EvalFrameDefault
	_PyFunction_Vectorcall
	_PyEval_EvalFrameDefault
	_PyFunction_Vectorcall
	_PyEval_EvalFrameDefault
	_PyFunction_Vectorcall
	
	
	_PyEval_EvalFrameDefault
	_PyFunction_Vectorcall
	_PyEval_EvalFrameDefault
	_PyFunction_Vectorcall
	_PyEval_EvalFrameDefault
	
	PyEval_EvalCode
	
	
	
	_PyRun_SimpleFileObject
	_PyRun_AnyFileObject
	Py_RunMain
	Py_BytesMain
	__libc_start_main
	
*** End stack trace ***

2024-03-19 02:36:37.858588: W external/xla/xla/service/hlo_rematerialization.cc:2941] Can't reduce memory use below -3.78TiB (-4153862257057 bytes) by rematerialization; only reduced to 16.00TiB (17592186045328 bytes), down from 16.00TiB (17592186045456 bytes) originally
jax.errors.SimplifiedTraceback: For simplicity, JAX has removed its internal frames from the traceback of the following exception. Set JAX_TRACEBACK_FILTERING=off to include these.

The above exception was the direct cause of the following exception:

Traceback (most recent call last):
  File "/gpfsdswork/projects/rech/tkc/commun/jaxDecomp/benchmarks/pfft3d.py", line 170, in <module>
    run_benchmark(pdims, global_shape, backend, nb_nodes, output_path)
  File "/gpfsdswork/projects/rech/tkc/commun/jaxDecomp/benchmarks/pfft3d.py", line 34, in run_benchmark
    array = jax.random.normal(
  File "/gpfsdswork/projects/rech/tkc/commun/jaxDecomp/venv/v100/lib/python3.10/site-packages/jax/_src/random.py", line 720, in normal
    return _normal(key, shape, dtype)  # type: ignore
2024-03-19 02:36:37.858646: W external/xla/xla/service/hlo_rematerialization.cc:2941] Can't reduce memory use below -3.78TiB (-4153862257057 bytes) by rematerialization; only reduced to 16.00TiB (17592186045328 bytes), down from 16.00TiB (17592186045456 bytes) originally
2024-03-19 02:36:37.862861: E external/xla/xla/status_macros.cc:54] INTERNAL: RET_CHECK failure (external/xla/xla/service/gpu/fusions/fusion_emitter.cc:96) device_info.block_dim_limit().x == 0 || launch_dims.block_counts().x < device_info.block_dim_limit().x Kernel 'input_concatenate_fusion' launch needs more blocks (8589934590) than allowed by hardware (2147483647).
*** Begin stack trace ***
	
	
	
	
	
	
	
	
	
	
	
	
	
	
	
	
	
	
	
	
	
	
	
	
	
	
	
	
	
	
	_PyObject_MakeTpCall
	
	_PyEval_EvalFrameDefault
	_PyFunction_Vectorcall
	_PyEval_EvalFrameDefault
	_PyFunction_Vectorcall
	_PyEval_EvalFrameDefault
	_PyFunction_Vectorcall
	_PyEval_EvalFrameDefault
	_PyFunction_Vectorcall
	_PyEval_EvalFrameDefault
	_PyFunction_Vectorcall
	
	
	
	
	
	
	
	
	_PyObject_MakeTpCall
	
	
	_PyObject_MakeTpCall
	_PyEval_EvalFrameDefault
	_PyFunction_Vectorcall
	PyObject_Call
	_PyEval_EvalFrameDefault
	_PyFunction_Vectorcall
	_PyEval_EvalFrameDefault
	_PyFunction_Vectorcall
	PyObject_Call
	_PyEval_EvalFrameDefault
	_PyFunction_Vectorcall
	
	
	_PyEval_EvalFrameDefault
	_PyFunction_Vectorcall
	PyObject_Call
	_PyEval_EvalFrameDefault
	_PyFunction_Vectorcall
	_PyEval_EvalFrameDefault
	_PyFunction_Vectorcall
	_PyEval_EvalFrameDefault
	
	PyObject_Call
	_PyEval_EvalFrameDefault
	_PyFunction_Vectorcall
	_PyEval_EvalFrameDefault
	_PyFunction_Vectorcall
	_PyEval_EvalFrameDefault
	_PyFunction_Vectorcall
	
	
	_PyEval_EvalFrameDefault
	_PyFunction_Vectorcall
	_PyEval_EvalFrameDefault
	_PyFunction_Vectorcall
	_PyEval_EvalFrameDefault
	
	PyEval_EvalCode
	
	
	
	_PyRun_SimpleFileObject
	_PyRun_AnyFileObject
	Py_RunMain
	Py_BytesMain
	__libc_start_main
	
*** End stack trace ***

2024-03-19 02:36:37.862841: E external/xla/xla/status_macros.cc:54] INTERNAL: RET_CHECK failure (external/xla/xla/service/gpu/fusions/fusion_emitter.cc:96) device_info.block_dim_limit().x == 0 || launch_dims.block_counts().x < device_info.block_dim_limit().x Kernel 'input_concatenate_fusion' launch needs more blocks (8589934590) than allowed by hardware (2147483647).
*** Begin stack trace ***
	
	
	
	
	
	
	
	
	
	
	
	
	
	
	
	
	
	
	
	
	
	
	
	
	
	
	
	
	
	
	_PyObject_MakeTpCall
	
	_PyEval_EvalFrameDefault
	_PyFunction_Vectorcall
	_PyEval_EvalFrameDefault
	_PyFunction_Vectorcall
	_PyEval_EvalFrameDefault
	_PyFunction_Vectorcall
	_PyEval_EvalFrameDefault
	_PyFunction_Vectorcall
	_PyEval_EvalFrameDefault
	_PyFunction_Vectorcall
	
	
	
	
	
	
	
	
	_PyObject_MakeTpCall
	
	
	_PyObject_MakeTpCall
	_PyEval_EvalFrameDefault
	_PyFunction_Vectorcall
	PyObject_Call
	_PyEval_EvalFrameDefault
	_PyFunction_Vectorcall
	_PyEval_EvalFrameDefault
	_PyFunction_Vectorcall
	PyObject_Call
	_PyEval_EvalFrameDefault
jaxlib.xla_extension.XlaRuntimeError: INTERNAL: RET_CHECK failure (external/xla/xla/service/gpu/fusions/fusion_emitter.cc:96) device_info.block_dim_limit().x == 0 || launch_dims.block_counts().x < device_info.block_dim_limit().x Kernel 'input_concatenate_fusion' launch needs more blocks (8589934590) than allowed by hardware (2147483647).
	_PyFunction_Vectorcall
	
	
	_PyEval_EvalFrameDefault
	_PyFunction_Vectorcall
	PyObject_Call
	_PyEval_EvalFrameDefault
	_PyFunction_Vectorcall
	_PyEval_EvalFrameDefault
	_PyFunction_Vectorcall
	_PyEval_EvalFrameDefault
	
	PyObject_Call
	_PyEval_EvalFrameDefault
	_PyFunction_Vectorcall
	_PyEval_EvalFrameDefault
	_PyFunction_Vectorcall
	_PyEval_EvalFrameDefault
	_PyFunction_Vectorcall
	
	
	_PyEval_EvalFrameDefault
	_PyFunction_Vectorcall
	_PyEval_EvalFrameDefault
	_PyFunction_Vectorcall
	_PyEval_EvalFrameDefault
	
	PyEval_EvalCode
	
	
	
	_PyRun_SimpleFileObject
	_PyRun_AnyFileObject
	Py_RunMain
	Py_BytesMain
	__libc_start_main
	
*** End stack trace ***

jax.errors.SimplifiedTraceback: For simplicity, JAX has removed its internal frames from the traceback of the following exception. Set JAX_TRACEBACK_FILTERING=off to include these.

The above exception was the direct cause of the following exception:

Traceback (most recent call last):
  File "/gpfsdswork/projects/rech/tkc/commun/jaxDecomp/benchmarks/pfft3d.py", line 170, in <module>
    run_benchmark(pdims, global_shape, backend, nb_nodes, output_path)
  File "/gpfsdswork/projects/rech/tkc/commun/jaxDecomp/benchmarks/pfft3d.py", line 34, in run_benchmark
    array = jax.random.normal(
  File "/gpfsdswork/projects/rech/tkc/commun/jaxDecomp/venv/v100/lib/python3.10/site-packages/jax/_src/random.py", line 720, in normal
    return _normal(key, shape, dtype)  # type: ignore
jaxlib.xla_extension.XlaRuntimeError: INTERNAL: RET_CHECK failure (external/xla/xla/service/gpu/fusions/fusion_emitter.cc:96) device_info.block_dim_limit().x == 0 || launch_dims.block_counts().x < device_info.block_dim_limit().x Kernel 'input_concatenate_fusion' launch needs more blocks (8589934590) than allowed by hardware (2147483647).
jax.errors.SimplifiedTraceback: For simplicity, JAX has removed its internal frames from the traceback of the following exception. Set JAX_TRACEBACK_FILTERING=off to include these.

The above exception was the direct cause of the following exception:

Traceback (most recent call last):
  File "/gpfsdswork/projects/rech/tkc/commun/jaxDecomp/benchmarks/pfft3d.py", line 170, in <module>
    run_benchmark(pdims, global_shape, backend, nb_nodes, output_path)
  File "/gpfsdswork/projects/rech/tkc/commun/jaxDecomp/benchmarks/pfft3d.py", line 34, in run_benchmark
    array = jax.random.normal(
  File "/gpfsdswork/projects/rech/tkc/commun/jaxDecomp/venv/v100/lib/python3.10/site-packages/jax/_src/random.py", line 720, in normal
    return _normal(key, shape, dtype)  # type: ignore
jaxlib.xla_extension.XlaRuntimeError: INTERNAL: RET_CHECK failure (external/xla/xla/service/gpu/fusions/fusion_emitter.cc:96) device_info.block_dim_limit().x == 0 || launch_dims.block_counts().x < device_info.block_dim_limit().x Kernel 'input_concatenate_fusion' launch needs more blocks (8589934590) than allowed by hardware (2147483647).
jax.errors.SimplifiedTraceback: For simplicity, JAX has removed its internal frames from the traceback of the following exception. Set JAX_TRACEBACK_FILTERING=off to include these.

The above exception was the direct cause of the following exception:

Traceback (most recent call last):
  File "/gpfsdswork/projects/rech/tkc/commun/jaxDecomp/benchmarks/pfft3d.py", line 170, in <module>
    run_benchmark(pdims, global_shape, backend, nb_nodes, output_path)
  File "/gpfsdswork/projects/rech/tkc/commun/jaxDecomp/benchmarks/pfft3d.py", line 34, in run_benchmark
    array = jax.random.normal(
  File "/gpfsdswork/projects/rech/tkc/commun/jaxDecomp/venv/v100/lib/python3.10/site-packages/jax/_src/random.py", line 720, in normal
    return _normal(key, shape, dtype)  # type: ignore
jaxlib.xla_extension.XlaRuntimeError: INTERNAL: RET_CHECK failure (external/xla/xla/service/gpu/fusions/fusion_emitter.cc:96) device_info.block_dim_limit().x == 0 || launch_dims.block_counts().x < device_info.block_dim_limit().x Kernel 'input_concatenate_fusion' launch needs more blocks (8589934590) than allowed by hardware (2147483647).
jax.errors.SimplifiedTraceback: For simplicity, JAX has removed its internal frames from the traceback of the following exception. Set JAX_TRACEBACK_FILTERING=off to include these.

The above exception was the direct cause of the following exception:

Traceback (most recent call last):
  File "/gpfsdswork/projects/rech/tkc/commun/jaxDecomp/benchmarks/pfft3d.py", line 170, in <module>
    run_benchmark(pdims, global_shape, backend, nb_nodes, output_path)
  File "/gpfsdswork/projects/rech/tkc/commun/jaxDecomp/benchmarks/pfft3d.py", line 34, in run_benchmark
    array = jax.random.normal(
  File "/gpfsdswork/projects/rech/tkc/commun/jaxDecomp/venv/v100/lib/python3.10/site-packages/jax/_src/random.py", line 720, in normal
    return _normal(key, shape, dtype)  # type: ignore
jaxlib.xla_extension.XlaRuntimeError: INTERNAL: RET_CHECK failure (external/xla/xla/service/gpu/fusions/fusion_emitter.cc:96) device_info.block_dim_limit().x == 0 || launch_dims.block_counts().x < device_info.block_dim_limit().x Kernel 'input_concatenate_fusion' launch needs more blocks (8589934590) than allowed by hardware (2147483647).
2024-03-19 02:36:37.868921: W external/xla/xla/service/hlo_rematerialization.cc:2941] Can't reduce memory use below -3.78TiB (-4153862257057 bytes) by rematerialization; only reduced to 16.00TiB (17592186045328 bytes), down from 16.00TiB (17592186045456 bytes) originally
2024-03-19 02:36:37.869698: W external/xla/xla/service/hlo_rematerialization.cc:2941] Can't reduce memory use below -3.78TiB (-4153862257057 bytes) by rematerialization; only reduced to 16.00TiB (17592186045328 bytes), down from 16.00TiB (17592186045456 bytes) originally
2024-03-19 02:36:37.869778: W external/xla/xla/service/hlo_rematerialization.cc:2941] Can't reduce memory use below -3.78TiB (-4153862257057 bytes) by rematerialization; only reduced to 16.00TiB (17592186045328 bytes), down from 16.00TiB (17592186045456 bytes) originally
2024-03-19 02:36:37.873030: E external/xla/xla/status_macros.cc:54] INTERNAL: RET_CHECK failure (external/xla/xla/service/gpu/fusions/fusion_emitter.cc:96) device_info.block_dim_limit().x == 0 || launch_dims.block_counts().x < device_info.block_dim_limit().x Kernel 'input_concatenate_fusion' launch needs more blocks (8589934590) than allowed by hardware (2147483647).
*** Begin stack trace ***
	
	
	
	
	
	
	
	
	
	
	
	
	
	
	
	
	
	
	
	
	
	
	
	
	
	
	
	
	
	
	_PyObject_MakeTpCall
	
	_PyEval_EvalFrameDefault
	_PyFunction_Vectorcall
	_PyEval_EvalFrameDefault
	_PyFunction_Vectorcall
	_PyEval_EvalFrameDefault
	_PyFunction_Vectorcall
	_PyEval_EvalFrameDefault
	_PyFunction_Vectorcall
	_PyEval_EvalFrameDefault
	_PyFunction_Vectorcall
	
	
	
	
	
	
	
	
	_PyObject_MakeTpCall
	
	
	_PyObject_MakeTpCall
	_PyEval_EvalFrameDefault
	_PyFunction_Vectorcall
	PyObject_Call
	_PyEval_EvalFrameDefault
	_PyFunction_Vectorcall
	_PyEval_EvalFrameDefault
	_PyFunction_Vectorcall
	PyObject_Call
	_PyEval_EvalFrameDefault
	_PyFunction_Vectorcall
	
	
	_PyEval_EvalFrameDefault
	_PyFunction_Vectorcall
	PyObject_Call
	_PyEval_EvalFrameDefault
	_PyFunction_Vectorcall
	_PyEval_EvalFrameDefault
	_PyFunction_Vectorcall
	_PyEval_EvalFrameDefault
	
	PyObject_Call
	_PyEval_EvalFrameDefault
	_PyFunction_Vectorcall
	_PyEval_EvalFrameDefault
	_PyFunction_Vectorcall
	_PyEval_EvalFrameDefault
	_PyFunction_Vectorcall
	
	
	_PyEval_EvalFrameDefault
	_PyFunction_Vectorcall
	_PyEval_EvalFrameDefault
	_PyFunction_Vectorcall
	_PyEval_EvalFrameDefault
	
	PyEval_EvalCode
	
	
	
	_PyRun_SimpleFileObject
	_PyRun_AnyFileObject
	Py_RunMain
	Py_BytesMain
	__libc_start_main
	
*** End stack trace ***

2024-03-19 02:36:37.873125: E external/xla/xla/status_macros.cc:54] INTERNAL: RET_CHECK failure (external/xla/xla/service/gpu/fusions/fusion_emitter.cc:96) device_info.block_dim_limit().x == 0 || launch_dims.block_counts().x < device_info.block_dim_limit().x Kernel 'input_concatenate_fusion' launch needs more blocks (8589934590) than allowed by hardware (2147483647).
*** Begin stack trace ***
	
	
	
	
	
	
	
	
	
	
	
	
	
	
	
	
	
	
	
	
	
	
	
	
	
	
	
	
	
	
	_PyObject_MakeTpCall
	
	_PyEval_EvalFrameDefault
	_PyFunction_Vectorcall
	_PyEval_EvalFrameDefault
	_PyFunction_Vectorcall
	_PyEval_EvalFrameDefault
	_PyFunction_Vectorcall
	_PyEval_EvalFrameDefault
	_PyFunction_Vectorcall
	_PyEval_EvalFrameDefault
	_PyFunction_Vectorcall
	
	
	
	
	
	
	
	
	_PyObject_MakeTpCall
	
	
	_PyObject_MakeTpCall
	_PyEval_EvalFrameDefault
	_PyFunction_Vectorcall
	PyObject_Call
	_PyEval_EvalFrameDefault
	_PyFunction_Vectorcall
	_PyEval_EvalFrameDefault
	_PyFunction_Vectorcall
	PyObject_Call
	_PyEval_EvalFrameDefault
	_PyFunction_Vectorcall
	
	
	_PyEval_EvalFrameDefault
	_PyFunction_Vectorcall
	PyObject_Call
	_PyEval_EvalFrameDefault
	_PyFunction_Vectorcall
	_PyEval_EvalFrameDefault
	_PyFunction_Vectorcall
	_PyEval_EvalFrameDefault
	
	PyObject_Call
	_PyEval_EvalFrameDefault
	_PyFunction_Vectorcall
	_PyEval_EvalFrameDefault
	_PyFunction_Vectorcall
	_PyEval_EvalFrameDefault
	_PyFunction_Vectorcall
	
	
	_PyEval_EvalFrameDefault
	_PyFunction_Vectorcall
	_PyEval_EvalFrameDefault
	_PyFunction_Vectorcall
	_PyEval_EvalFrameDefault
	
	PyEval_EvalCode
	
	
	
	_PyRun_SimpleFileObject
	_PyRun_AnyFileObject
	Py_RunMain
	Py_BytesMain
	__libc_start_main
	
*** End stack trace ***

2024-03-19 02:36:37.873969: E external/xla/xla/status_macros.cc:54] INTERNAL: RET_CHECK failure (external/xla/xla/service/gpu/fusions/fusion_emitter.cc:96) device_info.block_dim_limit().x == 0 || launch_dims.block_counts().x < device_info.block_dim_limit().x Kernel 'input_concatenate_fusion' launch needs more blocks (8589934590) than allowed by hardware (2147483647).
*** Begin stack trace ***
	
	
	
	
	
	
	
	
	
	
	
	
	
	
	
	
	
	
	
	
	
	
	
	
	
	
	
	
	
	
	_PyObject_MakeTpCall
	
	_PyEval_EvalFrameDefault
	_PyFunction_Vectorcall
	_PyEval_EvalFrameDefault
	_PyFunction_Vectorcall
	_PyEval_EvalFrameDefault
	_PyFunction_Vectorcall
	_PyEval_EvalFrameDefault
	_PyFunction_Vectorcall
	_PyEval_EvalFrameDefault
	_PyFunction_Vectorcall
	
	
	
	
	
	
	
	
	_PyObject_MakeTpCall
	
	
	_PyObject_MakeTpCall
	_PyEval_EvalFrameDefault
	_PyFunction_Vectorcall
	PyObject_Call
	_PyEval_EvalFrameDefault
	_PyFunction_Vectorcall
	_PyEval_EvalFrameDefault
	_PyFunction_Vectorcall
	PyObject_Call
	_PyEval_EvalFrameDefault
	_PyFunction_Vectorcall
	
	
	_PyEval_EvalFrameDefault
	_PyFunction_Vectorcall
	PyObject_Call
	_PyEval_EvalFrameDefault
	_PyFunction_Vectorcall
	_PyEval_EvalFrameDefault
	_PyFunction_Vectorcall
	_PyEval_EvalFrameDefault
	
	PyObject_Call
	_PyEval_EvalFrameDefault
	_PyFunction_Vectorcall
	_PyEval_EvalFrameDefault
	_PyFunction_Vectorcall
	_PyEval_EvalFrameDefault
	_PyFunction_Vectorcall
	
	
	_PyEval_EvalFrameDefault
	_PyFunction_Vectorcall
	_PyEval_EvalFrameDefault
	_PyFunction_Vectorcall
	_PyEval_EvalFrameDefault
	
	PyEval_EvalCode
	
	
	
	_PyRun_SimpleFileObject
	_PyRun_AnyFileObject
	Py_RunMain
	Py_BytesMain
	__libc_start_main
	
*** End stack trace ***

2024-03-19 02:36:37.873992: E external/xla/xla/status_macros.cc:54] INTERNAL: RET_CHECK failure (external/xla/xla/service/gpu/fusions/fusion_emitter.cc:96) device_info.block_dim_limit().x == 0 || launch_dims.block_counts().x < device_info.block_dim_limit().x Kernel 'input_concatenate_fusion' launch needs more blocks (8589934590) than allowed by hardware (2147483647).
*** Begin stack trace ***
	
	
	
	
	
	
	
	
	
	
	
	
	
	
	
	
	
	
	
	
	
	
	
	
	
	
	
	
	
	
	_PyObject_MakeTpCall
	
	_PyEval_EvalFrameDefault
	_PyFunction_Vectorcall
	_PyEval_EvalFrameDefault
	_PyFunction_Vectorcall
	_PyEval_EvalFrameDefault
	_PyFunction_Vectorcall
	_PyEval_EvalFrameDefault
	_PyFunction_Vectorcall
	_PyEval_EvalFrameDefault
	_PyFunction_Vectorcall
	
	
	
	
	
	
	
	
	_PyObject_MakeTpCall
	
	
	_PyObject_MakeTpCall
	_PyEval_EvalFrameDefault
	_PyFunction_Vectorcall
	PyObject_Call
	_PyEval_EvalFrameDefault
	_PyFunction_Vectorcall
	_PyEval_EvalFrameDefault
	_PyFunction_Vectorcall
	PyObject_Call
	_PyEval_EvalFrameDefault
	_PyFunction_Vectorcall
	
	
	_PyEval_EvalFrameDefault
	_PyFunction_Vectorcall
	PyObject_Call
	_PyEval_EvalFrameDefault
	_PyFunction_Vectorcall
	_PyEval_EvalFrameDefault
	_PyFunction_Vectorcall
	_PyEval_EvalFrameDefault
	
	PyObject_Call
	_PyEval_EvalFrameDefault
	_PyFunction_Vectorcall
	_PyEval_EvalFrameDefault
	_PyFunction_Vectorcall
	_PyEval_EvalFrameDefault
	_PyFunction_Vectorcall
	
	
	_PyEval_EvalFrameDefault
	_PyFunction_Vectorcall
	_PyEval_EvalFrameDefault
	_PyFunction_Vectorcall
	_PyEval_EvalFrameDefault
	
	PyEval_EvalCode
	
	
	
	_PyRun_SimpleFileObject
	_PyRun_AnyFileObject
	Py_RunMain
	Py_BytesMain
	__libc_start_main
	
*** End stack trace ***

jax.errors.SimplifiedTraceback: For simplicity, JAX has removed its internal frames from the traceback of the following exception. Set JAX_TRACEBACK_FILTERING=off to include these.

The above exception was the direct cause of the following exception:

Traceback (most recent call last):
  File "/gpfsdswork/projects/rech/tkc/commun/jaxDecomp/benchmarks/pfft3d.py", line 170, in <module>
    run_benchmark(pdims, global_shape, backend, nb_nodes, output_path)
  File "/gpfsdswork/projects/rech/tkc/commun/jaxDecomp/benchmarks/pfft3d.py", line 34, in run_benchmark
    array = jax.random.normal(
  File "/gpfsdswork/projects/rech/tkc/commun/jaxDecomp/venv/v100/lib/python3.10/site-packages/jax/_src/random.py", line 720, in normal
    return _normal(key, shape, dtype)  # type: ignore
jaxlib.xla_extension.XlaRuntimeError: INTERNAL: RET_CHECK failure (external/xla/xla/service/gpu/fusions/fusion_emitter.cc:96) device_info.block_dim_limit().x == 0 || launch_dims.block_counts().x < device_info.block_dim_limit().x Kernel 'input_concatenate_fusion' launch needs more blocks (8589934590) than allowed by hardware (2147483647).
jax.errors.SimplifiedTraceback: For simplicity, JAX has removed its internal frames from the traceback of the following exception. Set JAX_TRACEBACK_FILTERING=off to include these.

The above exception was the direct cause of the following exception:

Traceback (most recent call last):
  File "/gpfsdswork/projects/rech/tkc/commun/jaxDecomp/benchmarks/pfft3d.py", line 170, in <module>
    run_benchmark(pdims, global_shape, backend, nb_nodes, output_path)
  File "/gpfsdswork/projects/rech/tkc/commun/jaxDecomp/benchmarks/pfft3d.py", line 34, in run_benchmark
    array = jax.random.normal(
  File "/gpfsdswork/projects/rech/tkc/commun/jaxDecomp/venv/v100/lib/python3.10/site-packages/jax/_src/random.py", line 720, in normal
    return _normal(key, shape, dtype)  # type: ignore
jaxlib.xla_extension.XlaRuntimeError: INTERNAL: RET_CHECK failure (external/xla/xla/service/gpu/fusions/fusion_emitter.cc:96) device_info.block_dim_limit().x == 0 || launch_dims.block_counts().x < device_info.block_dim_limit().x Kernel 'input_concatenate_fusion' launch needs more blocks (8589934590) than allowed by hardware (2147483647).
jax.errors.SimplifiedTraceback: For simplicity, JAX has removed its internal frames from the traceback of the following exception. Set JAX_TRACEBACK_FILTERING=off to include these.

The above exception was the direct cause of the following exception:

Traceback (most recent call last):
  File "/gpfsdswork/projects/rech/tkc/commun/jaxDecomp/benchmarks/pfft3d.py", line 170, in <module>
    run_benchmark(pdims, global_shape, backend, nb_nodes, output_path)
  File "/gpfsdswork/projects/rech/tkc/commun/jaxDecomp/benchmarks/pfft3d.py", line 34, in run_benchmark
    array = jax.random.normal(
  File "/gpfsdswork/projects/rech/tkc/commun/jaxDecomp/venv/v100/lib/python3.10/site-packages/jax/_src/random.py", line 720, in normal
    return _normal(key, shape, dtype)  # type: ignore
jaxlib.xla_extension.XlaRuntimeError: INTERNAL: RET_CHECK failure (external/xla/xla/service/gpu/fusions/fusion_emitter.cc:96) device_info.block_dim_limit().x == 0 || launch_dims.block_counts().x < device_info.block_dim_limit().x Kernel 'input_concatenate_fusion' launch needs more blocks (8589934590) than allowed by hardware (2147483647).
jax.errors.SimplifiedTraceback: For simplicity, JAX has removed its internal frames from the traceback of the following exception. Set JAX_TRACEBACK_FILTERING=off to include these.

The above exception was the direct cause of the following exception:

Traceback (most recent call last):
  File "/gpfsdswork/projects/rech/tkc/commun/jaxDecomp/benchmarks/pfft3d.py", line 170, in <module>
    run_benchmark(pdims, global_shape, backend, nb_nodes, output_path)
  File "/gpfsdswork/projects/rech/tkc/commun/jaxDecomp/benchmarks/pfft3d.py", line 34, in run_benchmark
    array = jax.random.normal(
  File "/gpfsdswork/projects/rech/tkc/commun/jaxDecomp/venv/v100/lib/python3.10/site-packages/jax/_src/random.py", line 720, in normal
    return _normal(key, shape, dtype)  # type: ignore
jaxlib.xla_extension.XlaRuntimeError: INTERNAL: RET_CHECK failure (external/xla/xla/service/gpu/fusions/fusion_emitter.cc:96) device_info.block_dim_limit().x == 0 || launch_dims.block_counts().x < device_info.block_dim_limit().x Kernel 'input_concatenate_fusion' launch needs more blocks (8589934590) than allowed by hardware (2147483647).
2024-03-19 02:36:37.905733: W external/xla/xla/service/hlo_rematerialization.cc:2941] Can't reduce memory use below -3.78TiB (-4153862257057 bytes) by rematerialization; only reduced to 16.00TiB (17592186045328 bytes), down from 16.00TiB (17592186045456 bytes) originally
2024-03-19 02:36:37.906317: W external/xla/xla/service/hlo_rematerialization.cc:2941] Can't reduce memory use below -3.78TiB (-4153862257057 bytes) by rematerialization; only reduced to 16.00TiB (17592186045328 bytes), down from 16.00TiB (17592186045456 bytes) originally
2024-03-19 02:36:37.909922: E external/xla/xla/status_macros.cc:54] INTERNAL: RET_CHECK failure (external/xla/xla/service/gpu/fusions/fusion_emitter.cc:96) device_info.block_dim_limit().x == 0 || launch_dims.block_counts().x < device_info.block_dim_limit().x Kernel 'input_concatenate_fusion' launch needs more blocks (8589934590) than allowed by hardware (2147483647).
*** Begin stack trace ***
	
	
	
	
	
	
	
	
	
	
	
	
	
	
	
	
	
	
	
	
	
	
	
	
	
	
	
	
	
	
	_PyObject_MakeTpCall
	
	_PyEval_EvalFrameDefault
	_PyFunction_Vectorcall
	_PyEval_EvalFrameDefault
	_PyFunction_Vectorcall
	_PyEval_EvalFrameDefault
	_PyFunction_Vectorcall
	_PyEval_EvalFrameDefault
	_PyFunction_Vectorcall
	_PyEval_EvalFrameDefault
	_PyFunction_Vectorcall
	
	
	
	
	
	
	
	
	_PyObject_MakeTpCall
	
	
	_PyObject_MakeTpCall
	_PyEval_EvalFrameDefault
	_PyFunction_Vectorcall
	PyObject_Call
	_PyEval_EvalFrameDefault
	_PyFunction_Vectorcall
	_PyEval_EvalFrameDefault
	_PyFunction_Vectorcall
	PyObject_Call
	_PyEval_EvalFrameDefault
	_PyFunction_Vectorcall
	
	
	_PyEval_EvalFrameDefault
	_PyFunction_Vectorcall
	PyObject_Call
	_PyEval_EvalFrameDefault
	_PyFunction_Vectorcall
	_PyEval_EvalFrameDefault
	_PyFunction_Vectorcall
	_PyEval_EvalFrameDefault
	
	PyObject_Call
	_PyEval_EvalFrameDefault
	_PyFunction_Vectorcall
	_PyEval_EvalFrameDefault
	_PyFunction_Vectorcall
	_PyEval_EvalFrameDefault
	_PyFunction_Vectorcall
	
	
	_PyEval_EvalFrameDefault
	_PyFunction_Vectorcall
	_PyEval_EvalFrameDefault
	_PyFunction_Vectorcall
	_PyEval_EvalFrameDefault
	
	PyEval_EvalCode
	
	
	
	_PyRun_SimpleFileObject
	_PyRun_AnyFileObject
	Py_RunMain
	Py_BytesMain
	__libc_start_main
	
*** End stack trace ***

2024-03-19 02:36:37.910505: E external/xla/xla/status_macros.cc:54] INTERNAL: RET_CHECK failure (external/xla/xla/service/gpu/fusions/fusion_emitter.cc:96) device_info.block_dim_limit().x == 0 || launch_dims.block_counts().x < device_info.block_dim_limit().x Kernel 'input_concatenate_fusion' launch needs more blocks (8589934590) than allowed by hardware (2147483647).
*** Begin stack trace ***
	
	
	
	
	
	
	
	
	
	
	
	
	
	
	
	
	
	
	
	
	
	
	
	
	
	
	
	
	
	
	_PyObject_MakeTpCall
	
	_PyEval_EvalFrameDefault
	_PyFunction_Vectorcall
	_PyEval_EvalFrameDefault
	_PyFunction_Vectorcall
	_PyEval_EvalFrameDefault
	_PyFunction_Vectorcall
	_PyEval_EvalFrameDefault
	_PyFunction_Vectorcall
	_PyEval_EvalFrameDefault
	_PyFunction_Vectorcall
	
	
	
	
	
	
	
	
	_PyObject_MakeTpCall
	
	
	_PyObject_MakeTpCall
	_PyEval_EvalFrameDefault
	_PyFunction_Vectorcall
	PyObject_Call
	_PyEval_EvalFrameDefault
	_PyFunction_Vectorcall
	_PyEval_EvalFrameDefault
	_PyFunction_Vectorcall
	PyObject_Call
	_PyEval_EvalFrameDefault
2024-03-19 02:36:37.880243: W external/xla/xla/service/hlo_rematerialization.cc:2941] Can't reduce memory use below -3.78TiB (-4153862257057 bytes) by rematerialization; only reduced to 16.00TiB (17592186045328 bytes), down from 16.00TiB (17592186045456 bytes) originally
	_PyFunction_Vectorcall
	
	
	_PyEval_EvalFrameDefault
	_PyFunction_Vectorcall
	PyObject_Call
	_PyEval_EvalFrameDefault
	_PyFunction_Vectorcall
	_PyEval_EvalFrameDefault
	_PyFunction_Vectorcall
	_PyEval_EvalFrameDefault
	
	PyObject_Call
	_PyEval_EvalFrameDefault
	_PyFunction_Vectorcall
	_PyEval_EvalFrameDefault
	_PyFunction_Vectorcall
	_PyEval_EvalFrameDefault
	_PyFunction_Vectorcall
	
	
	_PyEval_EvalFrameDefault
	_PyFunction_Vectorcall
	_PyEval_EvalFrameDefault
	_PyFunction_Vectorcall
	_PyEval_EvalFrameDefault
	
	PyEval_EvalCode
	
	
	
	_PyRun_SimpleFileObject
	_PyRun_AnyFileObject
	Py_RunMain
	Py_BytesMain
	__libc_start_main
	
*** End stack trace ***

2024-03-19 02:36:37.880758: W external/xla/xla/service/hlo_rematerialization.cc:2941] Can't reduce memory use below -3.78TiB (-4153862257057 bytes) by rematerialization; only reduced to 16.00TiB (17592186045328 bytes), down from 16.00TiB (17592186045456 bytes) originally
2024-03-19 02:36:37.882502: W external/xla/xla/service/hlo_rematerialization.cc:2941] Can't reduce memory use below -3.78TiB (-4153862257057 bytes) by rematerialization; only reduced to 16.00TiB (17592186045328 bytes), down from 16.00TiB (17592186045456 bytes) originally
2024-03-19 02:36:37.884487: E external/xla/xla/status_macros.cc:54] INTERNAL: RET_CHECK failure (external/xla/xla/service/gpu/fusions/fusion_emitter.cc:96) device_info.block_dim_limit().x == 0 || launch_dims.block_counts().x < device_info.block_dim_limit().x Kernel 'input_concatenate_fusion' launch needs more blocks (8589934590) than allowed by hardware (2147483647).
*** Begin stack trace ***
	
	
	
	
	
	
	
	
	
	
	
	
	
	
	
	
	
	
	
	
	
	
	
	
	
	
	
	
	
	
	_PyObject_MakeTpCall
	
	_PyEval_EvalFrameDefault
	_PyFunction_Vectorcall
	_PyEval_EvalFrameDefault
	_PyFunction_Vectorcall
	_PyEval_EvalFrameDefault
	_PyFunction_Vectorcall
	_PyEval_EvalFrameDefault
	_PyFunction_Vectorcall
	_PyEval_EvalFrameDefault
	_PyFunction_Vectorcall
	
	
	
	
	
	
	
	
	_PyObject_MakeTpCall
	
	
	_PyObject_MakeTpCall
	_PyEval_EvalFrameDefault
	_PyFunction_Vectorcall
	PyObject_Call
	_PyEval_EvalFrameDefault
	_PyFunction_Vectorcall
	_PyEval_EvalFrameDefault
	_PyFunction_Vectorcall
	PyObject_Call
	_PyEval_EvalFrameDefault
	_PyFunction_Vectorcall
	
	
	_PyEval_EvalFrameDefault
	_PyFunction_Vectorcall
	PyObject_Call
	_PyEval_EvalFrameDefault
	_PyFunction_Vectorcall
	_PyEval_EvalFrameDefault
	_PyFunction_Vectorcall
	_PyEval_EvalFrameDefault
	
	PyObject_Call
	_PyEval_EvalFrameDefault
	_PyFunction_Vectorcall
	_PyEval_EvalFrameDefault
	_PyFunction_Vectorcall
	_PyEval_EvalFrameDefault
	_PyFunction_Vectorcall
	
	
	_PyEval_EvalFrameDefault
	_PyFunction_Vectorcall
	_PyEval_EvalFrameDefault
	_PyFunction_Vectorcall
	_PyEval_EvalFrameDefault
	
	PyEval_EvalCode
	
	
	
	_PyRun_SimpleFileObject
	_PyRun_AnyFileObject
	Py_RunMain
	Py_BytesMain
	__libc_start_main
	
*** End stack trace ***

2024-03-19 02:36:37.884538: E external/xla/xla/status_macros.cc:54] INTERNAL: RET_CHECK failure (external/xla/xla/service/gpu/fusions/fusion_emitter.cc:96) device_info.block_dim_limit().x == 0 || launch_dims.block_counts().x < device_info.block_dim_limit().x Kernel 'input_concatenate_fusion' launch needs more blocks (8589934590) than allowed by hardware (2147483647).
*** Begin stack trace ***
	
	
	
	
	
	
	
	
	
	
	
	
	
	
	
	
	
	
	
	
	
	
	
	
	
	
	
	
	
	
	_PyObject_MakeTpCall
	
	_PyEval_EvalFrameDefault
	_PyFunction_Vectorcall
	_PyEval_EvalFrameDefault
	_PyFunction_Vectorcall
	_PyEval_EvalFrameDefault
	_PyFunction_Vectorcall
	_PyEval_EvalFrameDefault
	_PyFunction_Vectorcall
	_PyEval_EvalFrameDefault
	_PyFunction_Vectorcall
	
	
	
	
	
	
	
	
	_PyObject_MakeTpCall
	
	
	_PyObject_MakeTpCall
	_PyEval_EvalFrameDefault
	_PyFunction_Vectorcall
	PyObject_Call
	_PyEval_EvalFrameDefault
	_PyFunction_Vectorcall
	_PyEval_EvalFrameDefault
	_PyFunction_Vectorcall
	PyObject_Call
	_PyEval_EvalFrameDefault
	_PyFunction_Vectorcall
	
	
	_PyEval_EvalFrameDefault
	_PyFunction_Vectorcall
	PyObject_Call
	_PyEval_EvalFrameDefault
	_PyFunction_Vectorcall
	_PyEval_EvalFrameDefault
	_PyFunction_Vectorcall
	_PyEval_EvalFrameDefault
	
	PyObject_Call
	_PyEval_EvalFrameDefault
	_PyFunction_Vectorcall
	_PyEval_EvalFrameDefault
	_PyFunction_Vectorcall
	_PyEval_EvalFrameDefault
	_PyFunction_Vectorcall
	
	
	_PyEval_EvalFrameDefault
	_PyFunction_Vectorcall
	_PyEval_EvalFrameDefault
	_PyFunction_Vectorcall
	_PyEval_EvalFrameDefault
	
	PyEval_EvalCode
	
	
	
	_PyRun_SimpleFileObject
	_PyRun_AnyFileObject
	Py_RunMain
	Py_BytesMain
	__libc_start_main
	
*** End stack trace ***

2024-03-19 02:36:37.884944: E external/xla/xla/status_macros.cc:54] INTERNAL: RET_CHECK failure (external/xla/xla/service/gpu/fusions/fusion_emitter.cc:96) device_info.block_dim_limit().x == 0 || launch_dims.block_counts().x < device_info.block_dim_limit().x Kernel 'input_concatenate_fusion' launch needs more blocks (8589934590) than allowed by hardware (2147483647).
*** Begin stack trace ***
	
	
	
	
	
	
	
	
	
	
	
	
	
	
	
	
	
	
	
	
	
	
	
	
	
	
	
	
	
	
	_PyObject_MakeTpCall
	
	_PyEval_EvalFrameDefault
	_PyFunction_Vectorcall
	_PyEval_EvalFrameDefault
	_PyFunction_Vectorcall
	_PyEval_EvalFrameDefault
	_PyFunction_Vectorcall
	_PyEval_EvalFrameDefault
	_PyFunction_Vectorcall
	_PyEval_EvalFrameDefault
	_PyFunction_Vectorcall
	
	
	
	
	
	
	
	
	_PyObject_MakeTpCall
	
	
	_PyObject_MakeTpCall
	_PyEval_EvalFrameDefault
	_PyFunction_Vectorcall
	PyObject_Call
	_PyEval_EvalFrameDefault
	_PyFunction_Vectorcall
	_PyEval_EvalFrameDefault
	_PyFunction_Vectorcall
	PyObject_Call
	_PyEval_EvalFrameDefault
	_PyFunction_Vectorcall
	
	
	_PyEval_EvalFrameDefault
	_PyFunction_Vectorcall
	PyObject_Call
	_PyEval_EvalFrameDefault
	_PyFunction_Vectorcall
	_PyEval_EvalFrameDefault
	_PyFunction_Vectorcall
	_PyEval_EvalFrameDefault
	
	PyObject_Call
	_PyEval_EvalFrameDefault
	_PyFunction_Vectorcall
	_PyEval_EvalFrameDefault
	_PyFunction_Vectorcall
	_PyEval_EvalFrameDefault
	_PyFunction_Vectorcall
	
	
	_PyEval_EvalFrameDefault
	_PyFunction_Vectorcall
	_PyEval_EvalFrameDefault
	_PyFunction_Vectorcall
	_PyEval_EvalFrameDefault
	
	PyEval_EvalCode
	
	
	
	_PyRun_SimpleFileObject
	_PyRun_AnyFileObject
	Py_RunMain
	Py_BytesMain
	__libc_start_main
	
*** End stack trace ***

2024-03-19 02:36:37.886676: E external/xla/xla/status_macros.cc:54] INTERNAL: RET_CHECK failure (external/xla/xla/service/gpu/fusions/fusion_emitter.cc:96) device_info.block_dim_limit().x == 0 || launch_dims.block_counts().x < device_info.block_dim_limit().x Kernel 'input_concatenate_fusion' launch needs more blocks (8589934590) than allowed by hardware (2147483647).
*** Begin stack trace ***
	
	
	
	
	
	
	
	
	
	
	
	
	
	
	
	
	
	
	
	
	
	
	
	
	
	
	
	
	
	
	_PyObject_MakeTpCall
	
	_PyEval_EvalFrameDefault
	_PyFunction_Vectorcall
	_PyEval_EvalFrameDefault
	_PyFunction_Vectorcall
	_PyEval_EvalFrameDefault
	_PyFunction_Vectorcall
	_PyEval_EvalFrameDefault
	_PyFunction_Vectorcall
	_PyEval_EvalFrameDefault
	_PyFunction_Vectorcall
	
	
	
	
	
	
	
	
	_PyObject_MakeTpCall
	
	
	_PyObject_MakeTpCall
	_PyEval_EvalFrameDefault
	_PyFunction_Vectorcall
	PyObject_Call
	_PyEval_EvalFrameDefault
	_PyFunction_Vectorcall
	_PyEval_EvalFrameDefault
	_PyFunction_Vectorcall
	PyObject_Call
	_PyEval_EvalFrameDefault
	_PyFunction_Vectorcall
	
	
	_PyEval_EvalFrameDefault
	_PyFunction_Vectorcall
	PyObject_Call
	_PyEval_EvalFrameDefault
	_PyFunction_Vectorcall
	_PyEval_EvalFrameDefault
	_PyFunction_Vectorcall
	_PyEval_EvalFrameDefault
	
	PyObject_Call
	_PyEval_EvalFrameDefault
	_PyFunction_Vectorcall
	_PyEval_EvalFrameDefault
	_PyFunction_Vectorcall
	_PyEval_EvalFrameDefault
	_PyFunction_Vectorcall
	
	
	_PyEval_EvalFrameDefault
	_PyFunction_Vectorcall
	_PyEval_EvalFrameDefault
	_PyFunction_Vectorcall
	_PyEval_EvalFrameDefault
	
	PyEval_EvalCode
	
	
	
	_PyRun_SimpleFileObject
	_PyRun_AnyFileObject
	Py_RunMain
	Py_BytesMain
	__libc_start_main
	
*** End stack trace ***

jax.errors.SimplifiedTraceback: For simplicity, JAX has removed its internal frames from the traceback of the following exception. Set JAX_TRACEBACK_FILTERING=off to include these.

The above exception was the direct cause of the following exception:

Traceback (most recent call last):
  File "/gpfsdswork/projects/rech/tkc/commun/jaxDecomp/benchmarks/pfft3d.py", line 170, in <module>
    run_benchmark(pdims, global_shape, backend, nb_nodes, output_path)
  File "/gpfsdswork/projects/rech/tkc/commun/jaxDecomp/benchmarks/pfft3d.py", line 34, in run_benchmark
    array = jax.random.normal(
  File "/gpfsdswork/projects/rech/tkc/commun/jaxDecomp/venv/v100/lib/python3.10/site-packages/jax/_src/random.py", line 720, in normal
    return _normal(key, shape, dtype)  # type: ignore
jaxlib.xla_extension.XlaRuntimeError: INTERNAL: RET_CHECK failure (external/xla/xla/service/gpu/fusions/fusion_emitter.cc:96) device_info.block_dim_limit().x == 0 || launch_dims.block_counts().x < device_info.block_dim_limit().x Kernel 'input_concatenate_fusion' launch needs more blocks (8589934590) than allowed by hardware (2147483647).
jax.errors.SimplifiedTraceback: For simplicity, JAX has removed its internal frames from the traceback of the following exception. Set JAX_TRACEBACK_FILTERING=off to include these.

The above exception was the direct cause of the following exception:

Traceback (most recent call last):
  File "/gpfsdswork/projects/rech/tkc/commun/jaxDecomp/benchmarks/pfft3d.py", line 170, in <module>
    run_benchmark(pdims, global_shape, backend, nb_nodes, output_path)
  File "/gpfsdswork/projects/rech/tkc/commun/jaxDecomp/benchmarks/pfft3d.py", line 34, in run_benchmark
    array = jax.random.normal(
  File "/gpfsdswork/projects/rech/tkc/commun/jaxDecomp/venv/v100/lib/python3.10/site-packages/jax/_src/random.py", line 720, in normal
    return _normal(key, shape, dtype)  # type: ignore
jaxlib.xla_extension.XlaRuntimeError: INTERNAL: RET_CHECK failure (external/xla/xla/service/gpu/fusions/fusion_emitter.cc:96) device_info.block_dim_limit().x == 0 || launch_dims.block_counts().x < device_info.block_dim_limit().x Kernel 'input_concatenate_fusion' launch needs more blocks (8589934590) than allowed by hardware (2147483647).
jax.errors.SimplifiedTraceback: For simplicity, JAX has removed its internal frames from the traceback of the following exception. Set JAX_TRACEBACK_FILTERING=off to include these.

The above exception was the direct cause of the following exception:

Traceback (most recent call last):
  File "/gpfsdswork/projects/rech/tkc/commun/jaxDecomp/benchmarks/pfft3d.py", line 170, in <module>
    run_benchmark(pdims, global_shape, backend, nb_nodes, output_path)
  File "/gpfsdswork/projects/rech/tkc/commun/jaxDecomp/benchmarks/pfft3d.py", line 34, in run_benchmark
    array = jax.random.normal(
  File "/gpfsdswork/projects/rech/tkc/commun/jaxDecomp/venv/v100/lib/python3.10/site-packages/jax/_src/random.py", line 720, in normal
    return _normal(key, shape, dtype)  # type: ignore
jaxlib.xla_extension.XlaRuntimeError: INTERNAL: RET_CHECK failure (external/xla/xla/service/gpu/fusions/fusion_emitter.cc:96) device_info.block_dim_limit().x == 0 || launch_dims.block_counts().x < device_info.block_dim_limit().x Kernel 'input_concatenate_fusion' launch needs more blocks (8589934590) than allowed by hardware (2147483647).
2024-03-19 02:36:37.885566: W external/xla/xla/service/hlo_rematerialization.cc:2941] Can't reduce memory use below -3.78TiB (-4153862257057 bytes) by rematerialization; only reduced to 16.00TiB (17592186045328 bytes), down from 16.00TiB (17592186045456 bytes) originally
2024-03-19 02:36:37.886246: W external/xla/xla/service/hlo_rematerialization.cc:2941] Can't reduce memory use below -3.78TiB (-4153862257057 bytes) by rematerialization; only reduced to 16.00TiB (17592186045328 bytes), down from 16.00TiB (17592186045456 bytes) originally
2024-03-19 02:36:37.886497: W external/xla/xla/service/hlo_rematerialization.cc:2941] Can't reduce memory use below -3.78TiB (-4153862257057 bytes) by rematerialization; only reduced to 16.00TiB (17592186045328 bytes), down from 16.00TiB (17592186045456 bytes) originally
2024-03-19 02:36:37.889607: E external/xla/xla/status_macros.cc:54] INTERNAL: RET_CHECK failure (external/xla/xla/service/gpu/fusions/fusion_emitter.cc:96) device_info.block_dim_limit().x == 0 || launch_dims.block_counts().x < device_info.block_dim_limit().x Kernel 'input_concatenate_fusion' launch needs more blocks (8589934590) than allowed by hardware (2147483647).
*** Begin stack trace ***
	
	
	
	
	
	
	
	
	
	
	
	
	
	
	
	
	
	
	
	
	
	
	
	
	
	
	
	
	
	
	_PyObject_MakeTpCall
	
	_PyEval_EvalFrameDefault
	_PyFunction_Vectorcall
	_PyEval_EvalFrameDefault
	_PyFunction_Vectorcall
	_PyEval_EvalFrameDefault
	_PyFunction_Vectorcall
	_PyEval_EvalFrameDefault
	_PyFunction_Vectorcall
	_PyEval_EvalFrameDefault
	_PyFunction_Vectorcall
	
	
	
	
	
	
	
	
	_PyObject_MakeTpCall
	
	
	_PyObject_MakeTpCall
	_PyEval_EvalFrameDefault
	_PyFunction_Vectorcall
	PyObject_Call
	_PyEval_EvalFrameDefault
	_PyFunction_Vectorcall
	_PyEval_EvalFrameDefault
	_PyFunction_Vectorcall
	PyObject_Call
	_PyEval_EvalFrameDefault
	_PyFunction_Vectorcall
	
	
	_PyEval_EvalFrameDefault
	_PyFunction_Vectorcall
	PyObject_Call
	_PyEval_EvalFrameDefault
	_PyFunction_Vectorcall
	_PyEval_EvalFrameDefault
	_PyFunction_Vectorcall
	_PyEval_EvalFrameDefault
	
	PyObject_Call
	_PyEval_EvalFrameDefault
	_PyFunction_Vectorcall
	_PyEval_EvalFrameDefault
	_PyFunction_Vectorcall
	_PyEval_EvalFrameDefault
	_PyFunction_Vectorcall
	
	
	_PyEval_EvalFrameDefault
	_PyFunction_Vectorcall
	_PyEval_EvalFrameDefault
	_PyFunction_Vectorcall
	_PyEval_EvalFrameDefault
	
	PyEval_EvalCode
	
	
	
	_PyRun_SimpleFileObject
	_PyRun_AnyFileObject
	Py_RunMain
	Py_BytesMain
	__libc_start_main
	
*** End stack trace ***

2024-03-19 02:36:37.889831: E external/xla/xla/status_macros.cc:54] INTERNAL: RET_CHECK failure (external/xla/xla/service/gpu/fusions/fusion_emitter.cc:96) device_info.block_dim_limit().x == 0 || launch_dims.block_counts().x < device_info.block_dim_limit().x Kernel 'input_concatenate_fusion' launch needs more blocks (8589934590) than allowed by hardware (2147483647).
*** Begin stack trace ***
	
	
	
	
	
	
	
	
	
	
	
	
	
	
	
	
	
	
	
	
	
	
	
	
	
	
	
	
	
	
	_PyObject_MakeTpCall
	
	_PyEval_EvalFrameDefault
	_PyFunction_Vectorcall
	_PyEval_EvalFrameDefault
	_PyFunction_Vectorcall
	_PyEval_EvalFrameDefault
	_PyFunction_Vectorcall
	_PyEval_EvalFrameDefault
	_PyFunction_Vectorcall
	_PyEval_EvalFrameDefault
	_PyFunction_Vectorcall
	
	
	
	
	
	
	
	
	_PyObject_MakeTpCall
	
	
	_PyObject_MakeTpCall
	_PyEval_EvalFrameDefault
	_PyFunction_Vectorcall
	PyObject_Call
	_PyEval_EvalFrameDefault
	_PyFunction_Vectorcall
	_PyEval_EvalFrameDefault
	_PyFunction_Vectorcall
	PyObject_Call
	_PyEval_EvalFrameDefault
	_PyFunction_Vectorcall
	
	
	_PyEval_EvalFrameDefault
	_PyFunction_Vectorcall
	PyObject_Call
	_PyEval_EvalFrameDefault
	_PyFunction_Vectorcall
	_PyEval_EvalFrameDefault
	_PyFunction_Vectorcall
	_PyEval_EvalFrameDefault
	
	PyObject_Call
	_PyEval_EvalFrameDefault
	_PyFunction_Vectorcall
	_PyEval_EvalFrameDefault
	_PyFunction_Vectorcall
	_PyEval_EvalFrameDefault
	_PyFunction_Vectorcall
	
	
	_PyEval_EvalFrameDefault
	_PyFunction_Vectorcall
	_PyEval_EvalFrameDefault
	_PyFunction_Vectorcall
	_PyEval_EvalFrameDefault
	
	PyEval_EvalCode
	
	
	
	_PyRun_SimpleFileObject
	_PyRun_AnyFileObject
	Py_RunMain
	Py_BytesMain
	__libc_start_main
	
*** End stack trace ***

2024-03-19 02:36:37.890509: E external/xla/xla/status_macros.cc:54] INTERNAL: RET_CHECK failure (external/xla/xla/service/gpu/fusions/fusion_emitter.cc:96) device_info.block_dim_limit().x == 0 || launch_dims.block_counts().x < device_info.block_dim_limit().x Kernel 'input_concatenate_fusion' launch needs more blocks (8589934590) than allowed by hardware (2147483647).
*** Begin stack trace ***
	
	
	
	
	
	
	
	
	
	
	
	
	
	
	
	
	
	
	
	
	
	
	
	
	
	
	
	
	
	
	_PyObject_MakeTpCall
	
	_PyEval_EvalFrameDefault
	_PyFunction_Vectorcall
	_PyEval_EvalFrameDefault
	_PyFunction_Vectorcall
	_PyEval_EvalFrameDefault
	_PyFunction_Vectorcall
	_PyEval_EvalFrameDefault
	_PyFunction_Vectorcall
	_PyEval_EvalFrameDefault
	_PyFunction_Vectorcall
	
	
	
	
	
	
	
	
	_PyObject_MakeTpCall
	
	
	_PyObject_MakeTpCall
	_PyEval_EvalFrameDefault
	_PyFunction_Vectorcall
	PyObject_Call
	_PyEval_EvalFrameDefault
	_PyFunction_Vectorcall
	_PyEval_EvalFrameDefault
	_PyFunction_Vectorcall
	PyObject_Call
	_PyEval_EvalFrameDefault
	_PyFunction_Vectorcall
	
	
	_PyEval_EvalFrameDefault
	_PyFunction_Vectorcall
	PyObject_Call
	_PyEval_EvalFrameDefault
	_PyFunction_Vectorcall
	_PyEval_EvalFrameDefault
	_PyFunction_Vectorcall
	_PyEval_EvalFrameDefault
	
	PyObject_Call
	_PyEval_EvalFrameDefault
	_PyFunction_Vectorcall
	_PyEval_EvalFrameDefault
	_PyFunction_Vectorcall
	_PyEval_EvalFrameDefault
	_PyFunction_Vectorcall
	
	
	_PyEval_EvalFrameDefault
	_PyFunction_Vectorcall
	_PyEval_EvalFrameDefault
	_PyFunction_Vectorcall
	_PyEval_EvalFrameDefault
	
	PyEval_EvalCode
	
	
	
	_PyRun_SimpleFileObject
	_PyRun_AnyFileObject
	Py_RunMain
	Py_BytesMain
	__libc_start_main
	
*** End stack trace ***

2024-03-19 02:36:37.890683: E external/xla/xla/status_macros.cc:54] INTERNAL: RET_CHECK failure (external/xla/xla/service/gpu/fusions/fusion_emitter.cc:96) device_info.block_dim_limit().x == 0 || launch_dims.block_counts().x < device_info.block_dim_limit().x Kernel 'input_concatenate_fusion' launch needs more blocks (8589934590) than allowed by hardware (2147483647).
*** Begin stack trace ***
	
	
	
	
	
	
	
	
	
	
	
	
	
	
	
	
	
	
	
	
	
	
	
	
	
	
	
	
	
	
	_PyObject_MakeTpCall
	
	_PyEval_EvalFrameDefault
	_PyFunction_Vectorcall
	_PyEval_EvalFrameDefault
	_PyFunction_Vectorcall
	_PyEval_EvalFrameDefault
	_PyFunction_Vectorcall
	_PyEval_EvalFrameDefault
	_PyFunction_Vectorcall
	_PyEval_EvalFrameDefault
	_PyFunction_Vectorcall
	
	
	
	
	
	
	
	
	_PyObject_MakeTpCall
	
	
	_PyObject_MakeTpCall
	_PyEval_EvalFrameDefault
	_PyFunction_Vectorcall
	PyObject_Call
	_PyEval_EvalFrameDefault
	_PyFunction_Vectorcall
	_PyEval_EvalFrameDefault
	_PyFunction_Vectorcall
	PyObject_Call
	_PyEval_EvalFrameDefault
	_PyFunction_Vectorcall
	
	
	_PyEval_EvalFrameDefault
	_PyFunction_Vectorcall
	PyObject_Call
	_PyEval_EvalFrameDefault
	_PyFunction_Vectorcall
	_PyEval_EvalFrameDefault
	_PyFunction_Vectorcall
	_PyEval_EvalFrameDefault
	
	PyObject_Call
	_PyEval_EvalFrameDefault
	_PyFunction_Vectorcall
	_PyEval_EvalFrameDefault
	_PyFunction_Vectorcall
	_PyEval_EvalFrameDefault
	_PyFunction_Vectorcall
	
	
	_PyEval_EvalFrameDefault
	_PyFunction_Vectorcall
	_PyEval_EvalFrameDefault
	_PyFunction_Vectorcall
	_PyEval_EvalFrameDefault
	
	PyEval_EvalCode
	
	
	
	_PyRun_SimpleFileObject
	_PyRun_AnyFileObject
	Py_RunMain
	Py_BytesMain
	__libc_start_main
	
*** End stack trace ***

jax.errors.SimplifiedTraceback: For simplicity, JAX has removed its internal frames from the traceback of the following exception. Set JAX_TRACEBACK_FILTERING=off to include these.

The above exception was the direct cause of the following exception:

Traceback (most recent call last):
  File "/gpfsdswork/projects/rech/tkc/commun/jaxDecomp/benchmarks/pfft3d.py", line 170, in <module>
    run_benchmark(pdims, global_shape, backend, nb_nodes, output_path)
  File "/gpfsdswork/projects/rech/tkc/commun/jaxDecomp/benchmarks/pfft3d.py", line 34, in run_benchmark
    array = jax.random.normal(
  File "/gpfsdswork/projects/rech/tkc/commun/jaxDecomp/venv/v100/lib/python3.10/site-packages/jax/_src/random.py", line 720, in normal
    return _normal(key, shape, dtype)  # type: ignore
jaxlib.xla_extension.XlaRuntimeError: INTERNAL: RET_CHECK failure (external/xla/xla/service/gpu/fusions/fusion_emitter.cc:96) device_info.block_dim_limit().x == 0 || launch_dims.block_counts().x < device_info.block_dim_limit().x Kernel 'input_concatenate_fusion' launch needs more blocks (8589934590) than allowed by hardware (2147483647).
jax.errors.SimplifiedTraceback: For simplicity, JAX has removed its internal frames from the traceback of the following exception. Set JAX_TRACEBACK_FILTERING=off to include these.

The above exception was the direct cause of the following exception:

Traceback (most recent call last):
  File "/gpfsdswork/projects/rech/tkc/commun/jaxDecomp/benchmarks/pfft3d.py", line 170, in <module>
    run_benchmark(pdims, global_shape, backend, nb_nodes, output_path)
  File "/gpfsdswork/projects/rech/tkc/commun/jaxDecomp/benchmarks/pfft3d.py", line 34, in run_benchmark
    array = jax.random.normal(
  File "/gpfsdswork/projects/rech/tkc/commun/jaxDecomp/venv/v100/lib/python3.10/site-packages/jax/_src/random.py", line 720, in normal
    return _normal(key, shape, dtype)  # type: ignore
jaxlib.xla_extension.XlaRuntimeError: INTERNAL: RET_CHECK failure (external/xla/xla/service/gpu/fusions/fusion_emitter.cc:96) device_info.block_dim_limit().x == 0 || launch_dims.block_counts().x < device_info.block_dim_limit().x Kernel 'input_concatenate_fusion' launch needs more blocks (8589934590) than allowed by hardware (2147483647).
jax.errors.SimplifiedTraceback: For simplicity, JAX has removed its internal frames from the traceback of the following exception. Set JAX_TRACEBACK_FILTERING=off to include these.

The above exception was the direct cause of the following exception:

Traceback (most recent call last):
  File "/gpfsdswork/projects/rech/tkc/commun/jaxDecomp/benchmarks/pfft3d.py", line 170, in <module>
    run_benchmark(pdims, global_shape, backend, nb_nodes, output_path)
  File "/gpfsdswork/projects/rech/tkc/commun/jaxDecomp/benchmarks/pfft3d.py", line 34, in run_benchmark
    array = jax.random.normal(
  File "/gpfsdswork/projects/rech/tkc/commun/jaxDecomp/venv/v100/lib/python3.10/site-packages/jax/_src/random.py", line 720, in normal
    return _normal(key, shape, dtype)  # type: ignore
jaxlib.xla_extension.XlaRuntimeError: INTERNAL: RET_CHECK failure (external/xla/xla/service/gpu/fusions/fusion_emitter.cc:96) device_info.block_dim_limit().x == 0 || launch_dims.block_counts().x < device_info.block_dim_limit().x Kernel 'input_concatenate_fusion' launch needs more blocks (8589934590) than allowed by hardware (2147483647).
2024-03-19 02:36:37.886247: W external/xla/xla/service/hlo_rematerialization.cc:2941] Can't reduce memory use below -3.78TiB (-4153862257057 bytes) by rematerialization; only reduced to 16.00TiB (17592186045328 bytes), down from 16.00TiB (17592186045456 bytes) originally
2024-03-19 02:36:37.890208: E external/xla/xla/status_macros.cc:54] INTERNAL: RET_CHECK failure (external/xla/xla/service/gpu/fusions/fusion_emitter.cc:96) device_info.block_dim_limit().x == 0 || launch_dims.block_counts().x < device_info.block_dim_limit().x Kernel 'input_concatenate_fusion' launch needs more blocks (8589934590) than allowed by hardware (2147483647).
*** Begin stack trace ***
	
	
	
	
	
	
	
	
	
	
	
	
	
	
	
	
	
	
	
	
	
	
	
	
	
	
	
	
	
	
	_PyObject_MakeTpCall
	
	_PyEval_EvalFrameDefault
	_PyFunction_Vectorcall
	_PyEval_EvalFrameDefault
	_PyFunction_Vectorcall
	_PyEval_EvalFrameDefault
	_PyFunction_Vectorcall
	_PyEval_EvalFrameDefault
	_PyFunction_Vectorcall
	_PyEval_EvalFrameDefault
	_PyFunction_Vectorcall
	
	
	
	
	
	
	
	
	_PyObject_MakeTpCall
	
	
	_PyObject_MakeTpCall
	_PyEval_EvalFrameDefault
	_PyFunction_Vectorcall
	PyObject_Call
	_PyEval_EvalFrameDefault
	_PyFunction_Vectorcall
	_PyEval_EvalFrameDefault
	_PyFunction_Vectorcall
	PyObject_Call
	_PyEval_EvalFrameDefault
	_PyFunction_Vectorcall
	
	
	_PyEval_EvalFrameDefault
	_PyFunction_Vectorcall
	PyObject_Call
	_PyEval_EvalFrameDefault
	_PyFunction_Vectorcall
	_PyEval_EvalFrameDefault
	_PyFunction_Vectorcall
	_PyEval_EvalFrameDefault
	
	PyObject_Call
	_PyEval_EvalFrameDefault
	_PyFunction_Vectorcall
	_PyEval_EvalFrameDefault
	_PyFunction_Vectorcall
	_PyEval_EvalFrameDefault
	_PyFunction_Vectorcall
	
	
	_PyEval_EvalFrameDefault
	_PyFunction_Vectorcall
	_PyEval_EvalFrameDefault
	_PyFunction_Vectorcall
	_PyEval_EvalFrameDefault
	
	PyEval_EvalCode
	
	
	
	_PyRun_SimpleFileObject
	_PyRun_AnyFileObject
	Py_RunMain
	Py_BytesMain
	__libc_start_main
	
*** End stack trace ***

2024-03-19 02:36:37.890393: E external/xla/xla/status_macros.cc:54] INTERNAL: RET_CHECK failure (external/xla/xla/service/gpu/fusions/fusion_emitter.cc:96) device_info.block_dim_limit().x == 0 || launch_dims.block_counts().x < device_info.block_dim_limit().x Kernel 'input_concatenate_fusion' launch needs more blocks (8589934590) than allowed by hardware (2147483647).
*** Begin stack trace ***
	
	
	
	
	
	
	
	
	
	
	
	
	
	
	
	
	
	
	
	
	
	
	
	
	
	
	
	
	
	
	_PyObject_MakeTpCall
	
	_PyEval_EvalFrameDefault
	_PyFunction_Vectorcall
	_PyEval_EvalFrameDefault
	_PyFunction_Vectorcall
	_PyEval_EvalFrameDefault
	_PyFunction_Vectorcall
	_PyEval_EvalFrameDefault
	_PyFunction_Vectorcall
	_PyEval_EvalFrameDefault
	_PyFunction_Vectorcall
	
	
	
	
	
	
	
	
	_PyObject_MakeTpCall
	
	
	_PyObject_MakeTpCall
	_PyEval_EvalFrameDefault
	_PyFunction_Vectorcall
	PyObject_Call
	_PyEval_EvalFrameDefault
	_PyFunction_Vectorcall
	_PyEval_EvalFrameDefault
	_PyFunction_Vectorcall
	PyObject_Call
	_PyEval_EvalFrameDefault
	_PyFunction_Vectorcall
	
	
	_PyEval_EvalFrameDefault
	_PyFunction_Vectorcall
	PyObject_Call
	_PyEval_EvalFrameDefault
	_PyFunction_Vectorcall
	_PyEval_EvalFrameDefault
	_PyFunction_Vectorcall
	_PyEval_EvalFrameDefault
	
	PyObject_Call
	_PyEval_EvalFrameDefault
	_PyFunction_Vectorcall
	_PyEval_EvalFrameDefault
	_PyFunction_Vectorcall
	_PyEval_EvalFrameDefault
	_PyFunction_Vectorcall
	
	
	_PyEval_EvalFrameDefault
	_PyFunction_Vectorcall
	_PyEval_EvalFrameDefault
	_PyFunction_Vectorcall
	_PyEval_EvalFrameDefault
	
	PyEval_EvalCode
	
	
	
	_PyRun_SimpleFileObject
	_PyRun_AnyFileObject
	Py_RunMain
	Py_BytesMain
	__libc_start_main
	
*** End stack trace ***

jax.errors.SimplifiedTraceback: For simplicity, JAX has removed its internal frames from the traceback of the following exception. Set JAX_TRACEBACK_FILTERING=off to include these.

The above exception was the direct cause of the following exception:

Traceback (most recent call last):
  File "/gpfsdswork/projects/rech/tkc/commun/jaxDecomp/benchmarks/pfft3d.py", line 170, in <module>
    run_benchmark(pdims, global_shape, backend, nb_nodes, output_path)
  File "/gpfsdswork/projects/rech/tkc/commun/jaxDecomp/benchmarks/pfft3d.py", line 34, in run_benchmark
    array = jax.random.normal(
  File "/gpfsdswork/projects/rech/tkc/commun/jaxDecomp/venv/v100/lib/python3.10/site-packages/jax/_src/random.py", line 720, in normal
    return _normal(key, shape, dtype)  # type: ignore
jaxlib.xla_extension.XlaRuntimeError: INTERNAL: RET_CHECK failure (external/xla/xla/service/gpu/fusions/fusion_emitter.cc:96) device_info.block_dim_limit().x == 0 || launch_dims.block_counts().x < device_info.block_dim_limit().x Kernel 'input_concatenate_fusion' launch needs more blocks (8589934590) than allowed by hardware (2147483647).
jax.errors.SimplifiedTraceback: For simplicity, JAX has removed its internal frames from the traceback of the following exception. Set JAX_TRACEBACK_FILTERING=off to include these.

The above exception was the direct cause of the following exception:

Traceback (most recent call last):
  File "/gpfsdswork/projects/rech/tkc/commun/jaxDecomp/benchmarks/pfft3d.py", line 170, in <module>
    run_benchmark(pdims, global_shape, backend, nb_nodes, output_path)
  File "/gpfsdswork/projects/rech/tkc/commun/jaxDecomp/benchmarks/pfft3d.py", line 34, in run_benchmark
    array = jax.random.normal(
  File "/gpfsdswork/projects/rech/tkc/commun/jaxDecomp/venv/v100/lib/python3.10/site-packages/jax/_src/random.py", line 720, in normal
    return _normal(key, shape, dtype)  # type: ignore
jaxlib.xla_extension.XlaRuntimeError: INTERNAL: RET_CHECK failure (external/xla/xla/service/gpu/fusions/fusion_emitter.cc:96) device_info.block_dim_limit().x == 0 || launch_dims.block_counts().x < device_info.block_dim_limit().x Kernel 'input_concatenate_fusion' launch needs more blocks (8589934590) than allowed by hardware (2147483647).
2024-03-19 02:36:37.920792: W external/xla/xla/service/hlo_rematerialization.cc:2941] Can't reduce memory use below -3.78TiB (-4153862257057 bytes) by rematerialization; only reduced to 16.00TiB (17592186045328 bytes), down from 16.00TiB (17592186045456 bytes) originally
2024-03-19 02:36:37.920854: W external/xla/xla/service/hlo_rematerialization.cc:2941] Can't reduce memory use below -3.78TiB (-4153862257057 bytes) by rematerialization; only reduced to 16.00TiB (17592186045328 bytes), down from 16.00TiB (17592186045456 bytes) originally
2024-03-19 02:36:37.925020: E external/xla/xla/status_macros.cc:54] INTERNAL: RET_CHECK failure (external/xla/xla/service/gpu/fusions/fusion_emitter.cc:96) device_info.block_dim_limit().x == 0 || launch_dims.block_counts().x < device_info.block_dim_limit().x Kernel 'input_concatenate_fusion' launch needs more blocks (8589934590) than allowed by hardware (2147483647).
*** Begin stack trace ***
	
	
	
	
	
	
	
	
	
	
	
	
	
	
	
	
	
	
	
	
	
	
	
	
	
	
	
	
	
	
	_PyObject_MakeTpCall
	
	_PyEval_EvalFrameDefault
	_PyFunction_Vectorcall
	_PyEval_EvalFrameDefault
	_PyFunction_Vectorcall
	_PyEval_EvalFrameDefault
	_PyFunction_Vectorcall
	_PyEval_EvalFrameDefault
	_PyFunction_Vectorcall
	_PyEval_EvalFrameDefault
	_PyFunction_Vectorcall
	
	
	
	
	
	
	
	
	_PyObject_MakeTpCall
	
	
	_PyObject_MakeTpCall
	_PyEval_EvalFrameDefault
	_PyFunction_Vectorcall
	PyObject_Call
	_PyEval_EvalFrameDefault
	_PyFunction_Vectorcall
	_PyEval_EvalFrameDefault
	_PyFunction_Vectorcall
	PyObject_Call
	_PyEval_EvalFrameDefault
	_PyFunction_Vectorcall
	
	
	_PyEval_EvalFrameDefault
	_PyFunction_Vectorcall
	PyObject_Call
	_PyEval_EvalFrameDefault
	_PyFunction_Vectorcall
	_PyEval_EvalFrameDefault
	_PyFunction_Vectorcall
	_PyEval_EvalFrameDefault
	
	PyObject_Call
	_PyEval_EvalFrameDefault
	_PyFunction_Vectorcall
	_PyEval_EvalFrameDefault
	_PyFunction_Vectorcall
	_PyEval_EvalFrameDefault
	_PyFunction_Vectorcall
	
	
	_PyEval_EvalFrameDefault
	_PyFunction_Vectorcall
	_PyEval_EvalFrameDefault
	_PyFunction_Vectorcall
	_PyEval_EvalFrameDefault
	
	PyEval_EvalCode
	
	
	
	_PyRun_SimpleFileObject
	_PyRun_AnyFileObject
	Py_RunMain
	Py_BytesMain
	__libc_start_main
	
*** End stack trace ***

2024-03-19 02:36:37.925032: E external/xla/xla/status_macros.cc:54] INTERNAL: RET_CHECK failure (external/xla/xla/service/gpu/fusions/fusion_emitter.cc:96) device_info.block_dim_limit().x == 0 || launch_dims.block_counts().x < device_info.block_dim_limit().x Kernel 'input_concatenate_fusion' launch needs more blocks (8589934590) than allowed by hardware (2147483647).
*** Begin stack trace ***
	
	
	
	
	
	
	
	
	
	
	
	
	
	
	
	
	
	
	
	
	
	
	
	
	
	
	
	
	
	
	_PyObject_MakeTpCall
	
	_PyEval_EvalFrameDefault
	_PyFunction_Vectorcall
	_PyEval_EvalFrameDefault
	_PyFunction_Vectorcall
	_PyEval_EvalFrameDefault
	_PyFunction_Vectorcall
	_PyEval_EvalFrameDefault
	_PyFunction_Vectorcall
	_PyEval_EvalFrameDefault
	_PyFunction_Vectorcall
	
	
	
	
	
	
	
	
	_PyObject_MakeTpCall
	
	
	_PyObject_MakeTpCall
	_PyEval_EvalFrameDefault
	_PyFunction_Vectorcall
	PyObject_Call
	_PyEval_EvalFrameDefault
	_PyFunction_Vectorcall
	_PyEval_EvalFrameDefault
	_PyFunction_Vectorcall
	PyObject_Call
	_PyEval_EvalFrameDefault
	_PyFunction_Vectorcall
	
	
	_PyEval_EvalFrameDefault
	_PyFunction_Vectorcall
	PyObject_Call
	_PyEval_EvalFrameDefault
	_PyFunction_Vectorcall
	_PyEval_EvalFrameDefault
	_PyFunction_Vectorcall
	_PyEval_EvalFrameDefault
	
	PyObject_Call
	_PyEval_EvalFrameDefault
	_PyFunction_Vectorcall
	_PyEval_EvalFrameDefault
	_PyFunction_Vectorcall
	_PyEval_EvalFrameDefault
	_PyFunction_Vectorcall
	
	
	_PyEval_EvalFrameDefault
	_PyFunction_Vectorcall
	_PyEval_EvalFrameDefault
	_PyFunction_Vectorcall
	_PyEval_EvalFrameDefault
	
	PyEval_EvalCode
	
	
	
	_PyRun_SimpleFileObject
	_PyRun_AnyFileObject
	Py_RunMain
	Py_BytesMain
	__libc_start_main
	
*** End stack trace ***

jax.errors.SimplifiedTraceback: For simplicity, JAX has removed its internal frames from the traceback of the following exception. Set JAX_TRACEBACK_FILTERING=off to include these.

The above exception was the direct cause of the following exception:

Traceback (most recent call last):
  File "/gpfsdswork/projects/rech/tkc/commun/jaxDecomp/benchmarks/pfft3d.py", line 170, in <module>
    run_benchmark(pdims, global_shape, backend, nb_nodes, output_path)
  File "/gpfsdswork/projects/rech/tkc/commun/jaxDecomp/benchmarks/pfft3d.py", line 34, in run_benchmark
    array = jax.random.normal(
  File "/gpfsdswork/projects/rech/tkc/commun/jaxDecomp/venv/v100/lib/python3.10/site-packages/jax/_src/random.py", line 720, in normal
    return _normal(key, shape, dtype)  # type: ignore
jaxlib.xla_extension.XlaRuntimeError: INTERNAL: RET_CHECK failure (external/xla/xla/service/gpu/fusions/fusion_emitter.cc:96) device_info.block_dim_limit().x == 0 || launch_dims.block_counts().x < device_info.block_dim_limit().x Kernel 'input_concatenate_fusion' launch needs more blocks (8589934590) than allowed by hardware (2147483647).
jax.errors.SimplifiedTraceback: For simplicity, JAX has removed its internal frames from the traceback of the following exception. Set JAX_TRACEBACK_FILTERING=off to include these.

The above exception was the direct cause of the following exception:

Traceback (most recent call last):
  File "/gpfsdswork/projects/rech/tkc/commun/jaxDecomp/benchmarks/pfft3d.py", line 170, in <module>
    run_benchmark(pdims, global_shape, backend, nb_nodes, output_path)
  File "/gpfsdswork/projects/rech/tkc/commun/jaxDecomp/benchmarks/pfft3d.py", line 34, in run_benchmark
    array = jax.random.normal(
  File "/gpfsdswork/projects/rech/tkc/commun/jaxDecomp/venv/v100/lib/python3.10/site-packages/jax/_src/random.py", line 720, in normal
    return _normal(key, shape, dtype)  # type: ignore
jaxlib.xla_extension.XlaRuntimeError: INTERNAL: RET_CHECK failure (external/xla/xla/service/gpu/fusions/fusion_emitter.cc:96) device_info.block_dim_limit().x == 0 || launch_dims.block_counts().x < device_info.block_dim_limit().x Kernel 'input_concatenate_fusion' launch needs more blocks (8589934590) than allowed by hardware (2147483647).
jax.errors.SimplifiedTraceback: For simplicity, JAX has removed its internal frames from the traceback of the following exception. Set JAX_TRACEBACK_FILTERING=off to include these.

The above exception was the direct cause of the following exception:

Traceback (most recent call last):
  File "/gpfsdswork/projects/rech/tkc/commun/jaxDecomp/benchmarks/pfft3d.py", line 170, in <module>
    run_benchmark(pdims, global_shape, backend, nb_nodes, output_path)
  File "/gpfsdswork/projects/rech/tkc/commun/jaxDecomp/benchmarks/pfft3d.py", line 34, in run_benchmark
    array = jax.random.normal(
  File "/gpfsdswork/projects/rech/tkc/commun/jaxDecomp/venv/v100/lib/python3.10/site-packages/jax/_src/random.py", line 720, in normal
    return _normal(key, shape, dtype)  # type: ignore
jaxlib.xla_extension.XlaRuntimeError: INTERNAL: RET_CHECK failure (external/xla/xla/service/gpu/fusions/fusion_emitter.cc:96) device_info.block_dim_limit().x == 0 || launch_dims.block_counts().x < device_info.block_dim_limit().x Kernel 'input_concatenate_fusion' launch needs more blocks (8589934590) than allowed by hardware (2147483647).
jax.errors.SimplifiedTraceback: For simplicity, JAX has removed its internal frames from the traceback of the following exception. Set JAX_TRACEBACK_FILTERING=off to include these.

The above exception was the direct cause of the following exception:

Traceback (most recent call last):
  File "/gpfsdswork/projects/rech/tkc/commun/jaxDecomp/benchmarks/pfft3d.py", line 170, in <module>
    run_benchmark(pdims, global_shape, backend, nb_nodes, output_path)
  File "/gpfsdswork/projects/rech/tkc/commun/jaxDecomp/benchmarks/pfft3d.py", line 34, in run_benchmark
    array = jax.random.normal(
  File "/gpfsdswork/projects/rech/tkc/commun/jaxDecomp/venv/v100/lib/python3.10/site-packages/jax/_src/random.py", line 720, in normal
    return _normal(key, shape, dtype)  # type: ignore
jaxlib.xla_extension.XlaRuntimeError: INTERNAL: RET_CHECK failure (external/xla/xla/service/gpu/fusions/fusion_emitter.cc:96) device_info.block_dim_limit().x == 0 || launch_dims.block_counts().x < device_info.block_dim_limit().x Kernel 'input_concatenate_fusion' launch needs more blocks (8589934590) than allowed by hardware (2147483647).
jax.errors.SimplifiedTraceback: For simplicity, JAX has removed its internal frames from the traceback of the following exception. Set JAX_TRACEBACK_FILTERING=off to include these.

The above exception was the direct cause of the following exception:

Traceback (most recent call last):
  File "/gpfsdswork/projects/rech/tkc/commun/jaxDecomp/benchmarks/pfft3d.py", line 170, in <module>
    run_benchmark(pdims, global_shape, backend, nb_nodes, output_path)
  File "/gpfsdswork/projects/rech/tkc/commun/jaxDecomp/benchmarks/pfft3d.py", line 34, in run_benchmark
    array = jax.random.normal(
  File "/gpfsdswork/projects/rech/tkc/commun/jaxDecomp/venv/v100/lib/python3.10/site-packages/jax/_src/random.py", line 720, in normal
    return _normal(key, shape, dtype)  # type: ignore
jaxlib.xla_extension.XlaRuntimeError: INTERNAL: RET_CHECK failure (external/xla/xla/service/gpu/fusions/fusion_emitter.cc:96) device_info.block_dim_limit().x == 0 || launch_dims.block_counts().x < device_info.block_dim_limit().x Kernel 'input_concatenate_fusion' launch needs more blocks (8589934590) than allowed by hardware (2147483647).
jax.errors.SimplifiedTraceback: For simplicity, JAX has removed its internal frames from the traceback of the following exception. Set JAX_TRACEBACK_FILTERING=off to include these.

The above exception was the direct cause of the following exception:

Traceback (most recent call last):
  File "/gpfsdswork/projects/rech/tkc/commun/jaxDecomp/benchmarks/pfft3d.py", line 170, in <module>
    run_benchmark(pdims, global_shape, backend, nb_nodes, output_path)
  File "/gpfsdswork/projects/rech/tkc/commun/jaxDecomp/benchmarks/pfft3d.py", line 34, in run_benchmark
    array = jax.random.normal(
  File "/gpfsdswork/projects/rech/tkc/commun/jaxDecomp/venv/v100/lib/python3.10/site-packages/jax/_src/random.py", line 720, in normal
    return _normal(key, shape, dtype)  # type: ignore
jaxlib.xla_extension.XlaRuntimeError: INTERNAL: RET_CHECK failure (external/xla/xla/service/gpu/fusions/fusion_emitter.cc:96) device_info.block_dim_limit().x == 0 || launch_dims.block_counts().x < device_info.block_dim_limit().x Kernel 'input_concatenate_fusion' launch needs more blocks (8589934590) than allowed by hardware (2147483647).
srun: error: r6i6n5: tasks 8-11: Exited with exit code 1
srun: Terminating StepId=1139806.33
srun: error: r8i6n6: tasks 12-15: Exited with exit code 1
srun: error: r8i7n0: tasks 24-27: Exited with exit code 1
srun: error: r8i7n1: tasks 28-31: Exited with exit code 1
srun: error: r6i6n3: tasks 0-3: Exited with exit code 1
srun: error: r8i6n8: tasks 20-23: Exited with exit code 1
srun: error: r8i6n7: tasks 16-19: Exited with exit code 1
srun: error: r6i6n4: tasks 4-7: Exited with exit code 1
