2024-03-17 15:31:30.116982: W external/xla/xla/service/hlo_rematerialization.cc:2941] Can't reduce memory use below -1.88TiB (-2064790164282 bytes) by rematerialization; only reduced to 8.00TiB (8796093022576 bytes), down from 8.00TiB (8796093022736 bytes) originally
2024-03-17 15:31:30.150979: W external/xla/xla/service/hlo_rematerialization.cc:2941] Can't reduce memory use below -1.88TiB (-2064790164282 bytes) by rematerialization; only reduced to 8.00TiB (8796093022576 bytes), down from 8.00TiB (8796093022736 bytes) originally
2024-03-17 15:31:30.118289: W external/xla/xla/service/hlo_rematerialization.cc:2941] Can't reduce memory use below -1.88TiB (-2064790164282 bytes) by rematerialization; only reduced to 8.00TiB (8796093022576 bytes), down from 8.00TiB (8796093022736 bytes) originally
2024-03-17 15:31:30.121100: E external/xla/xla/status_macros.cc:54] INTERNAL: RET_CHECK failure (external/xla/xla/service/gpu/fusions/fusion_emitter.cc:96) device_info.block_dim_limit().x == 0 || launch_dims.block_counts().x < device_info.block_dim_limit().x Kernel 'input_concatenate_fusion' launch needs more blocks (4294967295) than allowed by hardware (2147483647).
*** Begin stack trace ***
	
	
	
	
	
	
	
	
	
	
	
	
	
	
	
	
	
	
	
	
	
	
	
	
	
	
	
	
	
	
	_PyObject_MakeTpCall
	
	_PyEval_EvalFrameDefault
	_PyFunction_Vectorcall
	_PyEval_EvalFrameDefault
	_PyFunction_Vectorcall
	_PyEval_EvalFrameDefault
	_PyFunction_Vectorcall
	_PyEval_EvalFrameDefault
	_PyFunction_Vectorcall
	_PyEval_EvalFrameDefault
	_PyFunction_Vectorcall
	
	
	
	
	
	
	
	
	_PyObject_MakeTpCall
	
	
	_PyObject_MakeTpCall
	_PyEval_EvalFrameDefault
	_PyFunction_Vectorcall
	PyObject_Call
	_PyEval_EvalFrameDefault
	_PyFunction_Vectorcall
	_PyEval_EvalFrameDefault
	_PyFunction_Vectorcall
	PyObject_Call
	_PyEval_EvalFrameDefault
	_PyFunction_Vectorcall
	
	
	_PyEval_EvalFrameDefault
	_PyFunction_Vectorcall
	PyObject_Call
	_PyEval_EvalFrameDefault
	_PyFunction_Vectorcall
	_PyEval_EvalFrameDefault
	_PyFunction_Vectorcall
	_PyEval_EvalFrameDefault
	
	PyObject_Call
	_PyEval_EvalFrameDefault
	_PyFunction_Vectorcall
	_PyEval_EvalFrameDefault
	_PyFunction_Vectorcall
	_PyEval_EvalFrameDefault
	_PyFunction_Vectorcall
	
	
	_PyEval_EvalFrameDefault
	_PyFunction_Vectorcall
	_PyEval_EvalFrameDefault
	_PyFunction_Vectorcall
	_PyEval_EvalFrameDefault
	
	PyEval_EvalCode
	
	
	
	_PyRun_SimpleFileObject
	_PyRun_AnyFileObject
	Py_RunMain
	Py_BytesMain
	__libc_start_main
	
*** End stack trace ***

2024-03-17 15:31:30.122277: E external/xla/xla/status_macros.cc:54] INTERNAL: RET_CHECK failure (external/xla/xla/service/gpu/fusions/fusion_emitter.cc:96) device_info.block_dim_limit().x == 0 || launch_dims.block_counts().x < device_info.block_dim_limit().x Kernel 'input_concatenate_fusion' launch needs more blocks (4294967295) than allowed by hardware (2147483647).
*** Begin stack trace ***
	
	
	
	
	
	
	
	
	
	
	
	
	
	
	
	
	
	
	
	
	
	
	
	
	
	
	
	
	
	
	_PyObject_MakeTpCall
	
	_PyEval_EvalFrameDefault
	_PyFunction_Vectorcall
	_PyEval_EvalFrameDefault
	_PyFunction_Vectorcall
	_PyEval_EvalFrameDefault
	_PyFunction_Vectorcall
	_PyEval_EvalFrameDefault
	_PyFunction_Vectorcall
	_PyEval_EvalFrameDefault
	_PyFunction_Vectorcall
	
	
	
	
	
	
	
	
	_PyObject_MakeTpCall
	
	
	_PyObject_MakeTpCall
	_PyEval_EvalFrameDefault
	_PyFunction_Vectorcall
	PyObject_Call
	_PyEval_EvalFrameDefault
	_PyFunction_Vectorcall
	_PyEval_EvalFrameDefault
	_PyFunction_Vectorcall
	PyObject_Call
	_PyEval_EvalFrameDefault
	_PyFunction_Vectorcall
	
	
	_PyEval_EvalFrameDefault
	_PyFunction_Vectorcall
	PyObject_Call
	_PyEval_EvalFrameDefault
	_PyFunction_Vectorcall
	_PyEval_EvalFrameDefault
	_PyFunction_Vectorcall
	_PyEval_EvalFrameDefault
	
	PyObject_Call
	_PyEval_EvalFrameDefault
	_PyFunction_Vectorcall
	_PyEval_EvalFrameDefault
	_PyFunction_Vectorcall
	_PyEval_EvalFrameDefault
	_PyFunction_Vectorcall
	
	
	_PyEval_EvalFrameDefault
	_PyFunction_Vectorcall
	_PyEval_EvalFrameDefault
	_PyFunction_Vectorcall
	_PyEval_EvalFrameDefault
	
	PyEval_EvalCode
	
	
	
	_PyRun_SimpleFileObject
	_PyRun_AnyFileObject
	Py_RunMain
	Py_BytesMain
	__libc_start_main
	
*** End stack trace ***

2024-03-17 15:31:30.126559: W external/xla/xla/service/hlo_rematerialization.cc:2941] Can't reduce memory use below -1.88TiB (-2064790164282 bytes) by rematerialization; only reduced to 8.00TiB (8796093022576 bytes), down from 8.00TiB (8796093022736 bytes) originally
2024-03-17 15:31:30.129670: W external/xla/xla/service/hlo_rematerialization.cc:2941] Can't reduce memory use below -1.88TiB (-2064790164282 bytes) by rematerialization; only reduced to 8.00TiB (8796093022576 bytes), down from 8.00TiB (8796093022736 bytes) originally
2024-03-17 15:31:30.130650: E external/xla/xla/status_macros.cc:54] INTERNAL: RET_CHECK failure (external/xla/xla/service/gpu/fusions/fusion_emitter.cc:96) device_info.block_dim_limit().x == 0 || launch_dims.block_counts().x < device_info.block_dim_limit().x Kernel 'input_concatenate_fusion' launch needs more blocks (4294967295) than allowed by hardware (2147483647).
*** Begin stack trace ***
	
	
	
	
	
	
	
	
	
	
	
	
	
	
	
	
	
	
	
	
	
	
	
	
	
	
	
	
	
	
	_PyObject_MakeTpCall
	
	_PyEval_EvalFrameDefault
	_PyFunction_Vectorcall
	_PyEval_EvalFrameDefault
	_PyFunction_Vectorcall
	_PyEval_EvalFrameDefault
	_PyFunction_Vectorcall
	_PyEval_EvalFrameDefault
	_PyFunction_Vectorcall
	_PyEval_EvalFrameDefault
	_PyFunction_Vectorcall
	
	
	
	
	
	
	
	
	_PyObject_MakeTpCall
	
	
	_PyObject_MakeTpCall
	_PyEval_EvalFrameDefault
	_PyFunction_Vectorcall
	PyObject_Call
	_PyEval_EvalFrameDefault
	_PyFunction_Vectorcall
	_PyEval_EvalFrameDefault
	_PyFunction_Vectorcall
	PyObject_Call
	_PyEval_EvalFrameDefault
	_PyFunction_Vectorcall
	
	
	_PyEval_EvalFrameDefault
	_PyFunction_Vectorcall
	PyObject_Call
	_PyEval_EvalFrameDefault
	_PyFunction_Vectorcall
	_PyEval_EvalFrameDefault
	_PyFunction_Vectorcall
	_PyEval_EvalFrameDefault
	
	PyObject_Call
	_PyEval_EvalFrameDefault
	_PyFunction_Vectorcall
	_PyEval_EvalFrameDefault
	_PyFunction_Vectorcall
	_PyEval_EvalFrameDefault
	_PyFunction_Vectorcall
	
	
	_PyEval_EvalFrameDefault
	_PyFunction_Vectorcall
	_PyEval_EvalFrameDefault
	_PyFunction_Vectorcall
	_PyEval_EvalFrameDefault
	
	PyEval_EvalCode
	
	
	
	_PyRun_SimpleFileObject
	_PyRun_AnyFileObject
	Py_RunMain
	Py_BytesMain
	__libc_start_main
	
*** End stack trace ***

2024-03-17 15:31:30.133625: E external/xla/xla/status_macros.cc:54] INTERNAL: RET_CHECK failure (external/xla/xla/service/gpu/fusions/fusion_emitter.cc:96) device_info.block_dim_limit().x == 0 || launch_dims.block_counts().x < device_info.block_dim_limit().x Kernel 'input_concatenate_fusion' launch needs more blocks (4294967295) than allowed by hardware (2147483647).
*** Begin stack trace ***
	
	
	
	
	
	
	
	
	
	
	
	
	
	
	
	
	
	
	
	
	
	
	
	
	
	
	
	
	
	
	_PyObject_MakeTpCall
	
	_PyEval_EvalFrameDefault
	_PyFunction_Vectorcall
	_PyEval_EvalFrameDefault
	_PyFunction_Vectorcall
	_PyEval_EvalFrameDefault
	_PyFunction_Vectorcall
	_PyEval_EvalFrameDefault
	_PyFunction_Vectorcall
	_PyEval_EvalFrameDefault
	_PyFunction_Vectorcall
	
	
	
	
	
	
	
	
	_PyObject_MakeTpCall
	
	
	_PyObject_MakeTpCall
	_PyEval_EvalFrameDefault
	_PyFunction_Vectorcall
	PyObject_Call
	_PyEval_EvalFrameDefault
	_PyFunction_Vectorcall
	_PyEval_EvalFrameDefault
	_PyFunction_Vectorcall
	PyObject_Call
	_PyEval_EvalFrameDefault
	_PyFunction_Vectorcall
	
	
	_PyEval_EvalFrameDefault
	_PyFunction_Vectorcall
	PyObject_Call
	_PyEval_EvalFrameDefault
	_PyFunction_Vectorcall
	_PyEval_EvalFrameDefault
	_PyFunction_Vectorcall
	_PyEval_EvalFrameDefault
	
	PyObject_Call
	_PyEval_EvalFrameDefault
	_PyFunction_Vectorcall
	_PyEval_EvalFrameDefault
	_PyFunction_Vectorcall
	_PyEval_EvalFrameDefault
	_PyFunction_Vectorcall
	
	
	_PyEval_EvalFrameDefault
	_PyFunction_Vectorcall
	_PyEval_EvalFrameDefault
	_PyFunction_Vectorcall
	_PyEval_EvalFrameDefault
	
	PyEval_EvalCode
	
	
	
	_PyRun_SimpleFileObject
	_PyRun_AnyFileObject
	Py_RunMain
	Py_BytesMain
	__libc_start_main
	
*** End stack trace ***

jax.errors.SimplifiedTraceback: For simplicity, JAX has removed its internal frames from the traceback of the following exception. Set JAX_TRACEBACK_FILTERING=off to include these.

The above exception was the direct cause of the following exception:

Traceback (most recent call last):
  File "/gpfsdswork/projects/rech/tkc/commun/jaxDecomp/benchmarks/pfft3d.py", line 168, in <module>
    run_benchmark(pdims, global_shape, backend, nb_nodes, output_path)
  File "/gpfsdswork/projects/rech/tkc/commun/jaxDecomp/benchmarks/pfft3d.py", line 32, in run_benchmark
    array = jax.random.normal(
  File "/gpfsdswork/projects/rech/tkc/commun/jaxDecomp/venv/v100/lib/python3.10/site-packages/jax/_src/random.py", line 720, in normal
    return _normal(key, shape, dtype)  # type: ignore
jaxlib.xla_extension.XlaRuntimeError: INTERNAL: RET_CHECK failure (external/xla/xla/service/gpu/fusions/fusion_emitter.cc:96) device_info.block_dim_limit().x == 0 || launch_dims.block_counts().x < device_info.block_dim_limit().x Kernel 'input_concatenate_fusion' launch needs more blocks (4294967295) than allowed by hardware (2147483647).
jax.errors.SimplifiedTraceback: For simplicity, JAX has removed its internal frames from the traceback of the following exception. Set JAX_TRACEBACK_FILTERING=off to include these.

The above exception was the direct cause of the following exception:

Traceback (most recent call last):
  File "/gpfsdswork/projects/rech/tkc/commun/jaxDecomp/benchmarks/pfft3d.py", line 168, in <module>
    run_benchmark(pdims, global_shape, backend, nb_nodes, output_path)
  File "/gpfsdswork/projects/rech/tkc/commun/jaxDecomp/benchmarks/pfft3d.py", line 32, in run_benchmark
    array = jax.random.normal(
  File "/gpfsdswork/projects/rech/tkc/commun/jaxDecomp/venv/v100/lib/python3.10/site-packages/jax/_src/random.py", line 720, in normal
    return _normal(key, shape, dtype)  # type: ignore
jaxlib.xla_extension.XlaRuntimeError: INTERNAL: RET_CHECK failure (external/xla/xla/service/gpu/fusions/fusion_emitter.cc:96) device_info.block_dim_limit().x == 0 || launch_dims.block_counts().x < device_info.block_dim_limit().x Kernel 'input_concatenate_fusion' launch needs more blocks (4294967295) than allowed by hardware (2147483647).
jax.errors.SimplifiedTraceback: For simplicity, JAX has removed its internal frames from the traceback of the following exception. Set JAX_TRACEBACK_FILTERING=off to include these.

The above exception was the direct cause of the following exception:

Traceback (most recent call last):
  File "/gpfsdswork/projects/rech/tkc/commun/jaxDecomp/benchmarks/pfft3d.py", line 168, in <module>
    run_benchmark(pdims, global_shape, backend, nb_nodes, output_path)
  File "/gpfsdswork/projects/rech/tkc/commun/jaxDecomp/benchmarks/pfft3d.py", line 32, in run_benchmark
    array = jax.random.normal(
  File "/gpfsdswork/projects/rech/tkc/commun/jaxDecomp/venv/v100/lib/python3.10/site-packages/jax/_src/random.py", line 720, in normal
    return _normal(key, shape, dtype)  # type: ignore
jaxlib.xla_extension.XlaRuntimeError: INTERNAL: RET_CHECK failure (external/xla/xla/service/gpu/fusions/fusion_emitter.cc:96) device_info.block_dim_limit().x == 0 || launch_dims.block_counts().x < device_info.block_dim_limit().x Kernel 'input_concatenate_fusion' launch needs more blocks (4294967295) than allowed by hardware (2147483647).
2024-03-17 15:31:30.151163: W external/xla/xla/service/hlo_rematerialization.cc:2941] Can't reduce memory use below -1.88TiB (-2064790164282 bytes) by rematerialization; only reduced to 8.00TiB (8796093022576 bytes), down from 8.00TiB (8796093022736 bytes) originally
2024-03-17 15:31:30.151471: W external/xla/xla/service/hlo_rematerialization.cc:2941] Can't reduce memory use below -1.88TiB (-2064790164282 bytes) by rematerialization; only reduced to 8.00TiB (8796093022576 bytes), down from 8.00TiB (8796093022736 bytes) originally
2024-03-17 15:31:30.151535: W external/xla/xla/service/hlo_rematerialization.cc:2941] Can't reduce memory use below -1.88TiB (-2064790164282 bytes) by rematerialization; only reduced to 8.00TiB (8796093022576 bytes), down from 8.00TiB (8796093022736 bytes) originally
2024-03-17 15:31:30.155143: E external/xla/xla/status_macros.cc:54] INTERNAL: RET_CHECK failure (external/xla/xla/service/gpu/fusions/fusion_emitter.cc:96) device_info.block_dim_limit().x == 0 || launch_dims.block_counts().x < device_info.block_dim_limit().x Kernel 'input_concatenate_fusion' launch needs more blocks (4294967295) than allowed by hardware (2147483647).
*** Begin stack trace ***
	
	
	
	
	
	
	
	
	
	
	
	
	
	
	
	
	
	
	
	
	
	
	
	
	
	
	
	
	
	
	_PyObject_MakeTpCall
	
	_PyEval_EvalFrameDefault
	_PyFunction_Vectorcall
	_PyEval_EvalFrameDefault
	_PyFunction_Vectorcall
	_PyEval_EvalFrameDefault
	_PyFunction_Vectorcall
	_PyEval_EvalFrameDefault
	_PyFunction_Vectorcall
	_PyEval_EvalFrameDefault
	_PyFunction_Vectorcall
	
	
	
	
	
	
	
	
	_PyObject_MakeTpCall
	
	
	_PyObject_MakeTpCall
	_PyEval_EvalFrameDefault
	_PyFunction_Vectorcall
	PyObject_Call
	_PyEval_EvalFrameDefault
	_PyFunction_Vectorcall
	_PyEval_EvalFrameDefault
	_PyFunction_Vectorcall
	PyObject_Call
	_PyEval_EvalFrameDefault
	_PyFunction_Vectorcall
	
	
	_PyEval_EvalFrameDefault
	_PyFunction_Vectorcall
	PyObject_Call
	_PyEval_EvalFrameDefault
	_PyFunction_Vectorcall
	_PyEval_EvalFrameDefault
	_PyFunction_Vectorcall
	_PyEval_EvalFrameDefault
	
	PyObject_Call
	_PyEval_EvalFrameDefault
	_PyFunction_Vectorcall
	_PyEval_EvalFrameDefault
	_PyFunction_Vectorcall
	_PyEval_EvalFrameDefault
	_PyFunction_Vectorcall
	
	
	_PyEval_EvalFrameDefault
	_PyFunction_Vectorcall
	_PyEval_EvalFrameDefault
	_PyFunction_Vectorcall
	_PyEval_EvalFrameDefault
	
	PyEval_EvalCode
	
	
	
	_PyRun_SimpleFileObject
	_PyRun_AnyFileObject
	Py_RunMain
	Py_BytesMain
	__libc_start_main
	
*** End stack trace ***

2024-03-17 15:31:30.155309: E external/xla/xla/status_macros.cc:54] INTERNAL: RET_CHECK failure (external/xla/xla/service/gpu/fusions/fusion_emitter.cc:96) device_info.block_dim_limit().x == 0 || launch_dims.block_counts().x < device_info.block_dim_limit().x Kernel 'input_concatenate_fusion' launch needs more blocks (4294967295) than allowed by hardware (2147483647).
*** Begin stack trace ***
	
	
	
	
	
	
	
	
	
	
	
	
	
	
	
	
	
	
	
	
	
	
	
	
	
	
	
	
	
	
	_PyObject_MakeTpCall
	
	_PyEval_EvalFrameDefault
	_PyFunction_Vectorcall
	_PyEval_EvalFrameDefault
	_PyFunction_Vectorcall
	_PyEval_EvalFrameDefault
	_PyFunction_Vectorcall
	_PyEval_EvalFrameDefault
	_PyFunction_Vectorcall
	_PyEval_EvalFrameDefault
	_PyFunction_Vectorcall
	
	
	
	
	
	
	
	
	_PyObject_MakeTpCall
	
	
	_PyObject_MakeTpCall
	_PyEval_EvalFrameDefault
	_PyFunction_Vectorcall
	PyObject_Call
	_PyEval_EvalFrameDefault
	_PyFunction_Vectorcall
	_PyEval_EvalFrameDefault
	_PyFunction_Vectorcall
	PyObject_Call
	_PyEval_EvalFrameDefault
	_PyFunction_Vectorcall
	
	
	_PyEval_EvalFrameDefault
	_PyFunction_Vectorcall
	PyObject_Call
	_PyEval_EvalFrameDefault
	_PyFunction_Vectorcall
	_PyEval_EvalFrameDefault
	_PyFunction_Vectorcall
	_PyEval_EvalFrameDefault
	
	PyObject_Call
	_PyEval_EvalFrameDefault
	_PyFunction_Vectorcall
	_PyEval_EvalFrameDefault
	_PyFunction_Vectorcall
	_PyEval_EvalFrameDefault
	_PyFunction_Vectorcall
	
	
	_PyEval_EvalFrameDefault
	_PyFunction_Vectorcall
	_PyEval_EvalFrameDefault
	_PyFunction_Vectorcall
	_PyEval_EvalFrameDefault
	
	PyEval_EvalCode
	
	
	
	_PyRun_SimpleFileObject
	_PyRun_AnyFileObject
	Py_RunMain
	Py_BytesMain
	__libc_start_main
	
*** End stack trace ***

2024-03-17 15:31:30.155525: E external/xla/xla/status_macros.cc:54] INTERNAL: RET_CHECK failure (external/xla/xla/service/gpu/fusions/fusion_emitter.cc:96) device_info.block_dim_limit().x == 0 || launch_dims.block_counts().x < device_info.block_dim_limit().x Kernel 'input_concatenate_fusion' launch needs more blocks (4294967295) than allowed by hardware (2147483647).
*** Begin stack trace ***
	
	
	
	
	
	
	
	
	
	
	
	
	
	
	
	
	
	
	
	
	
	
	
	
	
	
	
	
	
	
	_PyObject_MakeTpCall
	
	_PyEval_EvalFrameDefault
	_PyFunction_Vectorcall
	_PyEval_EvalFrameDefault
	_PyFunction_Vectorcall
	_PyEval_EvalFrameDefault
	_PyFunction_Vectorcall
	_PyEval_EvalFrameDefault
	_PyFunction_Vectorcall
	_PyEval_EvalFrameDefault
	_PyFunction_Vectorcall
	
	
	
	
	
	
	
	
	_PyObject_MakeTpCall
	
	
	_PyObject_MakeTpCall
	_PyEval_EvalFrameDefault
	_PyFunction_Vectorcall
	PyObject_Call
	_PyEval_EvalFrameDefault
	_PyFunction_Vectorcall
	_PyEval_EvalFrameDefault
	_PyFunction_Vectorcall
	PyObject_Call
	_PyEval_EvalFrameDefault
	_PyFunction_Vectorcall
	
	
	_PyEval_EvalFrameDefault
	_PyFunction_Vectorcall
	PyObject_Call
	_PyEval_EvalFrameDefault
	_PyFunction_Vectorcall
	_PyEval_EvalFrameDefault
	_PyFunction_Vectorcall
	_PyEval_EvalFrameDefault
	
	PyObject_Call
	_PyEval_EvalFrameDefault
	_PyFunction_Vectorcall
	_PyEval_EvalFrameDefault
	_PyFunction_Vectorcall
	_PyEval_EvalFrameDefault
	_PyFunction_Vectorcall
	
	
	_PyEval_EvalFrameDefault
	_PyFunction_Vectorcall
	_PyEval_EvalFrameDefault
	_PyFunction_Vectorcall
	_PyEval_EvalFrameDefault
	
	PyEval_EvalCode
	
	
	
	_PyRun_SimpleFileObject
	_PyRun_AnyFileObject
	Py_RunMain
	Py_BytesMain
	__libc_start_main
	
*** End stack trace ***

2024-03-17 15:31:30.155675: E external/xla/xla/status_macros.cc:54] INTERNAL: RET_CHECK failure (external/xla/xla/service/gpu/fusions/fusion_emitter.cc:96) device_info.block_dim_limit().x == 0 || launch_dims.block_counts().x < device_info.block_dim_limit().x Kernel 'input_concatenate_fusion' launch needs more blocks (4294967295) than allowed by hardware (2147483647).
*** Begin stack trace ***
	
	
	
	
	
	
	
	
	
	
	
	
	
	
	
	
	
	
	
	
	
	
	
	
	
	
	
	
	
	
	_PyObject_MakeTpCall
	
	_PyEval_EvalFrameDefault
	_PyFunction_Vectorcall
	_PyEval_EvalFrameDefault
	_PyFunction_Vectorcall
	_PyEval_EvalFrameDefault
	_PyFunction_Vectorcall
	_PyEval_EvalFrameDefault
	_PyFunction_Vectorcall
	_PyEval_EvalFrameDefault
	_PyFunction_Vectorcall
	
	
	
	
	
	
	
	
	_PyObject_MakeTpCall
	
	
	_PyObject_MakeTpCall
	_PyEval_EvalFrameDefault
	_PyFunction_Vectorcall
	PyObject_Call
	_PyEval_EvalFrameDefault
	_PyFunction_Vectorcall
	_PyEval_EvalFrameDefault
	_PyFunction_Vectorcall
	PyObject_Call
	_PyEval_EvalFrameDefault
	_PyFunction_Vectorcall
	
	
	_PyEval_EvalFrameDefault
	_PyFunction_Vectorcall
	PyObject_Call
	_PyEval_EvalFrameDefault
	_PyFunction_Vectorcall
	_PyEval_EvalFrameDefault
	_PyFunction_Vectorcall
	_PyEval_EvalFrameDefault
	
	PyObject_Call
	_PyEval_EvalFrameDefault
	_PyFunction_Vectorcall
	_PyEval_EvalFrameDefault
	_PyFunction_Vectorcall
	_PyEval_EvalFrameDefault
	_PyFunction_Vectorcall
	
	
	_PyEval_EvalFrameDefault
	_PyFunction_Vectorcall
	_PyEval_EvalFrameDefault
	_PyFunction_Vectorcall
	_PyEval_EvalFrameDefault
	
	PyEval_EvalCode
	
	
	
	_PyRun_SimpleFileObject
	_PyRun_AnyFileObject
	Py_RunMain
	Py_BytesMain
	__libc_start_main
	
*** End stack trace ***

jax.errors.SimplifiedTraceback: For simplicity, JAX has removed its internal frames from the traceback of the following exception. Set JAX_TRACEBACK_FILTERING=off to include these.

The above exception was the direct cause of the following exception:

Traceback (most recent call last):
  File "/gpfsdswork/projects/rech/tkc/commun/jaxDecomp/benchmarks/pfft3d.py", line 168, in <module>
    run_benchmark(pdims, global_shape, backend, nb_nodes, output_path)
  File "/gpfsdswork/projects/rech/tkc/commun/jaxDecomp/benchmarks/pfft3d.py", line 32, in run_benchmark
    array = jax.random.normal(
  File "/gpfsdswork/projects/rech/tkc/commun/jaxDecomp/venv/v100/lib/python3.10/site-packages/jax/_src/random.py", line 720, in normal
    return _normal(key, shape, dtype)  # type: ignore
jaxlib.xla_extension.XlaRuntimeError: INTERNAL: RET_CHECK failure (external/xla/xla/service/gpu/fusions/fusion_emitter.cc:96) device_info.block_dim_limit().x == 0 || launch_dims.block_counts().x < device_info.block_dim_limit().x Kernel 'input_concatenate_fusion' launch needs more blocks (4294967295) than allowed by hardware (2147483647).
jax.errors.SimplifiedTraceback: For simplicity, JAX has removed its internal frames from the traceback of the following exception. Set JAX_TRACEBACK_FILTERING=off to include these.

The above exception was the direct cause of the following exception:

Traceback (most recent call last):
  File "/gpfsdswork/projects/rech/tkc/commun/jaxDecomp/benchmarks/pfft3d.py", line 168, in <module>
    run_benchmark(pdims, global_shape, backend, nb_nodes, output_path)
  File "/gpfsdswork/projects/rech/tkc/commun/jaxDecomp/benchmarks/pfft3d.py", line 32, in run_benchmark
    array = jax.random.normal(
  File "/gpfsdswork/projects/rech/tkc/commun/jaxDecomp/venv/v100/lib/python3.10/site-packages/jax/_src/random.py", line 720, in normal
    return _normal(key, shape, dtype)  # type: ignore
jaxlib.xla_extension.XlaRuntimeError: INTERNAL: RET_CHECK failure (external/xla/xla/service/gpu/fusions/fusion_emitter.cc:96) device_info.block_dim_limit().x == 0 || launch_dims.block_counts().x < device_info.block_dim_limit().x Kernel 'input_concatenate_fusion' launch needs more blocks (4294967295) than allowed by hardware (2147483647).
jax.errors.SimplifiedTraceback: For simplicity, JAX has removed its internal frames from the traceback of the following exception. Set JAX_TRACEBACK_FILTERING=off to include these.

The above exception was the direct cause of the following exception:

Traceback (most recent call last):
  File "/gpfsdswork/projects/rech/tkc/commun/jaxDecomp/benchmarks/pfft3d.py", line 168, in <module>
    run_benchmark(pdims, global_shape, backend, nb_nodes, output_path)
  File "/gpfsdswork/projects/rech/tkc/commun/jaxDecomp/benchmarks/pfft3d.py", line 32, in run_benchmark
    array = jax.random.normal(
  File "/gpfsdswork/projects/rech/tkc/commun/jaxDecomp/venv/v100/lib/python3.10/site-packages/jax/_src/random.py", line 720, in normal
    return _normal(key, shape, dtype)  # type: ignore
jaxlib.xla_extension.XlaRuntimeError: INTERNAL: RET_CHECK failure (external/xla/xla/service/gpu/fusions/fusion_emitter.cc:96) device_info.block_dim_limit().x == 0 || launch_dims.block_counts().x < device_info.block_dim_limit().x Kernel 'input_concatenate_fusion' launch needs more blocks (4294967295) than allowed by hardware (2147483647).
jax.errors.SimplifiedTraceback: For simplicity, JAX has removed its internal frames from the traceback of the following exception. Set JAX_TRACEBACK_FILTERING=off to include these.

The above exception was the direct cause of the following exception:

Traceback (most recent call last):
  File "/gpfsdswork/projects/rech/tkc/commun/jaxDecomp/benchmarks/pfft3d.py", line 168, in <module>
    run_benchmark(pdims, global_shape, backend, nb_nodes, output_path)
  File "/gpfsdswork/projects/rech/tkc/commun/jaxDecomp/benchmarks/pfft3d.py", line 32, in run_benchmark
    array = jax.random.normal(
  File "/gpfsdswork/projects/rech/tkc/commun/jaxDecomp/venv/v100/lib/python3.10/site-packages/jax/_src/random.py", line 720, in normal
    return _normal(key, shape, dtype)  # type: ignore
jaxlib.xla_extension.XlaRuntimeError: INTERNAL: RET_CHECK failure (external/xla/xla/service/gpu/fusions/fusion_emitter.cc:96) device_info.block_dim_limit().x == 0 || launch_dims.block_counts().x < device_info.block_dim_limit().x Kernel 'input_concatenate_fusion' launch needs more blocks (4294967295) than allowed by hardware (2147483647).
jax.errors.SimplifiedTraceback: For simplicity, JAX has removed its internal frames from the traceback of the following exception. Set JAX_TRACEBACK_FILTERING=off to include these.

The above exception was the direct cause of the following exception:

Traceback (most recent call last):
  File "/gpfsdswork/projects/rech/tkc/commun/jaxDecomp/benchmarks/pfft3d.py", line 168, in <module>
    run_benchmark(pdims, global_shape, backend, nb_nodes, output_path)
  File "/gpfsdswork/projects/rech/tkc/commun/jaxDecomp/benchmarks/pfft3d.py", line 32, in run_benchmark
    array = jax.random.normal(
  File "/gpfsdswork/projects/rech/tkc/commun/jaxDecomp/venv/v100/lib/python3.10/site-packages/jax/_src/random.py", line 720, in normal
    return _normal(key, shape, dtype)  # type: ignore
jaxlib.xla_extension.XlaRuntimeError: INTERNAL: RET_CHECK failure (external/xla/xla/service/gpu/fusions/fusion_emitter.cc:96) device_info.block_dim_limit().x == 0 || launch_dims.block_counts().x < device_info.block_dim_limit().x Kernel 'input_concatenate_fusion' launch needs more blocks (4294967295) than allowed by hardware (2147483647).
srun: error: r7i6n7: tasks 4-7: Exited with exit code 1
srun: Terminating StepId=1124578.63
srun: error: r7i1n0: tasks 0-3: Exited with exit code 1
